,ts_recv,ts_event,rtype,publisher_id,instrument_id,action,side,depth,price,size,flags,ts_in_delta,sequence,bid_px_00,bid_sz_00,bid_ct_00,ask_px_00,ask_sz_00,ask_ct_00,bid_px_01,bid_sz_01,bid_ct_01,ask_px_01,ask_sz_01,ask_ct_01,bid_px_02,bid_sz_02,bid_ct_02,ask_px_02,ask_sz_02,ask_ct_02,bid_px_03,bid_sz_03,bid_ct_03,ask_px_03,ask_sz_03,ask_ct_03,bid_px_04,bid_sz_04,bid_ct_04,ask_px_04,ask_sz_04,ask_ct_04,bid_px_05,bid_sz_05,bid_ct_05,ask_px_05,ask_sz_05,ask_ct_05,bid_px_06,bid_sz_06,bid_ct_06,ask_px_06,ask_sz_06,ask_ct_06,bid_px_07,bid_sz_07,bid_ct_07,ask_px_07,ask_sz_07,ask_ct_07,bid_px_08,bid_sz_08,bid_ct_08,ask_px_08,ask_sz_08,ask_ct_08,bid_px_09,bid_sz_09,bid_ct_09,ask_px_09,ask_sz_09,ask_ct_09,symbol,order_id
1699,2025-07-17T16:17:26.849505109Z,2025-07-17T16:17:26.849505109Z,10,2,1108,C,A,4,14.43,100,0,165550,286262262,13.11,100,1,13.97,2,1,13.03,2,1,14.22,100,1,12.98,200,2,14.25,100,1,12.86,100,1,14.36,100,1,12.73,100,1,14.46,200,2,12.71,100,1,14.48,700,1,12.5,700,1,14.49,100,1,12.46,100,1,14.54,800,2,12.43,700,1,14.56,700,1,12.42,700,1,14.58,100,1,ARL,344225489
1700,2025-07-17T16:17:26.874264677Z,2025-07-17T16:17:26.874264677Z,10,2,1108,C,A,9,14.58,100,0,165561,286262413,13.11,100,1,13.97,2,1,13.03,2,1,14.22,100,1,12.98,200,2,14.25,100,1,12.86,100,1,14.36,100,1,12.73,100,1,14.46,200,2,12.71,100,1,14.48,700,1,12.5,700,1,14.49,100,1,12.46,100,1,14.54,800,2,12.43,700,1,14.56,700,1,12.42,700,1,14.68,700,1,ARL,344280577
1701,2025-07-17T16:17:27.000617575Z,2025-07-17T16:17:27.000617575Z,10,2,1108,A,A,1,13.98,100,130,165215,286264622,13.11,100,1,13.97,2,1,13.03,2,1,13.98,100,1,12.98,200,2,14.22,100,1,12.86,100,1,14.25,100,1,12.73,100,1,14.36,100,1,12.71,100,1,14.46,200,2,12.5,700,1,14.48,700,1,12.46,100,1,14.49,100,1,12.43,700,1,14.54,800,2,12.42,700,1,14.56,700,1,ARL,344283633
1702,2025-07-17T16:17:27.204728176Z,2025-07-17T16:17:27.204728176Z,10,2,1108,C,A,2,14.22,100,130,165812,286267644,13.11,100,1,13.97,2,1,13.03,2,1,13.98,100,1,12.98,200,2,14.25,100,1,12.86,100,1,14.36,100,1,12.73,100,1,14.46,200,2,12.71,100,1,14.48,700,1,12.5,700,1,14.49,100,1,12.46,100,1,14.54,800,2,12.43,700,1,14.56,700,1,12.42,700,1,14.68,700,1,ARL,339365193
1703,2025-07-17T16:17:27.204730160Z,2025-07-17T16:17:27.204730160Z,10,2,1108,A,A,7,14.53,100,130,165107,286267645,13.11,100,1,13.97,2,1,13.03,2,1,13.98,100,1,12.98,200,2,14.25,100,1,12.86,100,1,14.36,100,1,12.73,100,1,14.46,200,2,12.71,100,1,14.48,700,1,12.5,700,1,14.49,100,1,12.46,100,1,14.53,100,1,12.43,700,1,14.54,800,2,12.42,700,1,14.56,700,1,ARL,344288585
1704,2025-07-17T16:17:27.381644366Z,2025-07-17T16:17:27.381644366Z,10,2,1108,C,A,6,14.49,100,130,165457,286271010,13.11,100,1,13.97,2,1,13.03,2,1,13.98,100,1,12.98,200,2,14.25,100,1,12.86,100,1,14.36,100,1,12.73,100,1,14.46,200,2,12.71,100,1,14.48,700,1,12.5,700,1,14.53,100,1,12.46,100,1,14.54,800,2,12.43,700,1,14.56,700,1,12.42,700,1,14.68,700,1,ARL,339366385
1705,2025-07-17T16:17:27.442997426Z,2025-07-17T16:17:27.442997426Z,10,2,1108,C,A,3,14.36,100,130,165022,286271749,13.11,100,1,13.97,2,1,13.03,2,1,13.98,100,1,12.98,200,2,14.25,100,1,12.86,100,1,14.46,200,2,12.73,100,1,14.48,700,1,12.71,100,1,14.53,100,1,12.5,700,1,14.54,800,2,12.46,100,1,14.56,700,1,12.43,700,1,14.68,700,1,12.42,700,1,14.81,100,1,ARL,344280617
1706,2025-07-17T16:17:27.443347265Z,2025-07-17T16:17:27.443347265Z,10,2,1108,A,A,8,14.6,100,130,165325,286271751,13.11,100,1,13.97,2,1,13.03,2,1,13.98,100,1,12.98,200,2,14.25,100,1,12.86,100,1,14.46,200,2,12.73,100,1,14.48,700,1,12.71,100,1,14.53,100,1,12.5,700,1,14.54,800,2,12.46,100,1,14.56,700,1,12.43,700,1,14.6,100,1,12.42,700,1,14.68,700,1,ARL,344294245
1707,2025-07-17T16:17:27.828890080Z,2025-07-17T16:17:27.828890080Z,10,2,1108,C,A,6,14.54,100,0,165208,286275353,13.11,100,1,13.97,2,1,13.03,2,1,13.98,100,1,12.98,200,2,14.25,100,1,12.86,100,1,14.46,200,2,12.73,100,1,14.48,700,1,12.71,100,1,14.53,100,1,12.5,700,1,14.54,700,1,12.46,100,1,14.56,700,1,12.43,700,1,14.6,100,1,12.42,700,1,14.68,700,1,ARL,344280645
1708,2025-07-17T16:17:27.828890080Z,2025-07-17T16:17:27.828890080Z,10,2,1108,A,A,10,14.77,100,130,165208,286275353,13.11,100,1,13.97,2,1,13.03,2,1,13.98,100,1,12.98,200,2,14.25,100,1,12.86,100,1,14.46,200,2,12.73,100,1,14.48,700,1,12.71,100,1,14.53,100,1,12.5,700,1,14.54,700,1,12.46,100,1,14.56,700,1,12.43,700,1,14.6,100,1,12.42,700,1,14.68,700,1,ARL,344300085
1709,2025-07-17T16:17:39.514525397Z,2025-07-17T16:17:39.514525397Z,10,2,1108,A,A,0,13.47,15,130,165354,286508705,13.11,100,1,13.47,15,1,13.03,2,1,13.97,2,1,12.98,200,2,13.98,100,1,12.86,100,1,14.25,100,1,12.73,100,1,14.46,200,2,12.71,100,1,14.48,700,1,12.5,700,1,14.53,100,1,12.46,100,1,14.54,700,1,12.43,700,1,14.56,700,1,12.42,700,1,14.6,100,1,ARL,344587533
1710,2025-07-17T16:17:39.828851797Z,2025-07-17T16:17:39.828851797Z,10,2,1108,C,A,4,14.46,100,0,165492,286513833,13.11,100,1,13.47,15,1,13.03,2,1,13.97,2,1,12.98,200,2,13.98,100,1,12.86,100,1,14.25,100,1,12.73,100,1,14.46,100,1,12.71,100,1,14.48,700,1,12.5,700,1,14.53,100,1,12.46,100,1,14.54,700,1,12.43,700,1,14.56,700,1,12.42,700,1,14.6,100,1,ARL,339739285
1711,2025-07-17T16:17:39.828851797Z,2025-07-17T16:17:39.828851797Z,10,2,1108,A,A,4,14.35,100,130,165492,286513833,13.11,100,1,13.47,15,1,13.03,2,1,13.97,2,1,12.98,200,2,13.98,100,1,12.86,100,1,14.25,100,1,12.73,100,1,14.35,100,1,12.71,100,1,14.46,100,1,12.5,700,1,14.48,700,1,12.46,100,1,14.53,100,1,12.43,700,1,14.54,700,1,12.42,700,1,14.56,700,1,ARL,344593405
1712,2025-07-17T16:17:39.829081898Z,2025-07-17T16:17:39.829081898Z,10,2,1108,C,A,5,14.46,100,0,165459,286513835,13.11,100,1,13.47,15,1,13.03,2,1,13.97,2,1,12.98,200,2,13.98,100,1,12.86,100,1,14.25,100,1,12.73,100,1,14.35,100,1,12.71,100,1,14.48,700,1,12.5,700,1,14.53,100,1,12.46,100,1,14.54,700,1,12.43,700,1,14.56,700,1,12.42,700,1,14.6,100,1,ARL,339739297
1713,2025-07-17T16:17:39.829081898Z,2025-07-17T16:17:39.829081898Z,10,2,1108,A,A,4,14.35,100,130,165459,286513835,13.11,100,1,13.47,15,1,13.03,2,1,13.97,2,1,12.98,200,2,13.98,100,1,12.86,100,1,14.25,100,1,12.73,100,1,14.35,200,2,12.71,100,1,14.48,700,1,12.5,700,1,14.53,100,1,12.46,100,1,14.54,700,1,12.43,700,1,14.56,700,1,12.42,700,1,14.6,100,1,ARL,344593409
1714,2025-07-17T16:17:40.321161439Z,2025-07-17T16:17:40.321161439Z,10,2,1108,C,A,2,13.98,100,0,165329,286524785,13.11,100,1,13.47,15,1,13.03,2,1,13.97,2,1,12.98,200,2,14.25,100,1,12.86,100,1,14.35,200,2,12.73,100,1,14.48,700,1,12.71,100,1,14.53,100,1,12.5,700,1,14.54,700,1,12.46,100,1,14.56,700,1,12.43,700,1,14.6,100,1,12.42,700,1,14.68,700,1,ARL,344283633
1715,2025-07-17T16:17:40.321161439Z,2025-07-17T16:17:40.321161439Z,10,2,1108,A,A,1,13.48,100,130,165329,286524785,13.11,100,1,13.47,15,1,13.03,2,1,13.48,100,1,12.98,200,2,13.97,2,1,12.86,100,1,14.25,100,1,12.73,100,1,14.35,200,2,12.71,100,1,14.48,700,1,12.5,700,1,14.53,100,1,12.46,100,1,14.54,700,1,12.43,700,1,14.56,700,1,12.42,700,1,14.6,100,1,ARL,344607833
1716,2025-07-17T16:17:40.321898765Z,2025-07-17T16:17:40.321898765Z,10,2,1108,C,A,9,14.6,100,130,165273,286524815,13.11,100,1,13.47,15,1,13.03,2,1,13.48,100,1,12.98,200,2,13.97,2,1,12.86,100,1,14.25,100,1,12.73,100,1,14.35,200,2,12.71,100,1,14.48,700,1,12.5,700,1,14.53,100,1,12.46,100,1,14.54,700,1,12.43,700,1,14.56,700,1,12.42,700,1,14.68,700,1,ARL,344294245
1717,2025-07-17T16:17:40.321903984Z,2025-07-17T16:17:40.321903984Z,10,2,1108,A,A,6,14.53,100,130,165758,286524817,13.11,100,1,13.47,15,1,13.03,2,1,13.48,100,1,12.98,200,2,13.97,2,1,12.86,100,1,14.25,100,1,12.73,100,1,14.35,200,2,12.71,100,1,14.48,700,1,12.5,700,1,14.53,200,2,12.46,100,1,14.54,700,1,12.43,700,1,14.56,700,1,12.42,700,1,14.68,700,1,ARL,344607889
1718,2025-07-17T16:17:40.322250847Z,2025-07-17T16:17:40.322250847Z,10,2,1108,A,A,3,14.08,100,130,165168,286524822,13.11,100,1,13.47,15,1,13.03,2,1,13.48,100,1,12.98,200,2,13.97,2,1,12.86,100,1,14.08,100,1,12.73,100,1,14.25,100,1,12.71,100,1,14.35,200,2,12.5,700,1,14.48,700,1,12.46,100,1,14.53,200,2,12.43,700,1,14.54,700,1,12.42,700,1,14.56,700,1,ARL,344607893
1719,2025-07-17T16:17:40.329015669Z,2025-07-17T16:17:40.329015669Z,10,2,1108,C,A,4,14.25,100,130,165228,286524967,13.11,100,1,13.47,15,1,13.03,2,1,13.48,100,1,12.98,200,2,13.97,2,1,12.86,100,1,14.08,100,1,12.73,100,1,14.35,200,2,12.71,100,1,14.48,700,1,12.5,700,1,14.53,200,2,12.46,100,1,14.54,700,1,12.43,700,1,14.56,700,1,12.42,700,1,14.68,700,1,ARL,344280953
1720,2025-07-17T16:17:40.329067996Z,2025-07-17T16:17:40.329067996Z,10,2,1108,A,A,2,13.75,100,130,165161,286524969,13.11,100,1,13.47,15,1,13.03,2,1,13.48,100,1,12.98,200,2,13.75,100,1,12.86,100,1,13.97,2,1,12.73,100,1,14.08,100,1,12.71,100,1,14.35,200,2,12.5,700,1,14.48,700,1,12.46,100,1,14.53,200,2,12.43,700,1,14.54,700,1,12.42,700,1,14.56,700,1,ARL,344608193
1721,2025-07-17T16:17:40.331386492Z,2025-07-17T16:17:40.331386492Z,10,2,1108,A,A,5,14.27,100,130,165164,286525005,13.11,100,1,13.47,15,1,13.03,2,1,13.48,100,1,12.98,200,2,13.75,100,1,12.86,100,1,13.97,2,1,12.73,100,1,14.08,100,1,12.71,100,1,14.27,100,1,12.5,700,1,14.35,200,2,12.46,100,1,14.48,700,1,12.43,700,1,14.53,200,2,12.42,700,1,14.54,700,1,ARL,344608225
1722,2025-07-17T16:17:40.333513866Z,2025-07-17T16:17:40.333513866Z,10,2,1108,A,A,7,14.43,100,130,165315,286525029,13.11,100,1,13.47,15,1,13.03,2,1,13.48,100,1,12.98,200,2,13.75,100,1,12.86,100,1,13.97,2,1,12.73,100,1,14.08,100,1,12.71,100,1,14.27,100,1,12.5,700,1,14.35,200,2,12.46,100,1,14.43,100,1,12.43,700,1,14.48,700,1,12.42,700,1,14.53,200,2,ARL,344608253
1723,2025-07-17T16:17:40.426425205Z,2025-07-17T16:17:40.426425205Z,10,2,1108,A,A,7,14.43,100,130,165362,286526540,13.11,100,1,13.47,15,1,13.03,2,1,13.48,100,1,12.98,200,2,13.75,100,1,12.86,100,1,13.97,2,1,12.73,100,1,14.08,100,1,12.71,100,1,14.27,100,1,12.5,700,1,14.35,200,2,12.46,100,1,14.43,200,2,12.43,700,1,14.48,700,1,12.42,700,1,14.53,200,2,ARL,344610073
1724,2025-07-17T16:17:40.474675991Z,2025-07-17T16:17:40.474675991Z,10,2,1108,A,A,4,14.01,100,130,165127,286527611,13.11,100,1,13.47,15,1,13.03,2,1,13.48,100,1,12.98,200,2,13.75,100,1,12.86,100,1,13.97,2,1,12.73,100,1,14.01,100,1,12.71,100,1,14.08,100,1,12.5,700,1,14.27,100,1,12.46,100,1,14.35,200,2,12.43,700,1,14.43,200,2,12.42,700,1,14.48,700,1,ARL,344612049
1725,2025-07-17T16:17:40.697555911Z,2025-07-17T16:17:40.697555911Z,10,2,1108,A,A,7,14.28,100,130,165294,286530329,13.11,100,1,13.47,15,1,13.03,2,1,13.48,100,1,12.98,200,2,13.75,100,1,12.86,100,1,13.97,2,1,12.73,100,1,14.01,100,1,12.71,100,1,14.08,100,1,12.5,700,1,14.27,100,1,12.46,100,1,14.28,100,1,12.43,700,1,14.35,200,2,12.42,700,1,14.43,200,2,ARL,344615393
1726,2025-07-17T16:17:41.585985709Z,2025-07-17T16:17:41.585985709Z,10,2,1108,C,A,3,13.97,2,0,165452,286543225,13.11,100,1,13.47,15,1,13.03,2,1,13.48,100,1,12.98,200,2,13.75,100,1,12.86,100,1,14.01,100,1,12.73,100,1,14.08,100,1,12.71,100,1,14.27,100,1,12.5,700,1,14.28,100,1,12.46,100,1,14.35,200,2,12.43,700,1,14.43,200,2,12.42,700,1,14.48,700,1,ARL,344280721
1727,2025-07-17T16:17:41.585985709Z,2025-07-17T16:17:41.585985709Z,10,2,1108,A,A,3,13.87,2,130,165452,286543225,13.11,100,1,13.47,15,1,13.03,2,1,13.48,100,1,12.98,200,2,13.75,100,1,12.86,100,1,13.87,2,1,12.73,100,1,14.01,100,1,12.71,100,1,14.08,100,1,12.5,700,1,14.27,100,1,12.46,100,1,14.28,100,1,12.43,700,1,14.35,200,2,12.42,700,1,14.43,200,2,ARL,344631921
1728,2025-07-17T16:17:42.552968542Z,2025-07-17T16:17:42.552968542Z,10,2,1108,A,A,0,13.45,15,130,165108,286561347,13.11,100,1,13.45,15,1,13.03,2,1,13.47,15,1,12.98,200,2,13.48,100,1,12.86,100,1,13.75,100,1,12.73,100,1,13.87,2,1,12.71,100,1,14.01,100,1,12.5,700,1,14.08,100,1,12.46,100,1,14.27,100,1,12.43,700,1,14.28,100,1,12.42,700,1,14.35,200,2,ARL,344653009
1729,2025-07-17T16:17:44.014448587Z,2025-07-17T16:17:44.014448587Z,10,2,1108,C,A,2,13.48,100,0,165462,286577648,13.11,100,1,13.45,15,1,13.03,2,1,13.47,15,1,12.98,200,2,13.75,100,1,12.86,100,1,13.87,2,1,12.73,100,1,14.01,100,1,12.71,100,1,14.08,100,1,12.5,700,1,14.27,100,1,12.46,100,1,14.28,100,1,12.43,700,1,14.35,200,2,12.42,700,1,14.43,200,2,ARL,344607833
1730,2025-07-17T16:17:44.014448587Z,2025-07-17T16:17:44.014448587Z,10,2,1108,A,A,1,13.46,100,130,165462,286577648,13.11,100,1,13.45,15,1,13.03,2,1,13.46,100,1,12.98,200,2,13.47,15,1,12.86,100,1,13.75,100,1,12.73,100,1,13.87,2,1,12.71,100,1,14.01,100,1,12.5,700,1,14.08,100,1,12.46,100,1,14.27,100,1,12.43,700,1,14.28,100,1,12.42,700,1,14.35,200,2,ARL,344673481
1731,2025-07-17T16:17:46.828095134Z,2025-07-17T16:17:46.828095134Z,10,2,1108,A,A,7,14.18,700,130,165257,286618024,13.11,100,1,13.45,15,1,13.03,2,1,13.46,100,1,12.98,200,2,13.47,15,1,12.86,100,1,13.75,100,1,12.73,100,1,13.87,2,1,12.71,100,1,14.01,100,1,12.5,700,1,14.08,100,1,12.46,100,1,14.18,700,1,12.43,700,1,14.27,100,1,12.42,700,1,14.28,100,1,ARL,344724301
1732,2025-07-17T16:17:49.387365405Z,2025-07-17T16:17:49.387365405Z,10,2,1108,C,A,4,13.87,2,0,165537,286651544,13.11,100,1,13.45,15,1,13.03,2,1,13.46,100,1,12.98,200,2,13.47,15,1,12.86,100,1,13.75,100,1,12.73,100,1,14.01,100,1,12.71,100,1,14.08,100,1,12.5,700,1,14.18,700,1,12.46,100,1,14.27,100,1,12.43,700,1,14.28,100,1,12.42,700,1,14.35,200,2,ARL,344631921
1733,2025-07-17T16:17:49.387365405Z,2025-07-17T16:17:49.387365405Z,10,2,1108,A,A,4,13.79,2,130,165537,286651544,13.11,100,1,13.45,15,1,13.03,2,1,13.46,100,1,12.98,200,2,13.47,15,1,12.86,100,1,13.75,100,1,12.73,100,1,13.79,2,1,12.71,100,1,14.01,100,1,12.5,700,1,14.08,100,1,12.46,100,1,14.18,700,1,12.43,700,1,14.27,100,1,12.42,700,1,14.28,100,1,ARL,344765077
1734,2025-07-17T16:17:52.834008196Z,2025-07-17T16:17:52.834008196Z,10,2,1108,C,A,2,13.47,15,130,165777,286689853,13.11,100,1,13.45,15,1,13.03,2,1,13.46,100,1,12.98,200,2,13.75,100,1,12.86,100,1,13.79,2,1,12.73,100,1,14.01,100,1,12.71,100,1,14.08,100,1,12.5,700,1,14.18,700,1,12.46,100,1,14.27,100,1,12.43,700,1,14.28,100,1,12.42,700,1,14.35,200,2,ARL,344587533
1735,2025-07-17T16:17:58.033161898Z,2025-07-17T16:17:58.033161898Z,10,2,1108,C,A,0,13.45,15,130,165155,286753046,13.11,100,1,13.46,100,1,13.03,2,1,13.75,100,1,12.98,200,2,13.79,2,1,12.86,100,1,14.01,100,1,12.73,100,1,14.08,100,1,12.71,100,1,14.18,700,1,12.5,700,1,14.27,100,1,12.46,100,1,14.28,100,1,12.43,700,1,14.35,200,2,12.42,700,1,14.43,200,2,ARL,344653009
1736,2025-07-17T16:17:58.036423237Z,2025-07-17T16:17:58.036423237Z,10,2,1108,C,A,0,13.46,100,130,165232,286753126,13.11,100,1,13.75,100,1,13.03,2,1,13.79,2,1,12.98,200,2,14.01,100,1,12.86,100,1,14.08,100,1,12.73,100,1,14.18,700,1,12.71,100,1,14.27,100,1,12.5,700,1,14.28,100,1,12.46,100,1,14.35,200,2,12.43,700,1,14.43,200,2,12.42,700,1,14.48,700,1,ARL,344673481
1737,2025-07-17T16:17:58.036696806Z,2025-07-17T16:17:58.036696806Z,10,2,1108,C,A,4,14.18,700,130,165116,286753127,13.11,100,1,13.75,100,1,13.03,2,1,13.79,2,1,12.98,200,2,14.01,100,1,12.86,100,1,14.08,100,1,12.73,100,1,14.27,100,1,12.71,100,1,14.28,100,1,12.5,700,1,14.35,200,2,12.46,100,1,14.43,200,2,12.43,700,1,14.48,700,1,12.42,700,1,14.53,100,1,ARL,344724301
1738,2025-07-17T16:17:58.036748831Z,2025-07-17T16:17:58.036748831Z,10,2,1108,A,A,8,14.44,700,130,165171,286753128,13.11,100,1,13.75,100,1,13.03,2,1,13.79,2,1,12.98,200,2,14.01,100,1,12.86,100,1,14.08,100,1,12.73,100,1,14.27,100,1,12.71,100,1,14.28,100,1,12.5,700,1,14.35,200,2,12.46,100,1,14.43,200,2,12.43,700,1,14.44,700,1,12.42,700,1,14.48,700,1,ARL,344897921
1739,2025-07-17T16:17:58.037165870Z,2025-07-17T16:17:58.037165870Z,10,2,1108,C,A,3,14.08,100,130,165076,286753137,13.11,100,1,13.75,100,1,13.03,2,1,13.79,2,1,12.98,200,2,14.01,100,1,12.86,100,1,14.27,100,1,12.73,100,1,14.28,100,1,12.71,100,1,14.35,200,2,12.5,700,1,14.43,200,2,12.46,100,1,14.44,700,1,12.43,700,1,14.48,700,1,12.42,700,1,14.54,700,1,ARL,344607893
1740,2025-07-17T16:17:58.037521442Z,2025-07-17T16:17:58.037521442Z,10,2,1108,A,A,6,14.36,100,130,165234,286753149,13.11,100,1,13.75,100,1,13.03,2,1,13.79,2,1,12.98,200,2,14.01,100,1,12.86,100,1,14.27,100,1,12.73,100,1,14.28,100,1,12.71,100,1,14.35,200,2,12.5,700,1,14.36,100,1,12.46,100,1,14.43,200,2,12.43,700,1,14.44,700,1,12.42,700,1,14.48,700,1,ARL,344897953
1741,2025-07-17T16:17:58.038594284Z,2025-07-17T16:17:58.038594284Z,10,2,1108,C,A,7,14.43,100,0,165451,286753168,13.11,100,1,13.75,100,1,13.03,2,1,13.79,2,1,12.98,200,2,14.01,100,1,12.86,100,1,14.27,100,1,12.73,100,1,14.28,100,1,12.71,100,1,14.35,200,2,12.5,700,1,14.36,100,1,12.46,100,1,14.43,100,1,12.43,700,1,14.44,700,1,12.42,700,1,14.48,700,1,ARL,344608253
1742,2025-07-17T16:17:58.053883828Z,2025-07-17T16:17:58.053883828Z,10,2,1108,C,A,0,13.75,100,130,165534,286753747,13.11,100,1,13.79,2,1,13.03,2,1,14.01,100,1,12.98,200,2,14.27,100,1,12.86,100,1,14.28,100,1,12.73,100,1,14.35,200,2,12.71,100,1,14.36,100,1,12.5,700,1,14.43,100,1,12.46,100,1,14.44,700,1,12.43,700,1,14.48,700,1,12.42,700,1,14.54,700,1,ARL,344608193
1743,2025-07-17T16:17:58.053934652Z,2025-07-17T16:17:58.053934652Z,10,2,1108,C,A,7,14.44,700,130,166153,286753751,13.11,100,1,13.79,2,1,13.03,2,1,14.01,100,1,12.98,200,2,14.27,100,1,12.86,100,1,14.28,100,1,12.73,100,1,14.35,200,2,12.71,100,1,14.36,100,1,12.5,700,1,14.43,100,1,12.46,100,1,14.48,700,1,12.43,700,1,14.54,700,1,12.42,700,1,14.56,700,1,ARL,344897921
1744,2025-07-17T16:17:58.053935872Z,2025-07-17T16:17:58.053935872Z,10,2,1108,A,A,2,14.03,100,130,165557,286753752,13.11,100,1,13.79,2,1,13.03,2,1,14.01,100,1,12.98,200,2,14.03,100,1,12.86,100,1,14.27,100,1,12.73,100,1,14.28,100,1,12.71,100,1,14.35,200,2,12.5,700,1,14.36,100,1,12.46,100,1,14.43,100,1,12.43,700,1,14.48,700,1,12.42,700,1,14.54,700,1,ARL,344898949
1745,2025-07-17T16:17:58.061505885Z,2025-07-17T16:17:58.061505885Z,10,2,1108,C,A,2,14.03,100,130,164975,286754272,13.11,100,1,13.79,2,1,13.03,2,1,14.01,100,1,12.98,200,2,14.27,100,1,12.86,100,1,14.28,100,1,12.73,100,1,14.35,200,2,12.71,100,1,14.36,100,1,12.5,700,1,14.43,100,1,12.46,100,1,14.48,700,1,12.43,700,1,14.54,700,1,12.42,700,1,14.56,700,1,ARL,344898949
1746,2025-07-17T16:17:58.061563628Z,2025-07-17T16:17:58.061563628Z,10,2,1108,A,A,2,14.25,100,130,167208,286754286,13.11,100,1,13.79,2,1,13.03,2,1,14.01,100,1,12.98,200,2,14.25,100,1,12.86,100,1,14.27,100,1,12.73,100,1,14.28,100,1,12.71,100,1,14.35,200,2,12.5,700,1,14.36,100,1,12.46,100,1,14.43,100,1,12.43,700,1,14.48,700,1,12.42,700,1,14.54,700,1,ARL,344899417
1747,2025-07-17T16:17:58.086415950Z,2025-07-17T16:17:58.086415950Z,10,2,1108,C,A,3,14.27,100,0,166083,286754819,13.11,100,1,13.79,2,1,13.03,2,1,14.01,100,1,12.98,200,2,14.25,100,1,12.86,100,1,14.28,100,1,12.73,100,1,14.35,200,2,12.71,100,1,14.36,100,1,12.5,700,1,14.43,100,1,12.46,100,1,14.48,700,1,12.43,700,1,14.54,700,1,12.42,700,1,14.56,700,1,ARL,344608225
1748,2025-07-17T16:17:58.086415950Z,2025-07-17T16:17:58.086415950Z,10,2,1108,A,A,8,14.54,100,130,166083,286754819,13.11,100,1,13.79,2,1,13.03,2,1,14.01,100,1,12.98,200,2,14.25,100,1,12.86,100,1,14.28,100,1,12.73,100,1,14.35,200,2,12.71,100,1,14.36,100,1,12.5,700,1,14.43,100,1,12.46,100,1,14.48,700,1,12.43,700,1,14.54,800,2,12.42,700,1,14.56,700,1,ARL,344899913
1749,2025-07-17T16:17:58.145382853Z,2025-07-17T16:17:58.145382853Z,10,2,1108,C,A,6,14.43,100,0,165644,286755340,13.11,100,1,13.79,2,1,13.03,2,1,14.01,100,1,12.98,200,2,14.25,100,1,12.86,100,1,14.28,100,1,12.73,100,1,14.35,200,2,12.71,100,1,14.36,100,1,12.5,700,1,14.48,700,1,12.46,100,1,14.54,800,2,12.43,700,1,14.56,700,1,12.42,700,1,14.96,100,1,ARL,344610073
1750,2025-07-17T16:17:58.145382853Z,2025-07-17T16:17:58.145382853Z,10,2,1108,A,A,9,14.96,100,130,165644,286755340,13.11,100,1,13.79,2,1,13.03,2,1,14.01,100,1,12.98,200,2,14.25,100,1,12.86,100,1,14.28,100,1,12.73,100,1,14.35,200,2,12.71,100,1,14.36,100,1,12.5,700,1,14.48,700,1,12.46,100,1,14.54,800,2,12.43,700,1,14.56,700,1,12.42,700,1,14.96,200,2,ARL,344900597
1751,2025-07-17T16:17:58.173665745Z,2025-07-17T16:17:58.173665745Z,10,2,1108,A,A,9,14.81,100,130,165528,286755602,13.11,100,1,13.79,2,1,13.03,2,1,14.01,100,1,12.98,200,2,14.25,100,1,12.86,100,1,14.28,100,1,12.73,100,1,14.35,200,2,12.71,100,1,14.36,100,1,12.5,700,1,14.48,700,1,12.46,100,1,14.54,800,2,12.43,700,1,14.56,700,1,12.42,700,1,14.81,100,1,ARL,344900925
1752,2025-07-17T16:17:58.173687330Z,2025-07-17T16:17:58.173687330Z,10,2,1108,C,A,3,14.28,100,130,165437,286755603,13.11,100,1,13.79,2,1,13.03,2,1,14.01,100,1,12.98,200,2,14.25,100,1,12.86,100,1,14.35,200,2,12.73,100,1,14.36,100,1,12.71,100,1,14.48,700,1,12.5,700,1,14.54,800,2,12.46,100,1,14.56,700,1,12.43,700,1,14.81,100,1,12.42,700,1,14.96,200,2,ARL,344615393
1753,2025-07-17T16:17:58.235623452Z,2025-07-17T16:17:58.235623452Z,10,2,1108,A,A,8,14.68,700,130,165124,286756143,13.11,100,1,13.79,2,1,13.03,2,1,14.01,100,1,12.98,200,2,14.25,100,1,12.86,100,1,14.35,200,2,12.73,100,1,14.36,100,1,12.71,100,1,14.48,700,1,12.5,700,1,14.54,800,2,12.46,100,1,14.56,700,1,12.43,700,1,14.68,700,1,12.42,700,1,14.81,100,1,ARL,344902153
1754,2025-07-17T16:17:58.502691073Z,2025-07-17T16:17:58.502691073Z,10,2,1108,A,A,6,14.53,100,130,165299,286758830,13.11,100,1,13.79,2,1,13.03,2,1,14.01,100,1,12.98,200,2,14.25,100,1,12.86,100,1,14.35,200,2,12.73,100,1,14.36,100,1,12.71,100,1,14.48,700,1,12.5,700,1,14.53,100,1,12.46,100,1,14.54,800,2,12.43,700,1,14.56,700,1,12.42,700,1,14.68,700,1,ARL,344905321
1755,2025-07-17T16:17:58.502692641Z,2025-07-17T16:17:58.502692641Z,10,2,1108,C,A,1,14.01,100,130,165459,286758831,13.11,100,1,13.79,2,1,13.03,2,1,14.25,100,1,12.98,200,2,14.35,200,2,12.86,100,1,14.36,100,1,12.73,100,1,14.48,700,1,12.71,100,1,14.53,100,1,12.5,700,1,14.54,800,2,12.46,100,1,14.56,700,1,12.43,700,1,14.68,700,1,12.42,700,1,14.81,100,1,ARL,344612049
1756,2025-07-17T16:17:58.704699676Z,2025-07-17T16:17:58.704699676Z,10,2,1108,C,A,3,14.36,100,130,165400,286760091,13.11,100,1,13.79,2,1,13.03,2,1,14.25,100,1,12.98,200,2,14.35,200,2,12.86,100,1,14.48,700,1,12.73,100,1,14.53,100,1,12.71,100,1,14.54,800,2,12.5,700,1,14.56,700,1,12.46,100,1,14.68,700,1,12.43,700,1,14.81,100,1,12.42,700,1,14.96,200,2,ARL,344897953
1757,2025-07-17T16:17:58.705051532Z,2025-07-17T16:17:58.705051532Z,10,2,1108,A,A,7,14.6,100,130,165306,286760096,13.11,100,1,13.79,2,1,13.03,2,1,14.25,100,1,12.98,200,2,14.35,200,2,12.86,100,1,14.48,700,1,12.73,100,1,14.53,100,1,12.71,100,1,14.54,800,2,12.5,700,1,14.56,700,1,12.46,100,1,14.6,100,1,12.43,700,1,14.68,700,1,12.42,700,1,14.81,100,1,ARL,344906945
1758,2025-07-17T16:17:59.086273873Z,2025-07-17T16:17:59.086273873Z,10,2,1108,C,A,5,14.54,100,130,165285,286766349,13.11,100,1,13.79,2,1,13.03,2,1,14.25,100,1,12.98,200,2,14.35,200,2,12.86,100,1,14.48,700,1,12.73,100,1,14.53,100,1,12.71,100,1,14.54,700,1,12.5,700,1,14.56,700,1,12.46,100,1,14.6,100,1,12.43,700,1,14.68,700,1,12.42,700,1,14.81,100,1,ARL,344899913
1759,2025-07-17T16:17:59.086395964Z,2025-07-17T16:17:59.086395964Z,10,2,1108,A,A,9,14.77,100,130,165474,286766355,13.11,100,1,13.79,2,1,13.03,2,1,14.25,100,1,12.98,200,2,14.35,200,2,12.86,100,1,14.48,700,1,12.73,100,1,14.53,100,1,12.71,100,1,14.54,700,1,12.5,700,1,14.56,700,1,12.46,100,1,14.6,100,1,12.43,700,1,14.68,700,1,12.42,700,1,14.77,100,1,ARL,344914361
1760,2025-07-17T16:18:02.178463984Z,2025-07-17T16:18:02.178463984Z,10,2,1108,A,A,1,13.8,100,130,165183,286829047,13.11,100,1,13.79,2,1,13.03,2,1,13.8,100,1,12.98,200,2,14.25,100,1,12.86,100,1,14.35,200,2,12.73,100,1,14.48,700,1,12.71,100,1,14.53,100,1,12.5,700,1,14.54,700,1,12.46,100,1,14.56,700,1,12.43,700,1,14.6,100,1,12.42,700,1,14.68,700,1,ARL,344989393
1761,2025-07-17T16:18:02.181307241Z,2025-07-17T16:18:02.181307241Z,10,2,1108,A,A,10,14.77,100,128,166657,286829106,13.11,100,1,13.79,2,1,13.03,2,1,13.8,100,1,12.98,200,2,14.25,100,1,12.86,100,1,14.35,200,2,12.73,100,1,14.48,700,1,12.71,100,1,14.53,100,1,12.5,700,1,14.54,700,1,12.46,100,1,14.56,700,1,12.43,700,1,14.6,100,1,12.42,700,1,14.68,700,1,ARL,344989525
1762,2025-07-17T16:18:02.184622698Z,2025-07-17T16:18:02.184622698Z,10,2,1108,C,A,2,14.25,100,130,165673,286829173,13.11,100,1,13.79,2,1,13.03,2,1,13.8,100,1,12.98,200,2,14.35,200,2,12.86,100,1,14.48,700,1,12.73,100,1,14.53,100,1,12.71,100,1,14.54,700,1,12.5,700,1,14.56,700,1,12.46,100,1,14.6,100,1,12.43,700,1,14.68,700,1,12.42,700,1,14.77,200,2,ARL,344899417
1763,2025-07-17T16:18:02.184674810Z,2025-07-17T16:18:02.184674810Z,10,2,1108,A,A,2,14.08,100,130,165200,286829174,13.11,100,1,13.79,2,1,13.03,2,1,13.8,100,1,12.98,200,2,14.08,100,1,12.86,100,1,14.35,200,2,12.73,100,1,14.48,700,1,12.71,100,1,14.53,100,1,12.5,700,1,14.54,700,1,12.46,100,1,14.56,700,1,12.43,700,1,14.6,100,1,12.42,700,1,14.68,700,1,ARL,344989601
1764,2025-07-17T16:18:02.186745185Z,2025-07-17T16:18:02.186745185Z,10,2,1108,A,A,8,14.59,100,130,165401,286829206,13.11,100,1,13.79,2,1,13.03,2,1,13.8,100,1,12.98,200,2,14.08,100,1,12.86,100,1,14.35,200,2,12.73,100,1,14.48,700,1,12.71,100,1,14.53,100,1,12.5,700,1,14.54,700,1,12.46,100,1,14.56,700,1,12.43,700,1,14.59,100,1,12.42,700,1,14.6,100,1,ARL,344989661
1765,2025-07-17T16:18:44.836067409Z,2025-07-17T16:18:44.836067409Z,10,2,1108,A,A,0,13.47,15,130,165965,287534438,13.11,100,1,13.47,15,1,13.03,2,1,13.79,2,1,12.98,200,2,13.8,100,1,12.86,100,1,14.08,100,1,12.73,100,1,14.35,200,2,12.71,100,1,14.48,700,1,12.5,700,1,14.53,100,1,12.46,100,1,14.54,700,1,12.43,700,1,14.56,700,1,12.42,700,1,14.59,100,1,ARL,345869437
1766,2025-07-17T16:18:45.977398557Z,2025-07-17T16:18:45.977398557Z,10,2,1108,C,A,2,13.8,100,0,165555,287547865,13.11,100,1,13.47,15,1,13.03,2,1,13.79,2,1,12.98,200,2,14.08,100,1,12.86,100,1,14.35,200,2,12.73,100,1,14.48,700,1,12.71,100,1,14.53,100,1,12.5,700,1,14.54,700,1,12.46,100,1,14.56,700,1,12.43,700,1,14.59,100,1,12.42,700,1,14.6,100,1,ARL,344989393
1767,2025-07-17T16:18:45.977398557Z,2025-07-17T16:18:45.977398557Z,10,2,1108,A,A,1,13.48,100,130,165555,287547865,13.11,100,1,13.47,15,1,13.03,2,1,13.48,100,1,12.98,200,2,13.79,2,1,12.86,100,1,14.08,100,1,12.73,100,1,14.35,200,2,12.71,100,1,14.48,700,1,12.5,700,1,14.53,100,1,12.46,100,1,14.54,700,1,12.43,700,1,14.56,700,1,12.42,700,1,14.59,100,1,ARL,345889137
1768,2025-07-17T16:18:45.978141738Z,2025-07-17T16:18:45.978141738Z,10,2,1108,A,A,6,14.53,100,130,165463,287547871,13.11,100,1,13.47,15,1,13.03,2,1,13.48,100,1,12.98,200,2,13.79,2,1,12.86,100,1,14.08,100,1,12.73,100,1,14.35,200,2,12.71,100,1,14.48,700,1,12.5,700,1,14.53,200,2,12.46,100,1,14.54,700,1,12.43,700,1,14.56,700,1,12.42,700,1,14.59,100,1,ARL,345889161
1769,2025-07-17T16:18:45.978493799Z,2025-07-17T16:18:45.978493799Z,10,2,1108,A,A,3,14.08,100,130,165257,287547872,13.11,100,1,13.47,15,1,13.03,2,1,13.48,100,1,12.98,200,2,13.79,2,1,12.86,100,1,14.08,200,2,12.73,100,1,14.35,200,2,12.71,100,1,14.48,700,1,12.5,700,1,14.53,200,2,12.46,100,1,14.54,700,1,12.43,700,1,14.56,700,1,12.42,700,1,14.59,100,1,ARL,345889165
1770,2025-07-17T16:18:45.979287575Z,2025-07-17T16:18:45.979287575Z,10,2,1108,A,A,5,14.43,100,130,165448,287547885,13.11,100,1,13.47,15,1,13.03,2,1,13.48,100,1,12.98,200,2,13.79,2,1,12.86,100,1,14.08,200,2,12.73,100,1,14.35,200,2,12.71,100,1,14.43,100,1,12.5,700,1,14.48,700,1,12.46,100,1,14.53,200,2,12.43,700,1,14.54,700,1,12.42,700,1,14.56,700,1,ARL,345889189
1771,2025-07-17T16:18:45.979972220Z,2025-07-17T16:18:45.979972220Z,10,2,1108,A,A,5,14.43,100,130,165615,287547890,13.11,100,1,13.47,15,1,13.03,2,1,13.48,100,1,12.98,200,2,13.79,2,1,12.86,100,1,14.08,200,2,12.73,100,1,14.35,200,2,12.71,100,1,14.43,200,2,12.5,700,1,14.48,700,1,12.46,100,1,14.53,200,2,12.43,700,1,14.54,700,1,12.42,700,1,14.56,700,1,ARL,345889201
1772,2025-07-17T16:18:45.982933040Z,2025-07-17T16:18:45.982933040Z,10,2,1108,A,A,4,14.27,100,130,165564,287547921,13.11,100,1,13.47,15,1,13.03,2,1,13.48,100,1,12.98,200,2,13.79,2,1,12.86,100,1,14.08,200,2,12.73,100,1,14.27,100,1,12.71,100,1,14.35,200,2,12.5,700,1,14.43,200,2,12.46,100,1,14.48,700,1,12.43,700,1,14.53,200,2,12.42,700,1,14.54,700,1,ARL,345889277
1773,2025-07-17T16:18:45.994141218Z,2025-07-17T16:18:45.994141218Z,10,2,1108,C,A,3,14.08,100,130,165379,287548000,13.11,100,1,13.47,15,1,13.03,2,1,13.48,100,1,12.98,200,2,13.79,2,1,12.86,100,1,14.08,100,1,12.73,100,1,14.27,100,1,12.71,100,1,14.35,200,2,12.5,700,1,14.43,200,2,12.46,100,1,14.48,700,1,12.43,700,1,14.53,200,2,12.42,700,1,14.54,700,1,ARL,344989601
1774,2025-07-17T16:18:45.994191684Z,2025-07-17T16:18:45.994191684Z,10,2,1108,A,A,2,13.75,100,130,165299,287548002,13.11,100,1,13.47,15,1,13.03,2,1,13.48,100,1,12.98,200,2,13.75,100,1,12.86,100,1,13.79,2,1,12.73,100,1,14.08,100,1,12.71,100,1,14.27,100,1,12.5,700,1,14.35,200,2,12.46,100,1,14.43,200,2,12.43,700,1,14.48,700,1,12.42,700,1,14.53,200,2,ARL,345889457
1775,2025-07-17T16:18:46.583636828Z,2025-07-17T16:18:46.583636828Z,10,2,1108,A,A,6,14.28,100,130,165348,287559115,13.11,100,1,13.47,15,1,13.03,2,1,13.48,100,1,12.98,200,2,13.75,100,1,12.86,100,1,13.79,2,1,12.73,100,1,14.08,100,1,12.71,100,1,14.27,100,1,12.5,700,1,14.28,100,1,12.46,100,1,14.35,200,2,12.43,700,1,14.43,200,2,12.42,700,1,14.48,700,1,ARL,345903265
1776,2025-07-17T16:18:46.972689989Z,2025-07-17T16:18:46.972689989Z,10,2,1108,A,A,4,14.01,100,130,165259,287565225,13.11,100,1,13.47,15,1,13.03,2,1,13.48,100,1,12.98,200,2,13.75,100,1,12.86,100,1,13.79,2,1,12.73,100,1,14.01,100,1,12.71,100,1,14.08,100,1,12.5,700,1,14.27,100,1,12.46,100,1,14.28,100,1,12.43,700,1,14.35,200,2,12.42,700,1,14.43,200,2,ARL,345911213
1777,2025-07-17T16:18:47.836002486Z,2025-07-17T16:18:47.836002486Z,10,2,1108,A,A,0,13.45,15,130,165346,287577128,13.11,100,1,13.45,15,1,13.03,2,1,13.47,15,1,12.98,200,2,13.48,100,1,12.86,100,1,13.75,100,1,12.73,100,1,13.79,2,1,12.71,100,1,14.01,100,1,12.5,700,1,14.08,100,1,12.46,100,1,14.27,100,1,12.43,700,1,14.28,100,1,12.42,700,1,14.35,200,2,ARL,345924181
1778,2025-07-17T16:18:47.956070064Z,2025-07-17T16:18:47.956070064Z,10,2,1108,C,A,2,13.48,100,0,166415,287579474,13.11,100,1,13.45,15,1,13.03,2,1,13.47,15,1,12.98,200,2,13.75,100,1,12.86,100,1,13.79,2,1,12.73,100,1,14.01,100,1,12.71,100,1,14.08,100,1,12.5,700,1,14.27,100,1,12.46,100,1,14.28,100,1,12.43,700,1,14.35,200,2,12.42,700,1,14.43,200,2,ARL,345889137
1779,2025-07-17T16:18:47.956070064Z,2025-07-17T16:18:47.956070064Z,10,2,1108,A,A,1,13.46,100,130,166415,287579474,13.11,100,1,13.45,15,1,13.03,2,1,13.46,100,1,12.98,200,2,13.47,15,1,12.86,100,1,13.75,100,1,12.73,100,1,13.79,2,1,12.71,100,1,14.01,100,1,12.5,700,1,14.08,100,1,12.46,100,1,14.27,100,1,12.43,700,1,14.28,100,1,12.42,700,1,14.35,200,2,ARL,345926413
1780,2025-07-17T16:18:51.228274415Z,2025-07-17T16:18:51.228274415Z,10,2,1108,A,A,7,14.18,700,130,165223,287639434,13.11,100,1,13.45,15,1,13.03,2,1,13.46,100,1,12.98,200,2,13.47,15,1,12.86,100,1,13.75,100,1,12.73,100,1,13.79,2,1,12.71,100,1,14.01,100,1,12.5,700,1,14.08,100,1,12.46,100,1,14.18,700,1,12.43,700,1,14.27,100,1,12.42,700,1,14.28,100,1,ARL,345998433
1781,2025-07-17T16:18:57.882196648Z,2025-07-17T16:18:57.882196648Z,10,2,1108,C,A,2,13.47,15,128,168809,287807679,13.11,100,1,13.45,15,1,13.03,2,1,13.46,100,1,12.98,200,2,13.75,100,1,12.86,100,1,13.79,2,1,12.73,100,1,14.01,100,1,12.71,100,1,14.08,100,1,12.5,700,1,14.18,700,1,12.46,100,1,14.27,100,1,12.43,700,1,14.28,100,1,12.42,700,1,14.35,200,2,ARL,345869437
1782,2025-07-17T16:19:04.990724544Z,2025-07-17T16:19:04.990724544Z,10,2,1108,C,A,3,13.79,2,0,165558,288025773,13.11,100,1,13.45,15,1,13.03,2,1,13.46,100,1,12.98,200,2,13.75,100,1,12.86,100,1,14.01,100,1,12.73,100,1,14.08,100,1,12.71,100,1,14.18,700,1,12.5,700,1,14.27,100,1,12.46,100,1,14.28,100,1,12.43,700,1,14.35,200,2,12.42,700,1,14.43,200,2,ARL,344765077
1783,2025-07-17T16:19:04.990724544Z,2025-07-17T16:19:04.990724544Z,10,2,1108,A,A,2,13.72,2,130,165558,288025773,13.11,100,1,13.45,15,1,13.03,2,1,13.46,100,1,12.98,200,2,13.72,2,1,12.86,100,1,13.75,100,1,12.73,100,1,14.01,100,1,12.71,100,1,14.08,100,1,12.5,700,1,14.18,700,1,12.46,100,1,14.27,100,1,12.43,700,1,14.28,100,1,12.42,700,1,14.35,200,2,ARL,346423105
1784,2025-07-17T16:19:08.837120837Z,2025-07-17T16:19:08.837120837Z,10,2,1108,A,A,0,13.43,15,130,165356,288088546,13.11,100,1,13.43,15,1,13.03,2,1,13.45,15,1,12.98,200,2,13.46,100,1,12.86,100,1,13.72,2,1,12.73,100,1,13.75,100,1,12.71,100,1,14.01,100,1,12.5,700,1,14.08,100,1,12.46,100,1,14.18,700,1,12.43,700,1,14.27,100,1,12.42,700,1,14.28,100,1,ARL,346492493
1785,2025-07-17T16:19:11.008187551Z,2025-07-17T16:19:11.008187551Z,10,2,1108,C,A,2,13.46,100,0,165651,288143215,13.11,100,1,13.43,15,1,13.03,2,1,13.45,15,1,12.98,200,2,13.72,2,1,12.86,100,1,13.75,100,1,12.73,100,1,14.01,100,1,12.71,100,1,14.08,100,1,12.5,700,1,14.18,700,1,12.46,100,1,14.27,100,1,12.43,700,1,14.28,100,1,12.42,700,1,14.35,200,2,ARL,345926413
1786,2025-07-17T16:19:11.008187551Z,2025-07-17T16:19:11.008187551Z,10,2,1108,A,A,1,13.44,100,130,165651,288143215,13.11,100,1,13.43,15,1,13.03,2,1,13.44,100,1,12.98,200,2,13.45,15,1,12.86,100,1,13.72,2,1,12.73,100,1,13.75,100,1,12.71,100,1,14.01,100,1,12.5,700,1,14.08,100,1,12.46,100,1,14.18,700,1,12.43,700,1,14.27,100,1,12.42,700,1,14.28,100,1,ARL,346562289
1787,2025-07-17T16:19:20.837342130Z,2025-07-17T16:19:20.837342130Z,10,2,1108,C,A,2,13.45,15,130,165776,288310746,13.11,100,1,13.43,15,1,13.03,2,1,13.44,100,1,12.98,200,2,13.72,2,1,12.86,100,1,13.75,100,1,12.73,100,1,14.01,100,1,12.71,100,1,14.08,100,1,12.5,700,1,14.18,700,1,12.46,100,1,14.27,100,1,12.43,700,1,14.28,100,1,12.42,700,1,14.35,200,2,ARL,345924181
1788,2025-07-17T16:19:26.653909048Z,2025-07-17T16:19:26.653909048Z,10,2,1108,A,A,0,13.41,15,128,166024,288411319,13.11,100,1,13.41,15,1,13.03,2,1,13.43,15,1,12.98,200,2,13.44,100,1,12.86,100,1,13.72,2,1,12.73,100,1,13.75,100,1,12.71,100,1,14.01,100,1,12.5,700,1,14.08,100,1,12.46,100,1,14.18,700,1,12.43,700,1,14.27,100,1,12.42,700,1,14.28,100,1,ARL,346891037
1789,2025-07-17T16:19:27.200430092Z,2025-07-17T16:19:27.200430092Z,10,2,1108,C,A,2,13.44,100,0,165904,288424564,13.11,100,1,13.41,15,1,13.03,2,1,13.43,15,1,12.98,200,2,13.72,2,1,12.86,100,1,13.75,100,1,12.73,100,1,14.01,100,1,12.71,100,1,14.08,100,1,12.5,700,1,14.18,700,1,12.46,100,1,14.27,100,1,12.43,700,1,14.28,100,1,12.42,700,1,14.35,200,2,ARL,346562289
1790,2025-07-17T16:19:27.200430092Z,2025-07-17T16:19:27.200430092Z,10,2,1108,A,A,1,13.42,100,130,165904,288424564,13.11,100,1,13.41,15,1,13.03,2,1,13.42,100,1,12.98,200,2,13.43,15,1,12.86,100,1,13.72,2,1,12.73,100,1,13.75,100,1,12.71,100,1,14.01,100,1,12.5,700,1,14.08,100,1,12.46,100,1,14.18,700,1,12.43,700,1,14.27,100,1,12.42,700,1,14.28,100,1,ARL,346904153
1791,2025-07-17T16:19:27.201212584Z,2025-07-17T16:19:27.201212584Z,10,2,1108,A,A,8,14.19,700,130,165665,288424582,13.11,100,1,13.41,15,1,13.03,2,1,13.42,100,1,12.98,200,2,13.43,15,1,12.86,100,1,13.72,2,1,12.73,100,1,13.75,100,1,12.71,100,1,14.01,100,1,12.5,700,1,14.08,100,1,12.46,100,1,14.18,700,1,12.43,700,1,14.19,700,1,12.42,700,1,14.27,100,1,ARL,346904221
1792,2025-07-17T16:19:28.991142567Z,2025-07-17T16:19:28.991142567Z,10,2,1108,C,B,1,13.03,2,0,165660,288452523,13.11,100,1,13.41,15,1,12.98,200,2,13.42,100,1,12.86,100,1,13.43,15,1,12.73,100,1,13.72,2,1,12.71,100,1,13.75,100,1,12.5,700,1,14.01,100,1,12.46,100,1,14.08,100,1,12.43,700,1,14.18,700,1,12.42,700,1,14.19,700,1,12.37,700,1,14.27,100,1,ARL,343084165
1793,2025-07-17T16:19:28.991142567Z,2025-07-17T16:19:28.991142567Z,10,2,1108,A,B,2,12.95,2,130,165660,288452523,13.11,100,1,13.41,15,1,12.98,200,2,13.42,100,1,12.95,2,1,13.43,15,1,12.86,100,1,13.72,2,1,12.73,100,1,13.75,100,1,12.71,100,1,14.01,100,1,12.5,700,1,14.08,100,1,12.46,100,1,14.18,700,1,12.43,700,1,14.19,700,1,12.42,700,1,14.27,100,1,ARL,346942181
1794,2025-07-17T16:19:30.834293908Z,2025-07-17T16:19:30.834293908Z,10,2,1108,C,A,0,13.41,15,130,165376,288478995,13.11,100,1,13.42,100,1,12.98,200,2,13.43,15,1,12.95,2,1,13.72,2,1,12.86,100,1,13.75,100,1,12.73,100,1,14.01,100,1,12.71,100,1,14.08,100,1,12.5,700,1,14.18,700,1,12.46,100,1,14.19,700,1,12.43,700,1,14.27,100,1,12.42,700,1,14.28,100,1,ARL,346891037
1795,2025-07-17T16:19:30.834842536Z,2025-07-17T16:19:30.834842536Z,10,2,1108,C,A,0,13.42,100,130,165486,288479015,13.11,100,1,13.43,15,1,12.98,200,2,13.72,2,1,12.95,2,1,13.75,100,1,12.86,100,1,14.01,100,1,12.73,100,1,14.08,100,1,12.71,100,1,14.18,700,1,12.5,700,1,14.19,700,1,12.46,100,1,14.27,100,1,12.43,700,1,14.28,100,1,12.42,700,1,14.35,200,2,ARL,346904153
1796,2025-07-17T16:19:30.835403659Z,2025-07-17T16:19:30.835403659Z,10,2,1108,C,A,0,13.43,15,130,165413,288479032,13.11,100,1,13.72,2,1,12.98,200,2,13.75,100,1,12.95,2,1,14.01,100,1,12.86,100,1,14.08,100,1,12.73,100,1,14.18,700,1,12.71,100,1,14.19,700,1,12.5,700,1,14.27,100,1,12.46,100,1,14.28,100,1,12.43,700,1,14.35,200,2,12.42,700,1,14.43,200,2,ARL,346492493
1797,2025-07-17T16:19:32.547320695Z,2025-07-17T16:19:32.547320695Z,10,2,1108,C,A,4,14.18,700,130,166488,288512762,13.11,100,1,13.72,2,1,12.98,200,2,13.75,100,1,12.95,2,1,14.01,100,1,12.86,100,1,14.08,100,1,12.73,100,1,14.19,700,1,12.71,100,1,14.27,100,1,12.5,700,1,14.28,100,1,12.46,100,1,14.35,200,2,12.43,700,1,14.43,200,2,12.42,700,1,14.48,800,2,ARL,345998433
1798,2025-07-17T16:19:32.547362298Z,2025-07-17T16:19:32.547362298Z,10,2,1108,A,A,9,14.44,700,130,165328,288512763,13.11,100,1,13.72,2,1,12.98,200,2,13.75,100,1,12.95,2,1,14.01,100,1,12.86,100,1,14.08,100,1,12.73,100,1,14.19,700,1,12.71,100,1,14.27,100,1,12.5,700,1,14.28,100,1,12.46,100,1,14.35,200,2,12.43,700,1,14.43,200,2,12.42,700,1,14.44,700,1,ARL,347022701
1799,2025-07-17T16:19:32.547904024Z,2025-07-17T16:19:32.547904024Z,10,2,1108,C,A,3,14.08,100,130,165181,288512768,13.11,100,1,13.72,2,1,12.98,200,2,13.75,100,1,12.95,2,1,14.01,100,1,12.86,100,1,14.19,700,1,12.73,100,1,14.27,100,1,12.71,100,1,14.28,100,1,12.5,700,1,14.35,200,2,12.46,100,1,14.43,200,2,12.43,700,1,14.44,700,1,12.42,700,1,14.48,800,2,ARL,345889165
1800,2025-07-17T16:19:32.547930966Z,2025-07-17T16:19:32.547930966Z,10,2,1108,C,A,3,14.19,700,130,165272,288512769,13.11,100,1,13.72,2,1,12.98,200,2,13.75,100,1,12.95,2,1,14.01,100,1,12.86,100,1,14.27,100,1,12.73,100,1,14.28,100,1,12.71,100,1,14.35,200,2,12.5,700,1,14.43,200,2,12.46,100,1,14.44,700,1,12.43,700,1,14.48,800,2,12.42,700,1,14.54,700,1,ARL,346904221
1801,2025-07-17T16:19:32.547947865Z,2025-07-17T16:19:32.547947865Z,10,2,1108,C,A,8,14.48,100,0,165684,288512770,13.11,100,1,13.72,2,1,12.98,200,2,13.75,100,1,12.95,2,1,14.01,100,1,12.86,100,1,14.27,100,1,12.73,100,1,14.28,100,1,12.71,100,1,14.35,200,2,12.5,700,1,14.43,200,2,12.46,100,1,14.44,700,1,12.43,700,1,14.48,700,1,12.42,700,1,14.54,700,1,ARL,346562329
1802,2025-07-17T16:19:32.547947865Z,2025-07-17T16:19:32.547947865Z,10,2,1108,A,A,10,14.82,100,130,165684,288512770,13.11,100,1,13.72,2,1,12.98,200,2,13.75,100,1,12.95,2,1,14.01,100,1,12.86,100,1,14.27,100,1,12.73,100,1,14.28,100,1,12.71,100,1,14.35,200,2,12.5,700,1,14.43,200,2,12.46,100,1,14.44,700,1,12.43,700,1,14.48,700,1,12.42,700,1,14.54,700,1,ARL,347022737
1803,2025-07-17T16:19:32.548258519Z,2025-07-17T16:19:32.548258519Z,10,2,1108,A,A,6,14.36,100,130,165386,288512772,13.11,100,1,13.72,2,1,12.98,200,2,13.75,100,1,12.95,2,1,14.01,100,1,12.86,100,1,14.27,100,1,12.73,100,1,14.28,100,1,12.71,100,1,14.35,200,2,12.5,700,1,14.36,100,1,12.46,100,1,14.43,200,2,12.43,700,1,14.44,700,1,12.42,700,1,14.48,700,1,ARL,347022741
1804,2025-07-17T16:19:32.548338068Z,2025-07-17T16:19:32.548338068Z,10,2,1108,A,A,9,14.48,700,130,165654,288512773,13.11,100,1,13.72,2,1,12.98,200,2,13.75,100,1,12.95,2,1,14.01,100,1,12.86,100,1,14.27,100,1,12.73,100,1,14.28,100,1,12.71,100,1,14.35,200,2,12.5,700,1,14.36,100,1,12.46,100,1,14.43,200,2,12.43,700,1,14.44,700,1,12.42,700,1,14.48,1400,2,ARL,347022749
1805,2025-07-17T16:19:32.549001387Z,2025-07-17T16:19:32.549001387Z,10,2,1108,C,A,3,14.27,100,0,165365,288512787,13.11,100,1,13.72,2,1,12.98,200,2,13.75,100,1,12.95,2,1,14.01,100,1,12.86,100,1,14.28,100,1,12.73,100,1,14.35,200,2,12.71,100,1,14.36,100,1,12.5,700,1,14.43,200,2,12.46,100,1,14.44,700,1,12.43,700,1,14.48,1400,2,12.42,700,1,14.54,700,1,ARL,345889277
1806,2025-07-17T16:19:32.549001387Z,2025-07-17T16:19:32.549001387Z,10,2,1108,A,A,9,14.54,100,130,165365,288512787,13.11,100,1,13.72,2,1,12.98,200,2,13.75,100,1,12.95,2,1,14.01,100,1,12.86,100,1,14.28,100,1,12.73,100,1,14.35,200,2,12.71,100,1,14.36,100,1,12.5,700,1,14.43,200,2,12.46,100,1,14.44,700,1,12.43,700,1,14.48,1400,2,12.42,700,1,14.54,800,2,ARL,347022789
1807,2025-07-17T16:19:32.549267465Z,2025-07-17T16:19:32.549267465Z,10,2,1108,C,A,6,14.43,100,0,165769,288512789,13.11,100,1,13.72,2,1,12.98,200,2,13.75,100,1,12.95,2,1,14.01,100,1,12.86,100,1,14.28,100,1,12.73,100,1,14.35,200,2,12.71,100,1,14.36,100,1,12.5,700,1,14.43,100,1,12.46,100,1,14.44,700,1,12.43,700,1,14.48,1400,2,12.42,700,1,14.54,800,2,ARL,345889201
1808,2025-07-17T16:19:32.549267465Z,2025-07-17T16:19:32.549267465Z,10,2,1108,A,A,10,14.72,100,130,165769,288512789,13.11,100,1,13.72,2,1,12.98,200,2,13.75,100,1,12.95,2,1,14.01,100,1,12.86,100,1,14.28,100,1,12.73,100,1,14.35,200,2,12.71,100,1,14.36,100,1,12.5,700,1,14.43,100,1,12.46,100,1,14.44,700,1,12.43,700,1,14.48,1400,2,12.42,700,1,14.54,800,2,ARL,347022797
1809,2025-07-17T16:19:32.554398971Z,2025-07-17T16:19:32.554398971Z,10,2,1108,C,A,6,14.43,100,0,165578,288512857,13.11,100,1,13.72,2,1,12.98,200,2,13.75,100,1,12.95,2,1,14.01,100,1,12.86,100,1,14.28,100,1,12.73,100,1,14.35,200,2,12.71,100,1,14.36,100,1,12.5,700,1,14.44,700,1,12.46,100,1,14.48,1400,2,12.43,700,1,14.54,800,2,12.42,700,1,14.72,100,1,ARL,345889189
1810,2025-07-17T16:19:32.554398971Z,2025-07-17T16:19:32.554398971Z,10,2,1108,A,A,9,14.72,100,130,165578,288512857,13.11,100,1,13.72,2,1,12.98,200,2,13.75,100,1,12.95,2,1,14.01,100,1,12.86,100,1,14.28,100,1,12.73,100,1,14.35,200,2,12.71,100,1,14.36,100,1,12.5,700,1,14.44,700,1,12.46,100,1,14.48,1400,2,12.43,700,1,14.54,800,2,12.42,700,1,14.72,200,2,ARL,347022893
1811,2025-07-17T16:19:32.565975313Z,2025-07-17T16:19:32.565975313Z,10,2,1108,C,A,1,13.75,100,130,165381,288512959,13.11,100,1,13.72,2,1,12.98,200,2,14.01,100,1,12.95,2,1,14.28,100,1,12.86,100,1,14.35,200,2,12.73,100,1,14.36,100,1,12.71,100,1,14.44,700,1,12.5,700,1,14.48,1400,2,12.46,100,1,14.54,800,2,12.43,700,1,14.72,200,2,12.42,700,1,14.82,100,1,ARL,345889457
1812,2025-07-17T16:19:32.566009468Z,2025-07-17T16:19:32.566009468Z,10,2,1108,C,A,5,14.44,700,130,164912,288512961,13.11,100,1,13.72,2,1,12.98,200,2,14.01,100,1,12.95,2,1,14.28,100,1,12.86,100,1,14.35,200,2,12.73,100,1,14.36,100,1,12.71,100,1,14.48,1400,2,12.5,700,1,14.54,800,2,12.46,100,1,14.72,200,2,12.43,700,1,14.82,100,1,12.42,700,1,15.13,200,2,ARL,347022701
1813,2025-07-17T16:19:32.566028302Z,2025-07-17T16:19:32.566028302Z,10,2,1108,A,A,2,14.03,100,130,165564,288512962,13.11,100,1,13.72,2,1,12.98,200,2,14.01,100,1,12.95,2,1,14.03,100,1,12.86,100,1,14.28,100,1,12.73,100,1,14.35,200,2,12.71,100,1,14.36,100,1,12.5,700,1,14.48,1400,2,12.46,100,1,14.54,800,2,12.43,700,1,14.72,200,2,12.42,700,1,14.82,100,1,ARL,347023005
1814,2025-07-17T16:19:32.566882768Z,2025-07-17T16:19:32.566882768Z,10,2,1108,C,A,8,14.72,100,0,165392,288512963,13.11,100,1,13.72,2,1,12.98,200,2,14.01,100,1,12.95,2,1,14.03,100,1,12.86,100,1,14.28,100,1,12.73,100,1,14.35,200,2,12.71,100,1,14.36,100,1,12.5,700,1,14.48,1400,2,12.46,100,1,14.54,800,2,12.43,700,1,14.72,100,1,12.42,700,1,14.82,100,1,ARL,347022893
1815,2025-07-17T16:19:32.566882768Z,2025-07-17T16:19:32.566882768Z,10,2,1108,A,A,10,14.95,100,130,165392,288512963,13.11,100,1,13.72,2,1,12.98,200,2,14.01,100,1,12.95,2,1,14.03,100,1,12.86,100,1,14.28,100,1,12.73,100,1,14.35,200,2,12.71,100,1,14.36,100,1,12.5,700,1,14.48,1400,2,12.46,100,1,14.54,800,2,12.43,700,1,14.72,100,1,12.42,700,1,14.82,100,1,ARL,347023021
1816,2025-07-17T16:19:32.567816385Z,2025-07-17T16:19:32.567816385Z,10,2,1108,C,A,8,14.72,100,0,165283,288512969,13.11,100,1,13.72,2,1,12.98,200,2,14.01,100,1,12.95,2,1,14.03,100,1,12.86,100,1,14.28,100,1,12.73,100,1,14.35,200,2,12.71,100,1,14.36,100,1,12.5,700,1,14.48,1400,2,12.46,100,1,14.54,800,2,12.43,700,1,14.82,100,1,12.42,700,1,14.95,100,1,ARL,347022797
1817,2025-07-17T16:19:32.567816385Z,2025-07-17T16:19:32.567816385Z,10,2,1108,A,A,10,14.96,100,130,165283,288512969,13.11,100,1,13.72,2,1,12.98,200,2,14.01,100,1,12.95,2,1,14.03,100,1,12.86,100,1,14.28,100,1,12.73,100,1,14.35,200,2,12.71,100,1,14.36,100,1,12.5,700,1,14.48,1400,2,12.46,100,1,14.54,800,2,12.43,700,1,14.82,100,1,12.42,700,1,14.95,100,1,ARL,347023045
1818,2025-07-17T16:19:32.568611131Z,2025-07-17T16:19:32.568611131Z,10,2,1108,C,A,0,13.72,2,0,165544,288512974,13.11,100,1,14.01,100,1,12.98,200,2,14.03,100,1,12.95,2,1,14.28,100,1,12.86,100,1,14.35,200,2,12.73,100,1,14.36,100,1,12.71,100,1,14.48,1400,2,12.5,700,1,14.54,800,2,12.46,100,1,14.82,100,1,12.43,700,1,14.95,100,1,12.42,700,1,14.96,100,1,ARL,346423105
1819,2025-07-17T16:19:32.568611131Z,2025-07-17T16:19:32.568611131Z,10,2,1108,A,A,0,13.98,2,130,165544,288512974,13.11,100,1,13.98,2,1,12.98,200,2,14.01,100,1,12.95,2,1,14.03,100,1,12.86,100,1,14.28,100,1,12.73,100,1,14.35,200,2,12.71,100,1,14.36,100,1,12.5,700,1,14.48,1400,2,12.46,100,1,14.54,800,2,12.43,700,1,14.82,100,1,12.42,700,1,14.95,100,1,ARL,347023061
1820,2025-07-17T16:19:32.586617069Z,2025-07-17T16:19:32.586617069Z,10,2,1108,C,A,2,14.03,100,130,165093,288513024,13.11,100,1,13.98,2,1,12.98,200,2,14.01,100,1,12.95,2,1,14.28,100,1,12.86,100,1,14.35,200,2,12.73,100,1,14.36,100,1,12.71,100,1,14.48,1400,2,12.5,700,1,14.54,800,2,12.46,100,1,14.82,100,1,12.43,700,1,14.95,100,1,12.42,700,1,14.96,100,1,ARL,347023005
1821,2025-07-17T16:19:32.586666869Z,2025-07-17T16:19:32.586666869Z,10,2,1108,A,A,2,14.25,100,130,165204,288513026,13.11,100,1,13.98,2,1,12.98,200,2,14.01,100,1,12.95,2,1,14.25,100,1,12.86,100,1,14.28,100,1,12.73,100,1,14.35,200,2,12.71,100,1,14.36,100,1,12.5,700,1,14.48,1400,2,12.46,100,1,14.54,800,2,12.43,700,1,14.82,100,1,12.42,700,1,14.95,100,1,ARL,347023197
1822,2025-07-17T16:19:32.597793442Z,2025-07-17T16:19:32.597793442Z,10,2,1108,C,A,8,14.82,100,0,165397,288513278,13.11,100,1,13.98,2,1,12.98,200,2,14.01,100,1,12.95,2,1,14.25,100,1,12.86,100,1,14.28,100,1,12.73,100,1,14.35,200,2,12.71,100,1,14.36,100,1,12.5,700,1,14.48,1400,2,12.46,100,1,14.54,800,2,12.43,700,1,14.95,100,1,12.42,700,1,14.96,100,1,ARL,347022737
1823,2025-07-17T16:19:32.597793442Z,2025-07-17T16:19:32.597793442Z,10,2,1108,A,A,10,15.05,100,130,165397,288513278,13.11,100,1,13.98,2,1,12.98,200,2,14.01,100,1,12.95,2,1,14.25,100,1,12.86,100,1,14.28,100,1,12.73,100,1,14.35,200,2,12.71,100,1,14.36,100,1,12.5,700,1,14.48,1400,2,12.46,100,1,14.54,800,2,12.43,700,1,14.95,100,1,12.42,700,1,14.96,100,1,ARL,347023333
1824,2025-07-17T16:19:32.602282571Z,2025-07-17T16:19:32.602282571Z,10,2,1108,A,A,8,14.68,700,130,165270,288513328,13.11,100,1,13.98,2,1,12.98,200,2,14.01,100,1,12.95,2,1,14.25,100,1,12.86,100,1,14.28,100,1,12.73,100,1,14.35,200,2,12.71,100,1,14.36,100,1,12.5,700,1,14.48,1400,2,12.46,100,1,14.54,800,2,12.43,700,1,14.68,700,1,12.42,700,1,14.95,100,1,ARL,347023357
1825,2025-07-17T16:19:32.706057444Z,2025-07-17T16:19:32.706057444Z,10,2,1108,A,A,7,14.53,100,0,166378,288514904,13.11,100,1,13.98,2,1,12.98,200,2,14.01,100,1,12.95,2,1,14.25,100,1,12.86,100,1,14.28,100,1,12.73,100,1,14.35,200,2,12.71,100,1,14.36,100,1,12.5,700,1,14.48,1400,2,12.46,100,1,14.53,100,1,12.43,700,1,14.54,800,2,12.42,700,1,14.68,700,1,ARL,347025333
1826,2025-07-17T16:19:32.706057831Z,2025-07-17T16:19:32.706057831Z,10,2,1108,C,A,1,14.01,100,130,165991,288514905,13.11,100,1,13.98,2,1,12.98,200,2,14.25,100,1,12.95,2,1,14.28,100,1,12.86,100,1,14.35,200,2,12.73,100,1,14.36,100,1,12.71,100,1,14.48,1400,2,12.5,700,1,14.53,100,1,12.46,100,1,14.54,800,2,12.43,700,1,14.68,700,1,12.42,700,1,14.95,100,1,ARL,345911213
1827,2025-07-17T16:19:32.857621837Z,2025-07-17T16:19:32.857621837Z,10,2,1108,A,A,9,14.81,100,130,165462,288516573,13.11,100,1,13.98,2,1,12.98,200,2,14.25,100,1,12.95,2,1,14.28,100,1,12.86,100,1,14.35,200,2,12.73,100,1,14.36,100,1,12.71,100,1,14.48,1400,2,12.5,700,1,14.53,100,1,12.46,100,1,14.54,800,2,12.43,700,1,14.68,700,1,12.42,700,1,14.81,100,1,ARL,347027121
1828,2025-07-17T16:19:32.857638959Z,2025-07-17T16:19:32.857638959Z,10,2,1108,C,A,2,14.28,100,130,165276,288516574,13.11,100,1,13.98,2,1,12.98,200,2,14.25,100,1,12.95,2,1,14.35,200,2,12.86,100,1,14.36,100,1,12.73,100,1,14.48,1400,2,12.71,100,1,14.53,100,1,12.5,700,1,14.54,800,2,12.46,100,1,14.68,700,1,12.43,700,1,14.81,100,1,12.42,700,1,14.95,100,1,ARL,345903265
1829,2025-07-17T16:19:32.886893433Z,2025-07-17T16:19:32.886893433Z,10,2,1108,A,A,1,13.99,100,130,165315,288519618,13.11,100,1,13.98,2,1,12.98,200,2,13.99,100,1,12.95,2,1,14.25,100,1,12.86,100,1,14.35,200,2,12.73,100,1,14.36,100,1,12.71,100,1,14.48,1400,2,12.5,700,1,14.53,100,1,12.46,100,1,14.54,800,2,12.43,700,1,14.68,700,1,12.42,700,1,14.81,100,1,ARL,347030085
1830,2025-07-17T16:19:33.241195095Z,2025-07-17T16:19:33.241195095Z,10,2,1108,C,A,4,14.36,100,130,165450,288533108,13.11,100,1,13.98,2,1,12.98,200,2,13.99,100,1,12.95,2,1,14.25,100,1,12.86,100,1,14.35,200,2,12.73,100,1,14.48,1400,2,12.71,100,1,14.53,100,1,12.5,700,1,14.54,800,2,12.46,100,1,14.68,700,1,12.43,700,1,14.81,100,1,12.42,700,1,14.95,100,1,ARL,347022741
1831,2025-07-17T16:19:33.241548838Z,2025-07-17T16:19:33.241548838Z,10,2,1108,A,A,7,14.6,100,130,165448,288533114,13.11,100,1,13.98,2,1,12.98,200,2,13.99,100,1,12.95,2,1,14.25,100,1,12.86,100,1,14.35,200,2,12.73,100,1,14.48,1400,2,12.71,100,1,14.53,100,1,12.5,700,1,14.54,800,2,12.46,100,1,14.6,100,1,12.43,700,1,14.68,700,1,12.42,700,1,14.81,100,1,ARL,347045237
1832,2025-07-17T16:19:33.550277249Z,2025-07-17T16:19:33.550277249Z,10,2,1108,C,A,6,14.54,100,130,165973,288537856,13.11,100,1,13.98,2,1,12.98,200,2,13.99,100,1,12.95,2,1,14.25,100,1,12.86,100,1,14.35,200,2,12.73,100,1,14.48,1400,2,12.71,100,1,14.53,100,1,12.5,700,1,14.54,700,1,12.46,100,1,14.6,100,1,12.43,700,1,14.68,700,1,12.42,700,1,14.81,100,1,ARL,347022789
1833,2025-07-17T16:19:33.550465490Z,2025-07-17T16:19:33.550465490Z,10,2,1108,A,A,9,14.77,100,130,165169,288537857,13.11,100,1,13.98,2,1,12.98,200,2,13.99,100,1,12.95,2,1,14.25,100,1,12.86,100,1,14.35,200,2,12.73,100,1,14.48,1400,2,12.71,100,1,14.53,100,1,12.5,700,1,14.54,700,1,12.46,100,1,14.6,100,1,12.43,700,1,14.68,700,1,12.42,700,1,14.77,100,1,ARL,347052337
1834,2025-07-17T16:19:42.789496729Z,2025-07-17T16:19:42.789496729Z,10,2,1108,C,B,2,12.95,2,0,165763,288669878,13.11,100,1,13.98,2,1,12.98,200,2,13.99,100,1,12.86,100,1,14.25,100,1,12.73,100,1,14.35,200,2,12.71,100,1,14.48,1400,2,12.5,700,1,14.53,100,1,12.46,100,1,14.54,700,1,12.43,700,1,14.6,100,1,12.42,700,1,14.68,700,1,12.37,700,1,14.77,100,1,ARL,346942181
1835,2025-07-17T16:19:42.789496729Z,2025-07-17T16:19:42.789496729Z,10,2,1108,A,B,1,13.03,2,130,165763,288669878,13.11,100,1,13.98,2,1,13.03,2,1,13.99,100,1,12.98,200,2,14.25,100,1,12.86,100,1,14.35,200,2,12.73,100,1,14.48,1400,2,12.71,100,1,14.53,100,1,12.5,700,1,14.54,700,1,12.46,100,1,14.6,100,1,12.43,700,1,14.68,700,1,12.42,700,1,14.77,100,1,ARL,347220093
1836,2025-07-17T16:19:50.837720648Z,2025-07-17T16:19:50.837720648Z,10,2,1108,A,A,0,13.44,15,130,165571,288783555,13.11,100,1,13.44,15,1,13.03,2,1,13.98,2,1,12.98,200,2,13.99,100,1,12.86,100,1,14.25,100,1,12.73,100,1,14.35,200,2,12.71,100,1,14.48,1400,2,12.5,700,1,14.53,100,1,12.46,100,1,14.54,700,1,12.43,700,1,14.6,100,1,12.42,700,1,14.68,700,1,ARL,347377693
1837,2025-07-17T16:19:51.986834012Z,2025-07-17T16:19:51.986834012Z,10,2,1108,C,A,2,13.99,100,0,165687,288797308,13.11,100,1,13.44,15,1,13.03,2,1,13.98,2,1,12.98,200,2,14.25,100,1,12.86,100,1,14.35,200,2,12.73,100,1,14.48,1400,2,12.71,100,1,14.53,100,1,12.5,700,1,14.54,700,1,12.46,100,1,14.6,100,1,12.43,700,1,14.68,700,1,12.42,700,1,14.77,100,1,ARL,347030085
1838,2025-07-17T16:19:51.986834012Z,2025-07-17T16:19:51.986834012Z,10,2,1108,A,A,1,13.45,100,130,165687,288797308,13.11,100,1,13.44,15,1,13.03,2,1,13.45,100,1,12.98,200,2,13.98,2,1,12.86,100,1,14.25,100,1,12.73,100,1,14.35,200,2,12.71,100,1,14.48,1400,2,12.5,700,1,14.53,100,1,12.46,100,1,14.54,700,1,12.43,700,1,14.6,100,1,12.42,700,1,14.68,700,1,ARL,347396033
1839,2025-07-17T16:19:51.987571652Z,2025-07-17T16:19:51.987571652Z,10,2,1108,C,A,8,14.6,100,128,166372,288797316,13.11,100,1,13.44,15,1,13.03,2,1,13.45,100,1,12.98,200,2,13.98,2,1,12.86,100,1,14.25,100,1,12.73,100,1,14.35,200,2,12.71,100,1,14.48,1400,2,12.5,700,1,14.53,100,1,12.46,100,1,14.54,700,1,12.43,700,1,14.68,700,1,12.42,700,1,14.77,100,1,ARL,347045237
1840,2025-07-17T16:19:51.987578278Z,2025-07-17T16:19:51.987578278Z,10,2,1108,A,A,6,14.49,100,130,165437,288797318,13.11,100,1,13.44,15,1,13.03,2,1,13.45,100,1,12.98,200,2,13.98,2,1,12.86,100,1,14.25,100,1,12.73,100,1,14.35,200,2,12.71,100,1,14.48,1400,2,12.5,700,1,14.49,100,1,12.46,100,1,14.53,100,1,12.43,700,1,14.54,700,1,12.42,700,1,14.68,700,1,ARL,347396065
1841,2025-07-17T16:19:51.987923621Z,2025-07-17T16:19:51.987923621Z,10,2,1108,A,A,3,14.05,100,130,165197,288797336,13.11,100,1,13.44,15,1,13.03,2,1,13.45,100,1,12.98,200,2,13.98,2,1,12.86,100,1,14.05,100,1,12.73,100,1,14.25,100,1,12.71,100,1,14.35,200,2,12.5,700,1,14.48,1400,2,12.46,100,1,14.49,100,1,12.43,700,1,14.53,100,1,12.42,700,1,14.54,700,1,ARL,347396069
1842,2025-07-17T16:19:51.989015100Z,2025-07-17T16:19:51.989015100Z,10,2,1108,A,A,6,14.4,100,130,165574,288797340,13.11,100,1,13.44,15,1,13.03,2,1,13.45,100,1,12.98,200,2,13.98,2,1,12.86,100,1,14.05,100,1,12.73,100,1,14.25,100,1,12.71,100,1,14.35,200,2,12.5,700,1,14.4,100,1,12.46,100,1,14.48,1400,2,12.43,700,1,14.49,100,1,12.42,700,1,14.53,100,1,ARL,347396085
1843,2025-07-17T16:19:51.990659712Z,2025-07-17T16:19:51.990659712Z,10,2,1108,C,A,2,13.98,2,0,165394,288797388,13.11,100,1,13.44,15,1,13.03,2,1,13.45,100,1,12.98,200,2,14.05,100,1,12.86,100,1,14.25,100,1,12.73,100,1,14.35,200,2,12.71,100,1,14.4,100,1,12.5,700,1,14.48,1400,2,12.46,100,1,14.49,100,1,12.43,700,1,14.53,100,1,12.42,700,1,14.54,700,1,ARL,347023061
1844,2025-07-17T16:19:51.990659712Z,2025-07-17T16:19:51.990659712Z,10,2,1108,A,A,2,13.86,2,130,165394,288797388,13.11,100,1,13.44,15,1,13.03,2,1,13.45,100,1,12.98,200,2,13.86,2,1,12.86,100,1,14.05,100,1,12.73,100,1,14.25,100,1,12.71,100,1,14.35,200,2,12.5,700,1,14.4,100,1,12.46,100,1,14.48,1400,2,12.43,700,1,14.49,100,1,12.42,700,1,14.53,100,1,ARL,347396177
1845,2025-07-17T16:19:52.000421983Z,2025-07-17T16:19:52.000421983Z,10,2,1108,C,A,4,14.25,100,130,165649,288797576,13.11,100,1,13.44,15,1,13.03,2,1,13.45,100,1,12.98,200,2,13.86,2,1,12.86,100,1,14.05,100,1,12.73,100,1,14.35,200,2,12.71,100,1,14.4,100,1,12.5,700,1,14.48,1400,2,12.46,100,1,14.49,100,1,12.43,700,1,14.53,100,1,12.42,700,1,14.54,700,1,ARL,347023197
1846,2025-07-17T16:19:52.000474403Z,2025-07-17T16:19:52.000474403Z,10,2,1108,A,A,2,13.72,100,130,165237,288797577,13.11,100,1,13.44,15,1,13.03,2,1,13.45,100,1,12.98,200,2,13.72,100,1,12.86,100,1,13.86,2,1,12.73,100,1,14.05,100,1,12.71,100,1,14.35,200,2,12.5,700,1,14.4,100,1,12.46,100,1,14.48,1400,2,12.43,700,1,14.49,100,1,12.42,700,1,14.53,100,1,ARL,347396369
1847,2025-07-17T16:19:52.007240010Z,2025-07-17T16:19:52.007240010Z,10,2,1108,A,A,6,14.4,100,130,165422,288797725,13.11,100,1,13.44,15,1,13.03,2,1,13.45,100,1,12.98,200,2,13.72,100,1,12.86,100,1,13.86,2,1,12.73,100,1,14.05,100,1,12.71,100,1,14.35,200,2,12.5,700,1,14.4,200,2,12.46,100,1,14.48,1400,2,12.43,700,1,14.49,100,1,12.42,700,1,14.53,100,1,ARL,347396549
1848,2025-07-17T16:19:52.051620731Z,2025-07-17T16:19:52.051620731Z,10,2,1108,A,A,5,14.24,100,130,165533,288798183,13.11,100,1,13.44,15,1,13.03,2,1,13.45,100,1,12.98,200,2,13.72,100,1,12.86,100,1,13.86,2,1,12.73,100,1,14.05,100,1,12.71,100,1,14.24,100,1,12.5,700,1,14.35,200,2,12.46,100,1,14.4,200,2,12.43,700,1,14.48,1400,2,12.42,700,1,14.49,100,1,ARL,347397201
1849,2025-07-17T16:19:52.565630623Z,2025-07-17T16:19:52.565630623Z,10,2,1108,A,A,6,14.25,100,130,165620,288804470,13.11,100,1,13.44,15,1,13.03,2,1,13.45,100,1,12.98,200,2,13.72,100,1,12.86,100,1,13.86,2,1,12.73,100,1,14.05,100,1,12.71,100,1,14.24,100,1,12.5,700,1,14.25,100,1,12.46,100,1,14.35,200,2,12.43,700,1,14.4,200,2,12.42,700,1,14.48,1400,2,ARL,347404325
1850,2025-07-17T16:19:52.662723196Z,2025-07-17T16:19:52.662723196Z,10,2,1108,A,A,4,13.98,100,0,166397,288807539,13.11,100,1,13.44,15,1,13.03,2,1,13.45,100,1,12.98,200,2,13.72,100,1,12.86,100,1,13.86,2,1,12.73,100,1,13.98,100,1,12.71,100,1,14.05,100,1,12.5,700,1,14.24,100,1,12.46,100,1,14.25,100,1,12.43,700,1,14.35,200,2,12.42,700,1,14.4,200,2,ARL,347406169
1851,2025-07-17T16:19:53.670533326Z,2025-07-17T16:19:53.670533326Z,10,2,1108,C,A,1,13.45,100,130,165292,288824717,13.11,100,1,13.44,15,1,13.03,2,1,13.72,100,1,12.98,200,2,13.86,2,1,12.86,100,1,13.98,100,1,12.73,100,1,14.05,100,1,12.71,100,1,14.24,100,1,12.5,700,1,14.25,100,1,12.46,100,1,14.35,200,2,12.43,700,1,14.4,200,2,12.42,700,1,14.48,1400,2,ARL,347396033
1852,2025-07-17T16:19:53.671281229Z,2025-07-17T16:19:53.671281229Z,10,2,1108,C,A,4,14.05,100,130,165163,288824751,13.11,100,1,13.44,15,1,13.03,2,1,13.72,100,1,12.98,200,2,13.86,2,1,12.86,100,1,13.98,100,1,12.73,100,1,14.24,100,1,12.71,100,1,14.25,100,1,12.5,700,1,14.35,200,2,12.46,100,1,14.4,200,2,12.43,700,1,14.48,1400,2,12.42,700,1,14.54,700,1,ARL,347396069
1853,2025-07-17T16:19:53.671629711Z,2025-07-17T16:19:53.671629711Z,10,2,1108,A,A,6,14.33,100,130,165259,288824753,13.11,100,1,13.44,15,1,13.03,2,1,13.72,100,1,12.98,200,2,13.86,2,1,12.86,100,1,13.98,100,1,12.73,100,1,14.24,100,1,12.71,100,1,14.25,100,1,12.5,700,1,14.33,100,1,12.46,100,1,14.35,200,2,12.43,700,1,14.4,200,2,12.42,700,1,14.48,1400,2,ARL,347422225
1854,2025-07-17T16:19:53.672883433Z,2025-07-17T16:19:53.672883433Z,10,2,1108,C,A,8,14.4,100,0,165393,288824777,13.11,100,1,13.44,15,1,13.03,2,1,13.72,100,1,12.98,200,2,13.86,2,1,12.86,100,1,13.98,100,1,12.73,100,1,14.24,100,1,12.71,100,1,14.25,100,1,12.5,700,1,14.33,100,1,12.46,100,1,14.35,200,2,12.43,700,1,14.4,100,1,12.42,700,1,14.48,1400,2,ARL,347396085
1855,2025-07-17T16:19:53.673277621Z,2025-07-17T16:19:53.673277621Z,10,2,1108,C,A,4,14.24,100,130,165378,288824780,13.11,100,1,13.44,15,1,13.03,2,1,13.72,100,1,12.98,200,2,13.86,2,1,12.86,100,1,13.98,100,1,12.73,100,1,14.25,100,1,12.71,100,1,14.33,100,1,12.5,700,1,14.35,200,2,12.46,100,1,14.4,100,1,12.43,700,1,14.48,1400,2,12.42,700,1,14.54,700,1,ARL,347397201
1856,2025-07-17T16:19:53.673398019Z,2025-07-17T16:19:53.673398019Z,10,2,1108,A,A,9,14.51,100,130,165246,288824781,13.11,100,1,13.44,15,1,13.03,2,1,13.72,100,1,12.98,200,2,13.86,2,1,12.86,100,1,13.98,100,1,12.73,100,1,14.25,100,1,12.71,100,1,14.33,100,1,12.5,700,1,14.35,200,2,12.46,100,1,14.4,100,1,12.43,700,1,14.48,1400,2,12.42,700,1,14.51,100,1,ARL,347422249
1857,2025-07-17T16:19:53.675249213Z,2025-07-17T16:19:53.675249213Z,10,2,1108,C,A,1,13.72,100,130,165234,288824805,13.11,100,1,13.44,15,1,13.03,2,1,13.86,2,1,12.98,200,2,13.98,100,1,12.86,100,1,14.25,100,1,12.73,100,1,14.33,100,1,12.71,100,1,14.35,200,2,12.5,700,1,14.4,100,1,12.46,100,1,14.48,1400,2,12.43,700,1,14.51,100,1,12.42,700,1,14.54,700,1,ARL,347396369
1858,2025-07-17T16:19:53.675301684Z,2025-07-17T16:19:53.675301684Z,10,2,1108,A,A,3,13.99,100,130,165149,288824807,13.11,100,1,13.44,15,1,13.03,2,1,13.86,2,1,12.98,200,2,13.98,100,1,12.86,100,1,13.99,100,1,12.73,100,1,14.25,100,1,12.71,100,1,14.33,100,1,12.5,700,1,14.35,200,2,12.46,100,1,14.4,100,1,12.43,700,1,14.48,1400,2,12.42,700,1,14.51,100,1,ARL,347422265
1859,2025-07-17T16:19:53.679468070Z,2025-07-17T16:19:53.679468070Z,10,2,1108,C,A,3,13.99,100,130,164954,288824919,13.11,100,1,13.44,15,1,13.03,2,1,13.86,2,1,12.98,200,2,13.98,100,1,12.86,100,1,14.25,100,1,12.73,100,1,14.33,100,1,12.71,100,1,14.35,200,2,12.5,700,1,14.4,100,1,12.46,100,1,14.48,1400,2,12.43,700,1,14.51,100,1,12.42,700,1,14.54,700,1,ARL,347422265
1860,2025-07-17T16:19:53.679517110Z,2025-07-17T16:19:53.679517110Z,10,2,1108,A,A,3,14.22,100,130,165465,288824921,13.11,100,1,13.44,15,1,13.03,2,1,13.86,2,1,12.98,200,2,13.98,100,1,12.86,100,1,14.22,100,1,12.73,100,1,14.25,100,1,12.71,100,1,14.33,100,1,12.5,700,1,14.35,200,2,12.46,100,1,14.4,100,1,12.43,700,1,14.48,1400,2,12.42,700,1,14.51,100,1,ARL,347422365
1861,2025-07-17T16:19:53.717918994Z,2025-07-17T16:19:53.717918994Z,10,2,1108,C,A,7,14.4,100,0,165757,288827326,13.11,100,1,13.44,15,1,13.03,2,1,13.86,2,1,12.98,200,2,13.98,100,1,12.86,100,1,14.22,100,1,12.73,100,1,14.25,100,1,12.71,100,1,14.33,100,1,12.5,700,1,14.35,200,2,12.46,100,1,14.48,1400,2,12.43,700,1,14.51,100,1,12.42,700,1,14.54,700,1,ARL,347396549
1862,2025-07-17T16:19:54.211710788Z,2025-07-17T16:19:54.211710788Z,10,2,1108,C,A,4,14.25,100,130,165289,288836876,13.11,100,1,13.44,15,1,13.03,2,1,13.86,2,1,12.98,200,2,13.98,100,1,12.86,100,1,14.22,100,1,12.73,100,1,14.33,100,1,12.71,100,1,14.35,200,2,12.5,700,1,14.48,1400,2,12.46,100,1,14.51,100,1,12.43,700,1,14.54,700,1,12.42,700,1,14.68,700,1,ARL,347404325
1863,2025-07-17T16:19:54.248820201Z,2025-07-17T16:19:54.248820201Z,10,2,1108,C,A,4,14.33,100,130,165267,288837261,13.11,100,1,13.44,15,1,13.03,2,1,13.86,2,1,12.98,200,2,13.98,100,1,12.86,100,1,14.22,100,1,12.73,100,1,14.35,200,2,12.71,100,1,14.48,1400,2,12.5,700,1,14.51,100,1,12.46,100,1,14.54,700,1,12.43,700,1,14.68,700,1,12.42,700,1,14.81,100,1,ARL,347422225
1864,2025-07-17T16:19:54.249170165Z,2025-07-17T16:19:54.249170165Z,10,2,1108,A,A,8,14.6,100,130,165551,288837262,13.11,100,1,13.44,15,1,13.03,2,1,13.86,2,1,12.98,200,2,13.98,100,1,12.86,100,1,14.22,100,1,12.73,100,1,14.35,200,2,12.71,100,1,14.48,1400,2,12.5,700,1,14.51,100,1,12.46,100,1,14.54,700,1,12.43,700,1,14.6,100,1,12.42,700,1,14.68,700,1,ARL,347437857
1865,2025-07-17T16:19:54.601687713Z,2025-07-17T16:19:54.601687713Z,10,2,1108,C,A,2,13.98,100,130,165222,288841783,13.11,100,1,13.44,15,1,13.03,2,1,13.86,2,1,12.98,200,2,14.22,100,1,12.86,100,1,14.35,200,2,12.73,100,1,14.48,1400,2,12.71,100,1,14.51,100,1,12.5,700,1,14.54,700,1,12.46,100,1,14.6,100,1,12.43,700,1,14.68,700,1,12.42,700,1,14.81,100,1,ARL,347406169
1866,2025-07-17T16:19:54.601688695Z,2025-07-17T16:19:54.601688695Z,10,2,1108,A,A,6,14.53,100,130,165245,288841784,13.11,100,1,13.44,15,1,13.03,2,1,13.86,2,1,12.98,200,2,14.22,100,1,12.86,100,1,14.35,200,2,12.73,100,1,14.48,1400,2,12.71,100,1,14.51,100,1,12.5,700,1,14.53,100,1,12.46,100,1,14.54,700,1,12.43,700,1,14.6,100,1,12.42,700,1,14.68,700,1,ARL,347443097
1867,2025-07-17T16:19:54.677084975Z,2025-07-17T16:19:54.677084975Z,10,2,1108,C,A,5,14.51,100,0,165479,288842530,13.11,100,1,13.44,15,1,13.03,2,1,13.86,2,1,12.98,200,2,14.22,100,1,12.86,100,1,14.35,200,2,12.73,100,1,14.48,1400,2,12.71,100,1,14.53,100,1,12.5,700,1,14.54,700,1,12.46,100,1,14.6,100,1,12.43,700,1,14.68,700,1,12.42,700,1,14.81,100,1,ARL,347422249
1868,2025-07-17T16:19:54.677084975Z,2025-07-17T16:19:54.677084975Z,10,2,1108,A,A,9,14.77,100,130,165479,288842530,13.11,100,1,13.44,15,1,13.03,2,1,13.86,2,1,12.98,200,2,14.22,100,1,12.86,100,1,14.35,200,2,12.73,100,1,14.48,1400,2,12.71,100,1,14.53,100,1,12.5,700,1,14.54,700,1,12.46,100,1,14.6,100,1,12.43,700,1,14.68,700,1,12.42,700,1,14.77,100,1,ARL,347444385
1869,2025-07-17T16:19:54.918922624Z,2025-07-17T16:19:54.918922624Z,10,2,1108,A,A,2,13.87,100,130,165313,288846635,13.11,100,1,13.44,15,1,13.03,2,1,13.86,2,1,12.98,200,2,13.87,100,1,12.86,100,1,14.22,100,1,12.73,100,1,14.35,200,2,12.71,100,1,14.48,1400,2,12.5,700,1,14.53,100,1,12.46,100,1,14.54,700,1,12.43,700,1,14.6,100,1,12.42,700,1,14.68,700,1,ARL,347449521
1870,2025-07-17T16:19:54.942776198Z,2025-07-17T16:19:54.942776198Z,10,2,1108,C,A,3,14.22,100,130,165260,288847105,13.11,100,1,13.44,15,1,13.03,2,1,13.86,2,1,12.98,200,2,13.87,100,1,12.86,100,1,14.35,200,2,12.73,100,1,14.48,1400,2,12.71,100,1,14.53,100,1,12.5,700,1,14.54,700,1,12.46,100,1,14.6,100,1,12.43,700,1,14.68,700,1,12.42,700,1,14.77,100,1,ARL,347422365
1871,2025-07-17T16:19:54.942832705Z,2025-07-17T16:19:54.942832705Z,10,2,1108,A,A,3,14.15,100,130,165310,288847115,13.11,100,1,13.44,15,1,13.03,2,1,13.86,2,1,12.98,200,2,13.87,100,1,12.86,100,1,14.15,100,1,12.73,100,1,14.35,200,2,12.71,100,1,14.48,1400,2,12.5,700,1,14.53,100,1,12.46,100,1,14.54,700,1,12.43,700,1,14.6,100,1,12.42,700,1,14.68,700,1,ARL,347449893
1872,2025-07-17T16:20:02.838295810Z,2025-07-17T16:20:02.838295810Z,10,2,1108,A,A,0,13.4,15,130,165397,288958120,13.11,100,1,13.4,15,1,13.03,2,1,13.44,15,1,12.98,200,2,13.86,2,1,12.86,100,1,13.87,100,1,12.73,100,1,14.15,100,1,12.71,100,1,14.35,200,2,12.5,700,1,14.48,1400,2,12.46,100,1,14.53,100,1,12.43,700,1,14.54,700,1,12.42,700,1,14.6,100,1,ARL,347592441
1873,2025-07-17T16:20:03.544791773Z,2025-07-17T16:20:03.544791773Z,10,2,1108,C,A,3,13.87,100,0,165383,288969245,13.11,100,1,13.4,15,1,13.03,2,1,13.44,15,1,12.98,200,2,13.86,2,1,12.86,100,1,14.15,100,1,12.73,100,1,14.35,200,2,12.71,100,1,14.48,1400,2,12.5,700,1,14.53,100,1,12.46,100,1,14.54,700,1,12.43,700,1,14.6,100,1,12.42,700,1,14.68,700,1,ARL,347449521
1874,2025-07-17T16:20:03.544791773Z,2025-07-17T16:20:03.544791773Z,10,2,1108,A,A,2,13.45,100,130,165383,288969245,13.11,100,1,13.4,15,1,13.03,2,1,13.44,15,1,12.98,200,2,13.45,100,1,12.86,100,1,13.86,2,1,12.73,100,1,14.15,100,1,12.71,100,1,14.35,200,2,12.5,700,1,14.48,1400,2,12.46,100,1,14.53,100,1,12.43,700,1,14.54,700,1,12.42,700,1,14.6,100,1,ARL,347605041
1875,2025-07-17T16:20:03.545526427Z,2025-07-17T16:20:03.545526427Z,10,2,1108,A,A,7,14.49,100,130,165794,288969257,13.11,100,1,13.4,15,1,13.03,2,1,13.44,15,1,12.98,200,2,13.45,100,1,12.86,100,1,13.86,2,1,12.73,100,1,14.15,100,1,12.71,100,1,14.35,200,2,12.5,700,1,14.48,1400,2,12.46,100,1,14.49,100,1,12.43,700,1,14.53,100,1,12.42,700,1,14.54,700,1,ARL,347605073
1876,2025-07-17T16:20:03.545881983Z,2025-07-17T16:20:03.545881983Z,10,2,1108,A,A,4,14.05,100,130,165248,288969265,13.11,100,1,13.4,15,1,13.03,2,1,13.44,15,1,12.98,200,2,13.45,100,1,12.86,100,1,13.86,2,1,12.73,100,1,14.05,100,1,12.71,100,1,14.15,100,1,12.5,700,1,14.35,200,2,12.46,100,1,14.48,1400,2,12.43,700,1,14.49,100,1,12.42,700,1,14.53,100,1,ARL,347605081
1877,2025-07-17T16:20:03.547556902Z,2025-07-17T16:20:03.547556902Z,10,2,1108,A,A,7,14.4,100,130,165316,288969290,13.11,100,1,13.4,15,1,13.03,2,1,13.44,15,1,12.98,200,2,13.45,100,1,12.86,100,1,13.86,2,1,12.73,100,1,14.05,100,1,12.71,100,1,14.15,100,1,12.5,700,1,14.35,200,2,12.46,100,1,14.4,100,1,12.43,700,1,14.48,1400,2,12.42,700,1,14.49,100,1,ARL,347605109
1878,2025-07-17T16:20:03.557856817Z,2025-07-17T16:20:03.557856817Z,10,2,1108,C,A,5,14.15,100,130,165248,288969562,13.11,100,1,13.4,15,1,13.03,2,1,13.44,15,1,12.98,200,2,13.45,100,1,12.86,100,1,13.86,2,1,12.73,100,1,14.05,100,1,12.71,100,1,14.35,200,2,12.5,700,1,14.4,100,1,12.46,100,1,14.48,1400,2,12.43,700,1,14.49,100,1,12.42,700,1,14.53,100,1,ARL,347449893
1879,2025-07-17T16:20:03.557909645Z,2025-07-17T16:20:03.557909645Z,10,2,1108,A,A,3,13.72,100,130,165241,288969565,13.11,100,1,13.4,15,1,13.03,2,1,13.44,15,1,12.98,200,2,13.45,100,1,12.86,100,1,13.72,100,1,12.73,100,1,13.86,2,1,12.71,100,1,14.05,100,1,12.5,700,1,14.35,200,2,12.46,100,1,14.4,100,1,12.43,700,1,14.48,1400,2,12.42,700,1,14.49,100,1,ARL,347605397
1880,2025-07-17T16:20:03.569738711Z,2025-07-17T16:20:03.569738711Z,10,2,1108,A,A,7,14.4,100,130,165870,288969738,13.11,100,1,13.4,15,1,13.03,2,1,13.44,15,1,12.98,200,2,13.45,100,1,12.86,100,1,13.72,100,1,12.73,100,1,13.86,2,1,12.71,100,1,14.05,100,1,12.5,700,1,14.35,200,2,12.46,100,1,14.4,200,2,12.43,700,1,14.48,1400,2,12.42,700,1,14.49,100,1,ARL,347605617
1881,2025-07-17T16:20:03.592738507Z,2025-07-17T16:20:03.592738507Z,10,2,1108,A,A,6,14.24,100,130,165326,288970211,13.11,100,1,13.4,15,1,13.03,2,1,13.44,15,1,12.98,200,2,13.45,100,1,12.86,100,1,13.72,100,1,12.73,100,1,13.86,2,1,12.71,100,1,14.05,100,1,12.5,700,1,14.24,100,1,12.46,100,1,14.35,200,2,12.43,700,1,14.4,200,2,12.42,700,1,14.48,1400,2,ARL,347605969
1882,2025-07-17T16:20:04.069496437Z,2025-07-17T16:20:04.069496437Z,10,2,1108,A,A,5,13.98,100,130,165276,288977269,13.11,100,1,13.4,15,1,13.03,2,1,13.44,15,1,12.98,200,2,13.45,100,1,12.86,100,1,13.72,100,1,12.73,100,1,13.86,2,1,12.71,100,1,13.98,100,1,12.5,700,1,14.05,100,1,12.46,100,1,14.24,100,1,12.43,700,1,14.35,200,2,12.42,700,1,14.4,200,2,ARL,347613877
1883,2025-07-17T16:20:04.111630484Z,2025-07-17T16:20:04.111630484Z,10,2,1108,A,A,8,14.25,100,130,165155,288978560,13.11,100,1,13.4,15,1,13.03,2,1,13.44,15,1,12.98,200,2,13.45,100,1,12.86,100,1,13.72,100,1,12.73,100,1,13.86,2,1,12.71,100,1,13.98,100,1,12.5,700,1,14.05,100,1,12.46,100,1,14.24,100,1,12.43,700,1,14.25,100,1,12.42,700,1,14.35,200,2,ARL,347615553
1884,2025-07-17T16:20:07.945262120Z,2025-07-17T16:20:07.945262120Z,10,2,1108,C,A,1,13.44,15,130,165165,289031160,13.11,100,1,13.4,15,1,13.03,2,1,13.45,100,1,12.98,200,2,13.72,100,1,12.86,100,1,13.86,2,1,12.73,100,1,13.98,100,1,12.71,100,1,14.05,100,1,12.5,700,1,14.24,100,1,12.46,100,1,14.25,100,1,12.43,700,1,14.35,200,2,12.42,700,1,14.4,200,2,ARL,347377693
1885,2025-07-17T16:20:08.949241997Z,2025-07-17T16:20:08.949241997Z,10,2,1108,A,A,0,13.36,15,130,165419,289046760,13.11,100,1,13.36,15,1,13.03,2,1,13.4,15,1,12.98,200,2,13.45,100,1,12.86,100,1,13.72,100,1,12.73,100,1,13.86,2,1,12.71,100,1,13.98,100,1,12.5,700,1,14.05,100,1,12.46,100,1,14.24,100,1,12.43,700,1,14.25,100,1,12.42,700,1,14.35,200,2,ARL,347710393
1886,2025-07-17T16:20:09.428650758Z,2025-07-17T16:20:09.428650758Z,10,2,1108,A,A,7,14.17,700,130,166474,289052533,13.11,100,1,13.36,15,1,13.03,2,1,13.4,15,1,12.98,200,2,13.45,100,1,12.86,100,1,13.72,100,1,12.73,100,1,13.86,2,1,12.71,100,1,13.98,100,1,12.5,700,1,14.05,100,1,12.46,100,1,14.17,700,1,12.43,700,1,14.24,100,1,12.42,700,1,14.25,100,1,ARL,347717317
1887,2025-07-17T16:20:09.704693450Z,2025-07-17T16:20:09.704693450Z,10,2,1108,C,A,4,13.86,2,0,166337,289057887,13.11,100,1,13.36,15,1,13.03,2,1,13.4,15,1,12.98,200,2,13.45,100,1,12.86,100,1,13.72,100,1,12.73,100,1,13.98,100,1,12.71,100,1,14.05,100,1,12.5,700,1,14.17,700,1,12.46,100,1,14.24,100,1,12.43,700,1,14.25,100,1,12.42,700,1,14.35,200,2,ARL,347396177
1888,2025-07-17T16:20:09.704693450Z,2025-07-17T16:20:09.704693450Z,10,2,1108,A,A,4,13.78,2,128,166337,289057887,13.11,100,1,13.36,15,1,13.03,2,1,13.4,15,1,12.98,200,2,13.45,100,1,12.86,100,1,13.72,100,1,12.73,100,1,13.78,2,1,12.71,100,1,13.98,100,1,12.5,700,1,14.05,100,1,12.46,100,1,14.17,700,1,12.43,700,1,14.24,100,1,12.42,700,1,14.25,100,1,ARL,347722857
1889,2025-07-17T16:20:11.608202073Z,2025-07-17T16:20:11.608202073Z,10,2,1108,A,A,8,14.24,100,130,165620,289085339,13.11,100,1,13.36,15,1,13.03,2,1,13.4,15,1,12.98,200,2,13.45,100,1,12.86,100,1,13.72,100,1,12.73,100,1,13.78,2,1,12.71,100,1,13.98,100,1,12.5,700,1,14.05,100,1,12.46,100,1,14.17,700,1,12.43,700,1,14.24,200,2,12.42,700,1,14.25,100,1,ARL,347760469
1890,2025-07-17T16:20:11.608307409Z,2025-07-17T16:20:11.608307409Z,10,2,1108,A,A,8,14.24,100,130,165358,289085342,13.11,100,1,13.36,15,1,13.03,2,1,13.4,15,1,12.98,200,2,13.45,100,1,12.86,100,1,13.72,100,1,12.73,100,1,13.78,2,1,12.71,100,1,13.98,100,1,12.5,700,1,14.05,100,1,12.46,100,1,14.17,700,1,12.43,700,1,14.24,300,3,12.42,700,1,14.25,100,1,ARL,347760485
1891,2025-07-17T16:20:20.587879078Z,2025-07-17T16:20:20.587879078Z,10,2,1108,C,A,4,13.78,2,0,165854,289232518,13.11,100,1,13.36,15,1,13.03,2,1,13.4,15,1,12.98,200,2,13.45,100,1,12.86,100,1,13.72,100,1,12.73,100,1,13.98,100,1,12.71,100,1,14.05,100,1,12.5,700,1,14.17,700,1,12.46,100,1,14.24,300,3,12.43,700,1,14.25,100,1,12.42,700,1,14.4,200,2,ARL,347722857
1892,2025-07-17T16:20:20.587879078Z,2025-07-17T16:20:20.587879078Z,10,2,1108,A,A,3,13.71,2,130,165854,289232518,13.11,100,1,13.36,15,1,13.03,2,1,13.4,15,1,12.98,200,2,13.45,100,1,12.86,100,1,13.71,2,1,12.73,100,1,13.72,100,1,12.71,100,1,13.98,100,1,12.5,700,1,14.05,100,1,12.46,100,1,14.17,700,1,12.43,700,1,14.24,300,3,12.42,700,1,14.25,100,1,ARL,347935421
1893,2025-07-17T16:20:20.839080003Z,2025-07-17T16:20:20.839080003Z,10,2,1108,C,A,1,13.4,15,130,165226,289235324,13.11,100,1,13.36,15,1,13.03,2,1,13.45,100,1,12.98,200,2,13.71,2,1,12.86,100,1,13.72,100,1,12.73,100,1,13.98,100,1,12.71,100,1,14.05,100,1,12.5,700,1,14.17,700,1,12.46,100,1,14.24,300,3,12.43,700,1,14.25,100,1,12.42,700,1,14.4,200,2,ARL,347592441
1894,2025-07-17T16:20:21.839400050Z,2025-07-17T16:20:21.839400050Z,10,2,1108,A,A,0,13.33,15,130,165850,289253047,13.11,100,1,13.33,15,1,13.03,2,1,13.36,15,1,12.98,200,2,13.45,100,1,12.86,100,1,13.71,2,1,12.73,100,1,13.72,100,1,12.71,100,1,13.98,100,1,12.5,700,1,14.05,100,1,12.46,100,1,14.17,700,1,12.43,700,1,14.24,300,3,12.42,700,1,14.25,100,1,ARL,347961173
1895,2025-07-17T16:20:27.448368575Z,2025-07-17T16:20:27.448368575Z,10,2,1108,C,A,1,13.36,15,130,165280,289339972,13.11,100,1,13.33,15,1,13.03,2,1,13.45,100,1,12.98,200,2,13.71,2,1,12.86,100,1,13.72,100,1,12.73,100,1,13.98,100,1,12.71,100,1,14.05,100,1,12.5,700,1,14.17,700,1,12.46,100,1,14.24,300,3,12.43,700,1,14.25,100,1,12.42,700,1,14.4,200,2,ARL,347710393
1896,2025-07-17T16:20:28.452388023Z,2025-07-17T16:20:28.452388023Z,10,2,1108,A,A,0,13.31,15,130,165389,289367352,13.11,100,1,13.31,15,1,13.03,2,1,13.33,15,1,12.98,200,2,13.45,100,1,12.86,100,1,13.71,2,1,12.73,100,1,13.72,100,1,12.71,100,1,13.98,100,1,12.5,700,1,14.05,100,1,12.46,100,1,14.17,700,1,12.43,700,1,14.24,300,3,12.42,700,1,14.25,100,1,ARL,348099617
1897,2025-07-17T16:20:31.453272244Z,2025-07-17T16:20:31.453272244Z,10,2,1108,C,A,1,13.33,15,130,165572,289452005,13.11,100,1,13.31,15,1,13.03,2,1,13.45,100,1,12.98,200,2,13.71,2,1,12.86,100,1,13.72,100,1,12.73,100,1,13.98,100,1,12.71,100,1,14.05,100,1,12.5,700,1,14.17,700,1,12.46,100,1,14.24,300,3,12.43,700,1,14.25,100,1,12.42,700,1,14.4,200,2,ARL,347961173
1898,2025-07-17T16:20:42.837908349Z,2025-07-17T16:20:42.837908349Z,10,2,1108,A,A,0,13.29,15,130,165352,289627630,13.11,100,1,13.29,15,1,13.03,2,1,13.31,15,1,12.98,200,2,13.45,100,1,12.86,100,1,13.71,2,1,12.73,100,1,13.72,100,1,12.71,100,1,13.98,100,1,12.5,700,1,14.05,100,1,12.46,100,1,14.17,700,1,12.43,700,1,14.24,300,3,12.42,700,1,14.25,100,1,ARL,348428649
1899,2025-07-17T16:20:56.875359282Z,2025-07-17T16:20:56.875359282Z,10,2,1108,C,B,1,13.03,2,0,165507,289958017,13.11,100,1,13.29,15,1,12.98,200,2,13.31,15,1,12.86,100,1,13.45,100,1,12.73,100,1,13.71,2,1,12.71,100,1,13.72,100,1,12.5,700,1,13.98,100,1,12.46,100,1,14.05,100,1,12.43,700,1,14.17,700,1,12.42,700,1,14.24,300,3,12.37,700,1,14.25,100,1,ARL,347220093
1900,2025-07-17T16:20:56.875359282Z,2025-07-17T16:20:56.875359282Z,10,2,1108,A,B,2,12.96,2,130,165507,289958017,13.11,100,1,13.29,15,1,12.98,200,2,13.31,15,1,12.96,2,1,13.45,100,1,12.86,100,1,13.71,2,1,12.73,100,1,13.72,100,1,12.71,100,1,13.98,100,1,12.5,700,1,14.05,100,1,12.46,100,1,14.17,700,1,12.43,700,1,14.24,300,3,12.42,700,1,14.25,100,1,ARL,348838809
1901,2025-07-17T16:21:03.027478065Z,2025-07-17T16:21:03.027478065Z,10,2,1108,C,A,1,13.31,15,130,165878,290149718,13.11,100,1,13.29,15,1,12.98,200,2,13.45,100,1,12.96,2,1,13.71,2,1,12.86,100,1,13.72,100,1,12.73,100,1,13.98,100,1,12.71,100,1,14.05,100,1,12.5,700,1,14.17,700,1,12.46,100,1,14.24,300,3,12.43,700,1,14.25,100,1,12.42,700,1,14.4,200,2,ARL,348099617
1902,2025-07-17T16:21:03.786169333Z,2025-07-17T16:21:03.786169333Z,10,2,1108,C,A,2,13.71,2,0,165582,290172493,13.11,100,1,13.29,15,1,12.98,200,2,13.45,100,1,12.96,2,1,13.72,100,1,12.86,100,1,13.98,100,1,12.73,100,1,14.05,100,1,12.71,100,1,14.17,700,1,12.5,700,1,14.24,300,3,12.46,100,1,14.25,100,1,12.43,700,1,14.4,200,2,12.42,700,1,14.48,1400,2,ARL,347935421
1903,2025-07-17T16:21:03.786169333Z,2025-07-17T16:21:03.786169333Z,10,2,1108,A,A,2,13.65,2,130,165582,290172493,13.11,100,1,13.29,15,1,12.98,200,2,13.45,100,1,12.96,2,1,13.65,2,1,12.86,100,1,13.72,100,1,12.73,100,1,13.98,100,1,12.71,100,1,14.05,100,1,12.5,700,1,14.17,700,1,12.46,100,1,14.24,300,3,12.43,700,1,14.25,100,1,12.42,700,1,14.4,200,2,ARL,349094877
1904,2025-07-17T16:21:04.031397539Z,2025-07-17T16:21:04.031397539Z,10,2,1108,A,A,0,13.27,15,130,165721,290175495,13.11,100,1,13.27,15,1,12.98,200,2,13.29,15,1,12.96,2,1,13.45,100,1,12.86,100,1,13.65,2,1,12.73,100,1,13.72,100,1,12.71,100,1,13.98,100,1,12.5,700,1,14.05,100,1,12.46,100,1,14.17,700,1,12.43,700,1,14.24,300,3,12.42,700,1,14.25,100,1,ARL,349100269
1905,2025-07-17T16:21:04.035632459Z,2025-07-17T16:21:04.035632459Z,10,2,1108,T,A,0,13.27,15,128,166770,290175561,13.11,100,1,13.27,15,1,12.98,200,2,13.29,15,1,12.96,2,1,13.45,100,1,12.86,100,1,13.65,2,1,12.73,100,1,13.72,100,1,12.71,100,1,13.98,100,1,12.5,700,1,14.05,100,1,12.46,100,1,14.17,700,1,12.43,700,1,14.24,300,3,12.42,700,1,14.25,100,1,ARL,0
1906,2025-07-17T16:21:04.035632459Z,2025-07-17T16:21:04.035632459Z,10,2,1108,T,B,0,13.27,15,128,166770,290175561,13.11,100,1,13.27,15,1,12.98,200,2,13.29,15,1,12.96,2,1,13.45,100,1,12.86,100,1,13.65,2,1,12.73,100,1,13.72,100,1,12.71,100,1,13.98,100,1,12.5,700,1,14.05,100,1,12.46,100,1,14.17,700,1,12.43,700,1,14.24,300,3,12.42,700,1,14.25,100,1,ARL,349100269
1907,2025-07-17T16:21:04.035632459Z,2025-07-17T16:21:04.035632459Z,10,2,1108,C,A,0,13.27,15,128,166770,290175561,13.11,100,1,13.29,15,1,12.98,200,2,13.45,100,1,12.96,2,1,13.65,2,1,12.86,100,1,13.72,100,1,12.73,100,1,13.98,100,1,12.71,100,1,14.05,100,1,12.5,700,1,14.17,700,1,12.46,100,1,14.24,300,3,12.43,700,1,14.25,100,1,12.42,700,1,14.4,200,2,ARL,349100269
1908,2025-07-17T16:21:04.035660519Z,2025-07-17T16:21:04.035660519Z,10,2,1108,A,B,0,13.14,11,130,165317,290175563,13.14,11,1,13.29,15,1,13.11,100,1,13.45,100,1,12.98,200,2,13.65,2,1,12.96,2,1,13.72,100,1,12.86,100,1,13.98,100,1,12.73,100,1,14.05,100,1,12.71,100,1,14.17,700,1,12.5,700,1,14.24,300,3,12.46,100,1,14.25,100,1,12.43,700,1,14.4,200,2,ARL,349100461
1909,2025-07-17T16:21:05.035006249Z,2025-07-17T16:21:05.035006249Z,10,2,1108,C,B,0,13.14,11,130,165341,290207081,13.11,100,1,13.29,15,1,12.98,200,2,13.45,100,1,12.96,2,1,13.65,2,1,12.86,100,1,13.72,100,1,12.73,100,1,13.98,100,1,12.71,100,1,14.05,100,1,12.5,700,1,14.17,700,1,12.46,100,1,14.24,300,3,12.43,700,1,14.25,100,1,12.42,700,1,14.4,200,2,ARL,349100461
1910,2025-07-17T16:21:13.027610071Z,2025-07-17T16:21:13.027610071Z,10,2,1108,C,A,0,13.29,15,130,166015,290382552,13.11,100,1,13.45,100,1,12.98,200,2,13.65,2,1,12.96,2,1,13.72,100,1,12.86,100,1,13.98,100,1,12.73,100,1,14.05,100,1,12.71,100,1,14.17,700,1,12.5,700,1,14.24,300,3,12.46,100,1,14.25,100,1,12.43,700,1,14.4,200,2,12.42,700,1,14.48,1400,2,ARL,348428649
1911,2025-07-17T16:21:13.028039954Z,2025-07-17T16:21:13.028039954Z,10,2,1108,C,A,0,13.45,100,128,168724,290382699,13.11,100,1,13.65,2,1,12.98,200,2,13.72,100,1,12.96,2,1,13.98,100,1,12.86,100,1,14.05,100,1,12.73,100,1,14.17,700,1,12.71,100,1,14.24,300,3,12.5,700,1,14.25,100,1,12.46,100,1,14.4,200,2,12.43,700,1,14.48,1400,2,12.42,700,1,14.49,100,1,ARL,347605041
1912,2025-07-17T16:21:13.028763898Z,2025-07-17T16:21:13.028763898Z,10,2,1108,C,A,5,14.24,100,0,165715,290382878,13.11,100,1,13.65,2,1,12.98,200,2,13.72,100,1,12.96,2,1,13.98,100,1,12.86,100,1,14.05,100,1,12.73,100,1,14.17,700,1,12.71,100,1,14.24,200,2,12.5,700,1,14.25,100,1,12.46,100,1,14.4,200,2,12.43,700,1,14.48,1400,2,12.42,700,1,14.49,100,1,ARL,347760485
1913,2025-07-17T16:21:13.028792918Z,2025-07-17T16:21:13.028792918Z,10,2,1108,C,A,3,14.05,100,128,167736,290382883,13.11,100,1,13.65,2,1,12.98,200,2,13.72,100,1,12.96,2,1,13.98,100,1,12.86,100,1,14.17,700,1,12.73,100,1,14.24,200,2,12.71,100,1,14.25,100,1,12.5,700,1,14.4,200,2,12.46,100,1,14.48,1400,2,12.43,700,1,14.49,100,1,12.42,700,1,14.54,700,1,ARL,347605081
1914,2025-07-17T16:21:13.029148929Z,2025-07-17T16:21:13.029148929Z,10,2,1108,A,A,6,14.33,100,130,165370,290382993,13.11,100,1,13.65,2,1,12.98,200,2,13.72,100,1,12.96,2,1,13.98,100,1,12.86,100,1,14.17,700,1,12.73,100,1,14.24,200,2,12.71,100,1,14.25,100,1,12.5,700,1,14.33,100,1,12.46,100,1,14.4,200,2,12.43,700,1,14.48,1400,2,12.42,700,1,14.49,100,1,ARL,349364205
1915,2025-07-17T16:21:13.029229862Z,2025-07-17T16:21:13.029229862Z,10,2,1108,C,A,9,14.49,100,0,165699,290383014,13.11,100,1,13.65,2,1,12.98,200,2,13.72,100,1,12.96,2,1,13.98,100,1,12.86,100,1,14.17,700,1,12.73,100,1,14.24,200,2,12.71,100,1,14.25,100,1,12.5,700,1,14.33,100,1,12.46,100,1,14.4,200,2,12.43,700,1,14.48,1400,2,12.42,700,1,14.54,700,1,ARL,347605073
1916,2025-07-17T16:21:13.029267150Z,2025-07-17T16:21:13.029267150Z,10,2,1108,C,A,3,14.17,700,130,166602,290383019,13.11,100,1,13.65,2,1,12.98,200,2,13.72,100,1,12.96,2,1,13.98,100,1,12.86,100,1,14.24,200,2,12.73,100,1,14.25,100,1,12.71,100,1,14.33,100,1,12.5,700,1,14.4,200,2,12.46,100,1,14.48,1400,2,12.43,700,1,14.54,700,1,12.42,700,1,14.63,100,1,ARL,347717317
1917,2025-07-17T16:21:13.029296174Z,2025-07-17T16:21:13.029296174Z,10,2,1108,C,A,3,14.24,100,0,165694,290383027,13.11,100,1,13.65,2,1,12.98,200,2,13.72,100,1,12.96,2,1,13.98,100,1,12.86,100,1,14.24,100,1,12.73,100,1,14.25,100,1,12.71,100,1,14.33,100,1,12.5,700,1,14.4,200,2,12.46,100,1,14.48,1400,2,12.43,700,1,14.54,700,1,12.42,700,1,14.63,100,1,ARL,347760469
1918,2025-07-17T16:21:13.029296174Z,2025-07-17T16:21:13.029296174Z,10,2,1108,A,A,9,14.63,100,130,165694,290383027,13.11,100,1,13.65,2,1,12.98,200,2,13.72,100,1,12.96,2,1,13.98,100,1,12.86,100,1,14.24,100,1,12.73,100,1,14.25,100,1,12.71,100,1,14.33,100,1,12.5,700,1,14.4,200,2,12.46,100,1,14.48,1400,2,12.43,700,1,14.54,700,1,12.42,700,1,14.63,200,2,ARL,349364233
1919,2025-07-17T16:21:13.029335284Z,2025-07-17T16:21:13.029335284Z,10,2,1108,A,A,7,14.41,700,130,165327,290383043,13.11,100,1,13.65,2,1,12.98,200,2,13.72,100,1,12.96,2,1,13.98,100,1,12.86,100,1,14.24,100,1,12.73,100,1,14.25,100,1,12.71,100,1,14.33,100,1,12.5,700,1,14.4,200,2,12.46,100,1,14.41,700,1,12.43,700,1,14.48,1400,2,12.42,700,1,14.54,700,1,ARL,349364241
1920,2025-07-17T16:21:13.033360385Z,2025-07-17T16:21:13.033360385Z,10,2,1108,C,A,3,14.24,100,0,165520,290383910,13.11,100,1,13.65,2,1,12.98,200,2,13.72,100,1,12.96,2,1,13.98,100,1,12.86,100,1,14.25,100,1,12.73,100,1,14.33,100,1,12.71,100,1,14.4,200,2,12.5,700,1,14.41,700,1,12.46,100,1,14.48,1400,2,12.43,700,1,14.54,700,1,12.42,700,1,14.63,200,2,ARL,347605969
1921,2025-07-17T16:21:13.033360385Z,2025-07-17T16:21:13.033360385Z,10,2,1108,A,A,8,14.51,100,130,165520,290383910,13.11,100,1,13.65,2,1,12.98,200,2,13.72,100,1,12.96,2,1,13.98,100,1,12.86,100,1,14.25,100,1,12.73,100,1,14.33,100,1,12.71,100,1,14.4,200,2,12.5,700,1,14.41,700,1,12.46,100,1,14.48,1400,2,12.43,700,1,14.51,100,1,12.42,700,1,14.54,700,1,ARL,349364905
1922,2025-07-17T16:21:13.041173935Z,2025-07-17T16:21:13.041173935Z,10,2,1108,C,A,1,13.72,100,130,165343,290385083,13.11,100,1,13.65,2,1,12.98,200,2,13.98,100,1,12.96,2,1,14.25,100,1,12.86,100,1,14.33,100,1,12.73,100,1,14.4,200,2,12.71,100,1,14.41,700,1,12.5,700,1,14.48,1400,2,12.46,100,1,14.51,100,1,12.43,700,1,14.54,700,1,12.42,700,1,14.63,200,2,ARL,347605397
1923,2025-07-17T16:21:13.041211567Z,2025-07-17T16:21:13.041211567Z,10,2,1108,C,A,5,14.41,700,130,165024,290385085,13.11,100,1,13.65,2,1,12.98,200,2,13.98,100,1,12.96,2,1,14.25,100,1,12.86,100,1,14.33,100,1,12.73,100,1,14.4,200,2,12.71,100,1,14.48,1400,2,12.5,700,1,14.51,100,1,12.46,100,1,14.54,700,1,12.43,700,1,14.63,200,2,12.42,700,1,14.78,100,1,ARL,349364241
1924,2025-07-17T16:21:13.041231123Z,2025-07-17T16:21:13.041231123Z,10,2,1108,A,A,2,13.99,100,130,165289,290385086,13.11,100,1,13.65,2,1,12.98,200,2,13.98,100,1,12.96,2,1,13.99,100,1,12.86,100,1,14.25,100,1,12.73,100,1,14.33,100,1,12.71,100,1,14.4,200,2,12.5,700,1,14.48,1400,2,12.46,100,1,14.51,100,1,12.43,700,1,14.54,700,1,12.42,700,1,14.63,200,2,ARL,349365741
1925,2025-07-17T16:21:13.042212059Z,2025-07-17T16:21:13.042212059Z,10,2,1108,A,B,0,13.11,10,130,165383,290385162,13.11,110,2,13.65,2,1,12.98,200,2,13.98,100,1,12.96,2,1,13.99,100,1,12.86,100,1,14.25,100,1,12.73,100,1,14.33,100,1,12.71,100,1,14.4,200,2,12.5,700,1,14.48,1400,2,12.46,100,1,14.51,100,1,12.43,700,1,14.54,700,1,12.42,700,1,14.63,200,2,ARL,349365825
1926,2025-07-17T16:21:13.046127777Z,2025-07-17T16:21:13.046127777Z,10,2,1108,C,A,2,13.99,100,130,165311,290385480,13.11,110,2,13.65,2,1,12.98,200,2,13.98,100,1,12.96,2,1,14.25,100,1,12.86,100,1,14.33,100,1,12.73,100,1,14.4,200,2,12.71,100,1,14.48,1400,2,12.5,700,1,14.51,100,1,12.46,100,1,14.54,700,1,12.43,700,1,14.63,200,2,12.42,700,1,14.78,100,1,ARL,349365741
1927,2025-07-17T16:21:13.046179769Z,2025-07-17T16:21:13.046179769Z,10,2,1108,A,A,2,14.22,100,130,165336,290385481,13.11,110,2,13.65,2,1,12.98,200,2,13.98,100,1,12.96,2,1,14.22,100,1,12.86,100,1,14.25,100,1,12.73,100,1,14.33,100,1,12.71,100,1,14.4,200,2,12.5,700,1,14.48,1400,2,12.46,100,1,14.51,100,1,12.43,700,1,14.54,700,1,12.42,700,1,14.63,200,2,ARL,349366121
1928,2025-07-17T16:21:13.051041384Z,2025-07-17T16:21:13.051041384Z,10,2,1108,C,A,0,13.65,2,0,165899,290385730,13.11,110,2,13.98,100,1,12.98,200,2,14.22,100,1,12.96,2,1,14.25,100,1,12.86,100,1,14.33,100,1,12.73,100,1,14.4,200,2,12.71,100,1,14.48,1400,2,12.5,700,1,14.51,100,1,12.46,100,1,14.54,700,1,12.43,700,1,14.63,200,2,12.42,700,1,14.78,100,1,ARL,349094877
1929,2025-07-17T16:21:13.051041384Z,2025-07-17T16:21:13.051041384Z,10,2,1108,A,A,0,13.98,2,130,165899,290385730,13.11,110,2,13.98,102,2,12.98,200,2,14.22,100,1,12.96,2,1,14.25,100,1,12.86,100,1,14.33,100,1,12.73,100,1,14.4,200,2,12.71,100,1,14.48,1400,2,12.5,700,1,14.51,100,1,12.46,100,1,14.54,700,1,12.43,700,1,14.63,200,2,12.42,700,1,14.78,100,1,ARL,349366297
1930,2025-07-17T16:21:13.053942197Z,2025-07-17T16:21:13.053942197Z,10,2,1108,C,A,4,14.4,100,0,165527,290385849,13.11,110,2,13.98,102,2,12.98,200,2,14.22,100,1,12.96,2,1,14.25,100,1,12.86,100,1,14.33,100,1,12.73,100,1,14.4,100,1,12.71,100,1,14.48,1400,2,12.5,700,1,14.51,100,1,12.46,100,1,14.54,700,1,12.43,700,1,14.63,200,2,12.42,700,1,14.78,100,1,ARL,347605109
1931,2025-07-17T16:21:13.079968994Z,2025-07-17T16:21:13.079968994Z,10,2,1108,C,A,9,14.78,100,0,165487,290387380,13.11,110,2,13.98,102,2,12.98,200,2,14.22,100,1,12.96,2,1,14.25,100,1,12.86,100,1,14.33,100,1,12.73,100,1,14.4,100,1,12.71,100,1,14.48,1400,2,12.5,700,1,14.51,100,1,12.46,100,1,14.54,700,1,12.43,700,1,14.63,200,2,12.42,700,1,14.8,100,1,ARL,349364213
1932,2025-07-17T16:21:13.155520730Z,2025-07-17T16:21:13.155520730Z,10,2,1108,C,A,9,14.8,100,0,165563,290388741,13.11,110,2,13.98,102,2,12.98,200,2,14.22,100,1,12.96,2,1,14.25,100,1,12.86,100,1,14.33,100,1,12.73,100,1,14.4,100,1,12.71,100,1,14.48,1400,2,12.5,700,1,14.51,100,1,12.46,100,1,14.54,700,1,12.43,700,1,14.63,200,2,12.42,700,1,14.96,100,1,ARL,347605169
1933,2025-07-17T16:21:13.214317987Z,2025-07-17T16:21:13.214317987Z,10,2,1108,C,A,4,14.4,100,0,165911,290389756,13.11,110,2,13.98,102,2,12.98,200,2,14.22,100,1,12.96,2,1,14.25,100,1,12.86,100,1,14.33,100,1,12.73,100,1,14.48,1400,2,12.71,100,1,14.51,100,1,12.5,700,1,14.54,700,1,12.46,100,1,14.63,200,2,12.43,700,1,14.96,100,1,12.42,700,1,15.06,100,1,ARL,347605617
1934,2025-07-17T16:21:13.214317987Z,2025-07-17T16:21:13.214317987Z,10,2,1108,A,A,8,14.96,100,130,165911,290389756,13.11,110,2,13.98,102,2,12.98,200,2,14.22,100,1,12.96,2,1,14.25,100,1,12.86,100,1,14.33,100,1,12.73,100,1,14.48,1400,2,12.71,100,1,14.51,100,1,12.5,700,1,14.54,700,1,12.46,100,1,14.63,200,2,12.43,700,1,14.96,200,2,12.42,700,1,15.06,100,1,ARL,349371829
1935,2025-07-17T16:21:13.236367880Z,2025-07-17T16:21:13.236367880Z,10,2,1108,A,A,8,14.68,700,130,165323,290390045,13.11,110,2,13.98,102,2,12.98,200,2,14.22,100,1,12.96,2,1,14.25,100,1,12.86,100,1,14.33,100,1,12.73,100,1,14.48,1400,2,12.71,100,1,14.51,100,1,12.5,700,1,14.54,700,1,12.46,100,1,14.63,200,2,12.43,700,1,14.68,700,1,12.42,700,1,14.96,200,2,ARL,349372241
1936,2025-07-17T16:21:13.533054792Z,2025-07-17T16:21:13.533054792Z,10,2,1108,C,A,3,14.33,100,130,165142,290394645,13.11,110,2,13.98,102,2,12.98,200,2,14.22,100,1,12.96,2,1,14.25,100,1,12.86,100,1,14.48,1400,2,12.73,100,1,14.51,100,1,12.71,100,1,14.54,700,1,12.5,700,1,14.63,200,2,12.46,100,1,14.68,700,1,12.43,700,1,14.96,200,2,12.42,700,1,15.06,100,1,ARL,349364205
1937,2025-07-17T16:21:13.533403508Z,2025-07-17T16:21:13.533403508Z,10,2,1108,A,A,6,14.6,100,130,165363,290394647,13.11,110,2,13.98,102,2,12.98,200,2,14.22,100,1,12.96,2,1,14.25,100,1,12.86,100,1,14.48,1400,2,12.73,100,1,14.51,100,1,12.71,100,1,14.54,700,1,12.5,700,1,14.6,100,1,12.46,100,1,14.63,200,2,12.43,700,1,14.68,700,1,12.42,700,1,14.96,200,2,ARL,349378277
1938,2025-07-17T16:21:13.617670801Z,2025-07-17T16:21:13.617670801Z,10,2,1108,A,A,9,14.81,100,130,165731,290395763,13.11,110,2,13.98,102,2,12.98,200,2,14.22,100,1,12.96,2,1,14.25,100,1,12.86,100,1,14.48,1400,2,12.73,100,1,14.51,100,1,12.71,100,1,14.54,700,1,12.5,700,1,14.6,100,1,12.46,100,1,14.63,200,2,12.43,700,1,14.68,700,1,12.42,700,1,14.81,100,1,ARL,349380345
1939,2025-07-17T16:21:13.617684550Z,2025-07-17T16:21:13.617684550Z,10,2,1108,C,A,2,14.25,100,130,165455,290395764,13.11,110,2,13.98,102,2,12.98,200,2,14.22,100,1,12.96,2,1,14.48,1400,2,12.86,100,1,14.51,100,1,12.73,100,1,14.54,700,1,12.71,100,1,14.6,100,1,12.5,700,1,14.63,200,2,12.46,100,1,14.68,700,1,12.43,700,1,14.81,100,1,12.42,700,1,14.96,200,2,ARL,347615553
1940,2025-07-17T16:21:13.652048799Z,2025-07-17T16:21:13.652048799Z,10,2,1108,A,A,1,13.99,100,130,165395,290396554,13.11,110,2,13.98,102,2,12.98,200,2,13.99,100,1,12.96,2,1,14.22,100,1,12.86,100,1,14.48,1400,2,12.73,100,1,14.51,100,1,12.71,100,1,14.54,700,1,12.5,700,1,14.6,100,1,12.46,100,1,14.63,200,2,12.43,700,1,14.68,700,1,12.42,700,1,14.81,100,1,ARL,349380925
1941,2025-07-17T16:21:13.742700842Z,2025-07-17T16:21:13.742700842Z,10,2,1108,A,A,5,14.53,100,0,166939,290397623,13.11,110,2,13.98,102,2,12.98,200,2,13.99,100,1,12.96,2,1,14.22,100,1,12.86,100,1,14.48,1400,2,12.73,100,1,14.51,100,1,12.71,100,1,14.53,100,1,12.5,700,1,14.54,700,1,12.46,100,1,14.6,100,1,12.43,700,1,14.63,200,2,12.42,700,1,14.68,700,1,ARL,349382189
1942,2025-07-17T16:21:13.742701630Z,2025-07-17T16:21:13.742701630Z,10,2,1108,C,A,0,13.98,100,130,166151,290397624,13.11,110,2,13.98,2,1,12.98,200,2,13.99,100,1,12.96,2,1,14.22,100,1,12.86,100,1,14.48,1400,2,12.73,100,1,14.51,100,1,12.71,100,1,14.53,100,1,12.5,700,1,14.54,700,1,12.46,100,1,14.6,100,1,12.43,700,1,14.63,200,2,12.42,700,1,14.68,700,1,ARL,347613877
1943,2025-07-17T16:21:14.030770739Z,2025-07-17T16:21:14.030770739Z,10,2,1108,C,A,4,14.51,100,130,165254,290403111,13.11,110,2,13.98,2,1,12.98,200,2,13.99,100,1,12.96,2,1,14.22,100,1,12.86,100,1,14.48,1400,2,12.73,100,1,14.53,100,1,12.71,100,1,14.54,700,1,12.5,700,1,14.6,100,1,12.46,100,1,14.63,200,2,12.43,700,1,14.68,700,1,12.42,700,1,14.81,100,1,ARL,349364905
1944,2025-07-17T16:21:14.030907193Z,2025-07-17T16:21:14.030907193Z,10,2,1108,A,A,9,14.77,100,130,165409,290403117,13.11,110,2,13.98,2,1,12.98,200,2,13.99,100,1,12.96,2,1,14.22,100,1,12.86,100,1,14.48,1400,2,12.73,100,1,14.53,100,1,12.71,100,1,14.54,700,1,12.5,700,1,14.6,100,1,12.46,100,1,14.63,200,2,12.43,700,1,14.68,700,1,12.42,700,1,14.77,100,1,ARL,349388057
1945,2025-07-17T16:21:14.045778918Z,2025-07-17T16:21:14.045778918Z,10,2,1108,C,A,7,14.63,100,0,165693,290403302,13.11,110,2,13.98,2,1,12.98,200,2,13.99,100,1,12.96,2,1,14.22,100,1,12.86,100,1,14.48,1400,2,12.73,100,1,14.53,100,1,12.71,100,1,14.54,700,1,12.5,700,1,14.6,100,1,12.46,100,1,14.63,100,1,12.43,700,1,14.68,700,1,12.42,700,1,14.77,100,1,ARL,349364233
1946,2025-07-17T16:21:14.046023656Z,2025-07-17T16:21:14.046023656Z,10,2,1108,C,A,7,14.63,100,0,165793,290403303,13.11,110,2,13.98,2,1,12.98,200,2,13.99,100,1,12.96,2,1,14.22,100,1,12.86,100,1,14.48,1400,2,12.73,100,1,14.53,100,1,12.71,100,1,14.54,700,1,12.5,700,1,14.6,100,1,12.46,100,1,14.68,700,1,12.43,700,1,14.77,100,1,12.42,700,1,14.81,100,1,ARL,349364085
1947,2025-07-17T16:21:14.046023656Z,2025-07-17T16:21:14.046023656Z,10,2,1108,A,A,10,14.87,100,130,165793,290403303,13.11,110,2,13.98,2,1,12.98,200,2,13.99,100,1,12.96,2,1,14.22,100,1,12.86,100,1,14.48,1400,2,12.73,100,1,14.53,100,1,12.71,100,1,14.54,700,1,12.5,700,1,14.6,100,1,12.46,100,1,14.68,700,1,12.43,700,1,14.77,100,1,12.42,700,1,14.81,100,1,ARL,349388385
1948,2025-07-17T16:21:18.838627443Z,2025-07-17T16:21:18.838627443Z,10,2,1108,C,B,0,13.11,10,130,165342,290472869,13.11,100,1,13.98,2,1,12.98,200,2,13.99,100,1,12.96,2,1,14.22,100,1,12.86,100,1,14.48,1400,2,12.73,100,1,14.53,100,1,12.71,100,1,14.54,700,1,12.5,700,1,14.6,100,1,12.46,100,1,14.68,700,1,12.43,700,1,14.77,100,1,12.42,700,1,14.81,100,1,ARL,349365825
1949,2025-07-17T16:21:19.432302263Z,2025-07-17T16:21:19.432302263Z,10,2,1108,A,A,3,14.32,100,130,166067,290480833,13.11,100,1,13.98,2,1,12.98,200,2,13.99,100,1,12.96,2,1,14.22,100,1,12.86,100,1,14.32,100,1,12.73,100,1,14.48,1400,2,12.71,100,1,14.53,100,1,12.5,700,1,14.54,700,1,12.46,100,1,14.6,100,1,12.43,700,1,14.68,700,1,12.42,700,1,14.77,100,1,ARL,349491773
1950,2025-07-17T16:21:19.432703556Z,2025-07-17T16:21:19.432703556Z,10,2,1108,A,A,3,14.32,100,130,165766,290480840,13.11,100,1,13.98,2,1,12.98,200,2,13.99,100,1,12.96,2,1,14.22,100,1,12.86,100,1,14.32,200,2,12.73,100,1,14.48,1400,2,12.71,100,1,14.53,100,1,12.5,700,1,14.54,700,1,12.46,100,1,14.6,100,1,12.43,700,1,14.68,700,1,12.42,700,1,14.77,100,1,ARL,349491781
1951,2025-07-17T16:21:21.559829242Z,2025-07-17T16:21:21.559829242Z,10,2,1108,C,A,3,14.32,100,0,165709,290520485,13.11,100,1,13.98,2,1,12.98,200,2,13.99,100,1,12.96,2,1,14.22,100,1,12.86,100,1,14.32,100,1,12.73,100,1,14.48,1400,2,12.71,100,1,14.53,100,1,12.5,700,1,14.54,700,1,12.46,100,1,14.6,100,1,12.43,700,1,14.68,700,1,12.42,700,1,14.77,100,1,ARL,349491781
1952,2025-07-17T16:21:21.559952130Z,2025-07-17T16:21:21.559952130Z,10,2,1108,C,A,3,14.32,100,0,165526,290520492,13.11,100,1,13.98,2,1,12.98,200,2,13.99,100,1,12.96,2,1,14.22,100,1,12.86,100,1,14.48,1400,2,12.73,100,1,14.53,100,1,12.71,100,1,14.54,700,1,12.5,700,1,14.6,100,1,12.46,100,1,14.68,700,1,12.43,700,1,14.77,100,1,12.42,700,1,14.81,100,1,ARL,349491773
1953,2025-07-17T16:21:21.559952130Z,2025-07-17T16:21:21.559952130Z,10,2,1108,A,A,10,14.88,100,130,165526,290520492,13.11,100,1,13.98,2,1,12.98,200,2,13.99,100,1,12.96,2,1,14.22,100,1,12.86,100,1,14.48,1400,2,12.73,100,1,14.53,100,1,12.71,100,1,14.54,700,1,12.5,700,1,14.6,100,1,12.46,100,1,14.68,700,1,12.43,700,1,14.77,100,1,12.42,700,1,14.81,100,1,ARL,349547205
1954,2025-07-17T16:21:24.785797985Z,2025-07-17T16:21:24.785797985Z,10,2,1108,C,B,2,12.96,2,0,165527,290591357,13.11,100,1,13.98,2,1,12.98,200,2,13.99,100,1,12.86,100,1,14.22,100,1,12.73,100,1,14.48,1400,2,12.71,100,1,14.53,100,1,12.5,700,1,14.54,700,1,12.46,100,1,14.6,100,1,12.43,700,1,14.68,700,1,12.42,700,1,14.77,100,1,12.37,700,1,14.81,100,1,ARL,348838809
1955,2025-07-17T16:21:24.785797985Z,2025-07-17T16:21:24.785797985Z,10,2,1108,A,B,1,13.04,2,130,165527,290591357,13.11,100,1,13.98,2,1,13.04,2,1,13.99,100,1,12.98,200,2,14.22,100,1,12.86,100,1,14.48,1400,2,12.73,100,1,14.53,100,1,12.71,100,1,14.54,700,1,12.5,700,1,14.6,100,1,12.46,100,1,14.68,700,1,12.43,700,1,14.77,100,1,12.42,700,1,14.81,100,1,ARL,349635277
1956,2025-07-17T16:21:30.041717299Z,2025-07-17T16:21:30.041717299Z,10,2,1108,A,A,3,14.33,100,130,165634,290665095,13.11,100,1,13.98,2,1,13.04,2,1,13.99,100,1,12.98,200,2,14.22,100,1,12.86,100,1,14.33,100,1,12.73,100,1,14.48,1400,2,12.71,100,1,14.53,100,1,12.5,700,1,14.54,700,1,12.46,100,1,14.6,100,1,12.43,700,1,14.68,700,1,12.42,700,1,14.77,100,1,ARL,349727893
1957,2025-07-17T16:21:30.041902504Z,2025-07-17T16:21:30.041902504Z,10,2,1108,A,A,3,14.33,100,130,165620,290665107,13.11,100,1,13.98,2,1,13.04,2,1,13.99,100,1,12.98,200,2,14.22,100,1,12.86,100,1,14.33,200,2,12.73,100,1,14.48,1400,2,12.71,100,1,14.53,100,1,12.5,700,1,14.54,700,1,12.46,100,1,14.6,100,1,12.43,700,1,14.68,700,1,12.42,700,1,14.77,100,1,ARL,349727897
1958,2025-07-17T16:21:32.891396207Z,2025-07-17T16:21:32.891396207Z,10,2,1108,C,A,3,14.33,100,0,165614,290706797,13.11,100,1,13.98,2,1,13.04,2,1,13.99,100,1,12.98,200,2,14.22,100,1,12.86,100,1,14.33,100,1,12.73,100,1,14.48,1400,2,12.71,100,1,14.53,100,1,12.5,700,1,14.54,700,1,12.46,100,1,14.6,100,1,12.43,700,1,14.68,700,1,12.42,700,1,14.77,100,1,ARL,349727893
1959,2025-07-17T16:21:32.920695054Z,2025-07-17T16:21:32.920695054Z,10,2,1108,C,A,3,14.33,100,0,165646,290707080,13.11,100,1,13.98,2,1,13.04,2,1,13.99,100,1,12.98,200,2,14.22,100,1,12.86,100,1,14.48,1400,2,12.73,100,1,14.53,100,1,12.71,100,1,14.54,700,1,12.5,700,1,14.6,100,1,12.46,100,1,14.68,700,1,12.43,700,1,14.77,100,1,12.42,700,1,14.81,100,1,ARL,349727897
1960,2025-07-17T16:21:32.920695054Z,2025-07-17T16:21:32.920695054Z,10,2,1108,A,A,10,14.88,100,130,165646,290707080,13.11,100,1,13.98,2,1,13.04,2,1,13.99,100,1,12.98,200,2,14.22,100,1,12.86,100,1,14.48,1400,2,12.73,100,1,14.53,100,1,12.71,100,1,14.54,700,1,12.5,700,1,14.6,100,1,12.46,100,1,14.68,700,1,12.43,700,1,14.77,100,1,12.42,700,1,14.81,100,1,ARL,349786613
1961,2025-07-17T16:22:10.251792275Z,2025-07-17T16:22:10.251792275Z,10,2,1108,A,A,0,13.43,15,128,166908,291313152,13.11,100,1,13.43,15,1,13.04,2,1,13.98,2,1,12.98,200,2,13.99,100,1,12.86,100,1,14.22,100,1,12.73,100,1,14.48,1400,2,12.71,100,1,14.53,100,1,12.5,700,1,14.54,700,1,12.46,100,1,14.6,100,1,12.43,700,1,14.68,700,1,12.42,700,1,14.77,100,1,ARL,350555261
1962,2025-07-17T16:22:10.252282744Z,2025-07-17T16:22:10.252282744Z,10,2,1108,A,A,4,14.33,100,130,166202,291313277,13.11,100,1,13.43,15,1,13.04,2,1,13.98,2,1,12.98,200,2,13.99,100,1,12.86,100,1,14.22,100,1,12.73,100,1,14.33,100,1,12.71,100,1,14.48,1400,2,12.5,700,1,14.53,100,1,12.46,100,1,14.54,700,1,12.43,700,1,14.6,100,1,12.42,700,1,14.68,700,1,ARL,350555469
1963,2025-07-17T16:22:10.253020717Z,2025-07-17T16:22:10.253020717Z,10,2,1108,A,A,4,14.33,100,130,165897,291313433,13.11,100,1,13.43,15,1,13.04,2,1,13.98,2,1,12.98,200,2,13.99,100,1,12.86,100,1,14.22,100,1,12.73,100,1,14.33,200,2,12.71,100,1,14.48,1400,2,12.5,700,1,14.53,100,1,12.46,100,1,14.54,700,1,12.43,700,1,14.6,100,1,12.42,700,1,14.68,700,1,ARL,350555717
1964,2025-07-17T16:22:10.259042453Z,2025-07-17T16:22:10.259042453Z,10,2,1108,C,A,2,13.99,100,0,165623,291313986,13.11,100,1,13.43,15,1,13.04,2,1,13.98,2,1,12.98,200,2,14.22,100,1,12.86,100,1,14.33,200,2,12.73,100,1,14.48,1400,2,12.71,100,1,14.53,100,1,12.5,700,1,14.54,700,1,12.46,100,1,14.6,100,1,12.43,700,1,14.68,700,1,12.42,700,1,14.77,100,1,ARL,349380925
1965,2025-07-17T16:22:10.259042453Z,2025-07-17T16:22:10.259042453Z,10,2,1108,A,A,1,13.96,100,130,165623,291313986,13.11,100,1,13.43,15,1,13.04,2,1,13.96,100,1,12.98,200,2,13.98,2,1,12.86,100,1,14.22,100,1,12.73,100,1,14.33,200,2,12.71,100,1,14.48,1400,2,12.5,700,1,14.53,100,1,12.46,100,1,14.54,700,1,12.43,700,1,14.6,100,1,12.42,700,1,14.68,700,1,ARL,350556253
1966,2025-07-17T16:22:10.651403186Z,2025-07-17T16:22:10.651403186Z,10,2,1108,C,A,0,13.43,15,130,165512,291322198,13.11,100,1,13.96,100,1,13.04,2,1,13.98,2,1,12.98,200,2,14.22,100,1,12.86,100,1,14.33,200,2,12.73,100,1,14.48,1400,2,12.71,100,1,14.53,100,1,12.5,700,1,14.54,700,1,12.46,100,1,14.6,100,1,12.43,700,1,14.68,700,1,12.42,700,1,14.77,100,1,ARL,350555261
1967,2025-07-17T16:22:11.256169948Z,2025-07-17T16:22:11.256169948Z,10,2,1108,C,A,3,14.33,100,0,165226,291329858,13.11,100,1,13.96,100,1,13.04,2,1,13.98,2,1,12.98,200,2,14.22,100,1,12.86,100,1,14.33,100,1,12.73,100,1,14.48,1400,2,12.71,100,1,14.53,100,1,12.5,700,1,14.54,700,1,12.46,100,1,14.6,100,1,12.43,700,1,14.68,700,1,12.42,700,1,14.77,100,1,ARL,350555717
1968,2025-07-17T16:22:11.293940494Z,2025-07-17T16:22:11.293940494Z,10,2,1108,C,A,3,14.33,100,0,165473,291330189,13.11,100,1,13.96,100,1,13.04,2,1,13.98,2,1,12.98,200,2,14.22,100,1,12.86,100,1,14.48,1400,2,12.73,100,1,14.53,100,1,12.71,100,1,14.54,700,1,12.5,700,1,14.6,100,1,12.46,100,1,14.68,700,1,12.43,700,1,14.77,100,1,12.42,700,1,14.81,100,1,ARL,350555469
1969,2025-07-17T16:22:11.293940494Z,2025-07-17T16:22:11.293940494Z,10,2,1108,A,A,10,14.86,100,130,165473,291330189,13.11,100,1,13.96,100,1,13.04,2,1,13.98,2,1,12.98,200,2,14.22,100,1,12.86,100,1,14.48,1400,2,12.73,100,1,14.53,100,1,12.71,100,1,14.54,700,1,12.5,700,1,14.6,100,1,12.46,100,1,14.68,700,1,12.43,700,1,14.77,100,1,12.42,700,1,14.81,100,1,ARL,350574501
1970,2025-07-17T16:23:50.726353370Z,2025-07-17T16:23:50.726353370Z,10,2,1108,A,A,3,14.33,100,130,165616,292930335,13.11,100,1,13.96,100,1,13.04,2,1,13.98,2,1,12.98,200,2,14.22,100,1,12.86,100,1,14.33,100,1,12.73,100,1,14.48,1400,2,12.71,100,1,14.53,100,1,12.5,700,1,14.54,700,1,12.46,100,1,14.6,100,1,12.43,700,1,14.68,700,1,12.42,700,1,14.77,100,1,ARL,352599713
1971,2025-07-17T16:23:50.751628250Z,2025-07-17T16:23:50.751628250Z,10,2,1108,A,A,3,14.33,100,130,165377,292931023,13.11,100,1,13.96,100,1,13.04,2,1,13.98,2,1,12.98,200,2,14.22,100,1,12.86,100,1,14.33,200,2,12.73,100,1,14.48,1400,2,12.71,100,1,14.53,100,1,12.5,700,1,14.54,700,1,12.46,100,1,14.6,100,1,12.43,700,1,14.68,700,1,12.42,700,1,14.77,100,1,ARL,352600973
1972,2025-07-17T16:23:55.522760301Z,2025-07-17T16:23:55.522760301Z,10,2,1108,A,A,0,13.42,15,130,165157,293010586,13.11,100,1,13.42,15,1,13.04,2,1,13.96,100,1,12.98,200,2,13.98,2,1,12.86,100,1,14.22,100,1,12.73,100,1,14.33,200,2,12.71,100,1,14.48,1400,2,12.5,700,1,14.53,100,1,12.46,100,1,14.54,700,1,12.43,700,1,14.6,100,1,12.42,700,1,14.68,700,1,ARL,352702077
1973,2025-07-17T16:23:56.914694445Z,2025-07-17T16:23:56.914694445Z,10,2,1108,C,A,1,13.96,100,0,165734,293025765,13.11,100,1,13.42,15,1,13.04,2,1,13.98,2,1,12.98,200,2,14.22,100,1,12.86,100,1,14.33,200,2,12.73,100,1,14.48,1400,2,12.71,100,1,14.53,100,1,12.5,700,1,14.54,700,1,12.46,100,1,14.6,100,1,12.43,700,1,14.68,700,1,12.42,700,1,14.77,100,1,ARL,350556253
1974,2025-07-17T16:23:56.914694445Z,2025-07-17T16:23:56.914694445Z,10,2,1108,A,A,1,13.95,100,130,165734,293025765,13.11,100,1,13.42,15,1,13.04,2,1,13.95,100,1,12.98,200,2,13.98,2,1,12.86,100,1,14.22,100,1,12.73,100,1,14.33,200,2,12.71,100,1,14.48,1400,2,12.5,700,1,14.53,100,1,12.46,100,1,14.54,700,1,12.43,700,1,14.6,100,1,12.42,700,1,14.68,700,1,ARL,352722381
1975,2025-07-17T16:23:58.527719150Z,2025-07-17T16:23:58.527719150Z,10,2,1108,A,A,0,13.4,15,130,165383,293099007,13.11,100,1,13.4,15,1,13.04,2,1,13.42,15,1,12.98,200,2,13.95,100,1,12.86,100,1,13.98,2,1,12.73,100,1,14.22,100,1,12.71,100,1,14.33,200,2,12.5,700,1,14.48,1400,2,12.46,100,1,14.53,100,1,12.43,700,1,14.54,700,1,12.42,700,1,14.6,100,1,ARL,352791109
1976,2025-07-17T16:23:58.631706924Z,2025-07-17T16:23:58.631706924Z,10,2,1108,C,A,2,13.95,100,0,165405,293104471,13.11,100,1,13.4,15,1,13.04,2,1,13.42,15,1,12.98,200,2,13.98,2,1,12.86,100,1,14.22,100,1,12.73,100,1,14.33,200,2,12.71,100,1,14.48,1400,2,12.5,700,1,14.53,100,1,12.46,100,1,14.54,700,1,12.43,700,1,14.6,100,1,12.42,700,1,14.68,700,1,ARL,352722381
1977,2025-07-17T16:23:58.631706924Z,2025-07-17T16:23:58.631706924Z,10,2,1108,A,A,2,13.93,100,130,165405,293104471,13.11,100,1,13.4,15,1,13.04,2,1,13.42,15,1,12.98,200,2,13.93,100,1,12.86,100,1,13.98,2,1,12.73,100,1,14.22,100,1,12.71,100,1,14.33,200,2,12.5,700,1,14.48,1400,2,12.46,100,1,14.53,100,1,12.43,700,1,14.54,700,1,12.42,700,1,14.6,100,1,ARL,352794377
1978,2025-07-17T16:24:02.427208036Z,2025-07-17T16:24:02.427208036Z,10,2,1108,C,A,1,13.42,15,130,165516,293179655,13.11,100,1,13.4,15,1,13.04,2,1,13.93,100,1,12.98,200,2,13.98,2,1,12.86,100,1,14.22,100,1,12.73,100,1,14.33,200,2,12.71,100,1,14.48,1400,2,12.5,700,1,14.53,100,1,12.46,100,1,14.54,700,1,12.43,700,1,14.6,100,1,12.42,700,1,14.68,700,1,ARL,352702077
1979,2025-07-17T16:24:04.377672438Z,2025-07-17T16:24:04.377672438Z,10,2,1108,A,A,0,13.38,15,130,165356,293217696,13.11,100,1,13.38,15,1,13.04,2,1,13.4,15,1,12.98,200,2,13.93,100,1,12.86,100,1,13.98,2,1,12.73,100,1,14.22,100,1,12.71,100,1,14.33,200,2,12.5,700,1,14.48,1400,2,12.46,100,1,14.53,100,1,12.43,700,1,14.54,700,1,12.42,700,1,14.6,100,1,ARL,352939445
1980,2025-07-17T16:24:04.378725117Z,2025-07-17T16:24:04.378725117Z,10,2,1108,C,A,2,13.93,100,0,165952,293217731,13.11,100,1,13.38,15,1,13.04,2,1,13.4,15,1,12.98,200,2,13.98,2,1,12.86,100,1,14.22,100,1,12.73,100,1,14.33,200,2,12.71,100,1,14.48,1400,2,12.5,700,1,14.53,100,1,12.46,100,1,14.54,700,1,12.43,700,1,14.6,100,1,12.42,700,1,14.68,700,1,ARL,352794377
1981,2025-07-17T16:24:04.378725117Z,2025-07-17T16:24:04.378725117Z,10,2,1108,A,A,2,13.91,100,130,165952,293217731,13.11,100,1,13.38,15,1,13.04,2,1,13.4,15,1,12.98,200,2,13.91,100,1,12.86,100,1,13.98,2,1,12.73,100,1,14.22,100,1,12.71,100,1,14.33,200,2,12.5,700,1,14.48,1400,2,12.46,100,1,14.53,100,1,12.43,700,1,14.54,700,1,12.42,700,1,14.6,100,1,ARL,352939465
1982,2025-07-17T16:25:06.191285410Z,2025-07-17T16:25:06.191285410Z,10,2,1108,C,B,1,13.04,2,0,165713,294247609,13.11,100,1,13.38,15,1,12.98,200,2,13.4,15,1,12.86,100,1,13.91,100,1,12.73,100,1,13.98,2,1,12.71,100,1,14.22,100,1,12.5,700,1,14.33,200,2,12.46,100,1,14.48,1400,2,12.43,700,1,14.53,100,1,12.42,700,1,14.54,700,1,12.37,700,1,14.6,100,1,ARL,349635277
1983,2025-07-17T16:25:06.191285410Z,2025-07-17T16:25:06.191285410Z,10,2,1108,A,B,0,13.11,2,130,165713,294247609,13.11,102,2,13.38,15,1,12.98,200,2,13.4,15,1,12.86,100,1,13.91,100,1,12.73,100,1,13.98,2,1,12.71,100,1,14.22,100,1,12.5,700,1,14.33,200,2,12.46,100,1,14.48,1400,2,12.43,700,1,14.53,100,1,12.42,700,1,14.54,700,1,12.37,700,1,14.6,100,1,ARL,354187617
1984,2025-07-17T16:25:08.976249966Z,2025-07-17T16:25:08.976249966Z,10,2,1108,C,A,3,13.98,2,0,165766,294349676,13.11,102,2,13.38,15,1,12.98,200,2,13.4,15,1,12.86,100,1,13.91,100,1,12.73,100,1,14.22,100,1,12.71,100,1,14.33,200,2,12.5,700,1,14.48,1400,2,12.46,100,1,14.53,100,1,12.43,700,1,14.54,700,1,12.42,700,1,14.6,100,1,12.37,700,1,14.68,700,1,ARL,349366297
1985,2025-07-17T16:25:08.976249966Z,2025-07-17T16:25:08.976249966Z,10,2,1108,A,A,2,13.91,2,130,165766,294349676,13.11,102,2,13.38,15,1,12.98,200,2,13.4,15,1,12.86,100,1,13.91,102,2,12.73,100,1,14.22,100,1,12.71,100,1,14.33,200,2,12.5,700,1,14.48,1400,2,12.46,100,1,14.53,100,1,12.43,700,1,14.54,700,1,12.42,700,1,14.6,100,1,12.37,700,1,14.68,700,1,ARL,354292533
1986,2025-07-17T16:25:35.128903877Z,2025-07-17T16:25:35.128903877Z,10,2,1108,C,A,0,13.38,15,128,168307,294934217,13.11,102,2,13.4,15,1,12.98,200,2,13.91,102,2,12.86,100,1,14.22,100,1,12.73,100,1,14.33,200,2,12.71,100,1,14.48,1400,2,12.5,700,1,14.53,100,1,12.46,100,1,14.54,700,1,12.43,700,1,14.6,100,1,12.42,700,1,14.68,700,1,12.37,700,1,14.77,100,1,ARL,352939445
1987,2025-07-17T16:25:39.510341866Z,2025-07-17T16:25:39.510341866Z,10,2,1108,C,A,0,13.4,15,130,165345,295034059,13.11,102,2,13.91,102,2,12.98,200,2,14.22,100,1,12.86,100,1,14.33,200,2,12.73,100,1,14.48,1400,2,12.71,100,1,14.53,100,1,12.5,700,1,14.54,700,1,12.46,100,1,14.6,100,1,12.43,700,1,14.68,700,1,12.42,700,1,14.77,100,1,12.37,700,1,14.81,100,1,ARL,352791109
1988,2025-07-17T16:25:39.510992800Z,2025-07-17T16:25:39.510992800Z,10,2,1108,C,A,2,14.33,100,0,166062,295034078,13.11,102,2,13.91,102,2,12.98,200,2,14.22,100,1,12.86,100,1,14.33,100,1,12.73,100,1,14.48,1400,2,12.71,100,1,14.53,100,1,12.5,700,1,14.54,700,1,12.46,100,1,14.6,100,1,12.43,700,1,14.68,700,1,12.42,700,1,14.77,100,1,12.37,700,1,14.81,100,1,ARL,352599713
1989,2025-07-17T16:25:39.510992800Z,2025-07-17T16:25:39.510992800Z,10,2,1108,A,A,9,14.8,100,130,166062,295034078,13.11,102,2,13.91,102,2,12.98,200,2,14.22,100,1,12.86,100,1,14.33,100,1,12.73,100,1,14.48,1400,2,12.71,100,1,14.53,100,1,12.5,700,1,14.54,700,1,12.46,100,1,14.6,100,1,12.43,700,1,14.68,700,1,12.42,700,1,14.77,100,1,12.37,700,1,14.8,100,1,ARL,355038285
1990,2025-07-17T16:25:39.511606124Z,2025-07-17T16:25:39.511606124Z,10,2,1108,C,A,2,14.33,100,0,165880,295034094,13.11,102,2,13.91,102,2,12.98,200,2,14.22,100,1,12.86,100,1,14.48,1400,2,12.73,100,1,14.53,100,1,12.71,100,1,14.54,700,1,12.5,700,1,14.6,100,1,12.46,100,1,14.68,700,1,12.43,700,1,14.77,100,1,12.42,700,1,14.8,100,1,12.37,700,1,14.81,100,1,ARL,352600973
1991,2025-07-17T16:25:39.511606124Z,2025-07-17T16:25:39.511606124Z,10,2,1108,A,A,8,14.8,100,130,165880,295034094,13.11,102,2,13.91,102,2,12.98,200,2,14.22,100,1,12.86,100,1,14.48,1400,2,12.73,100,1,14.53,100,1,12.71,100,1,14.54,700,1,12.5,700,1,14.6,100,1,12.46,100,1,14.68,700,1,12.43,700,1,14.77,100,1,12.42,700,1,14.8,200,2,12.37,700,1,14.81,100,1,ARL,355038317
1992,2025-07-17T16:25:39.513422230Z,2025-07-17T16:25:39.513422230Z,10,2,1108,A,B,0,13.11,10,130,165382,295034123,13.11,112,3,13.91,102,2,12.98,200,2,14.22,100,1,12.86,100,1,14.48,1400,2,12.73,100,1,14.53,100,1,12.71,100,1,14.54,700,1,12.5,700,1,14.6,100,1,12.46,100,1,14.68,700,1,12.43,700,1,14.77,100,1,12.42,700,1,14.8,200,2,12.37,700,1,14.81,100,1,ARL,355038373
1993,2025-07-17T16:25:40.874808027Z,2025-07-17T16:25:40.874808027Z,10,2,1108,A,A,0,13.9,15,130,171401,295093819,13.11,112,3,13.9,15,1,12.98,200,2,13.91,102,2,12.86,100,1,14.22,100,1,12.73,100,1,14.48,1400,2,12.71,100,1,14.53,100,1,12.5,700,1,14.54,700,1,12.46,100,1,14.6,100,1,12.43,700,1,14.68,700,1,12.42,700,1,14.77,100,1,12.37,700,1,14.8,200,2,ARL,355097305
1994,2025-07-17T16:25:49.509442229Z,2025-07-17T16:25:49.509442229Z,10,2,1108,C,B,0,13.11,10,130,165254,295316849,13.11,102,2,13.9,15,1,12.98,200,2,13.91,102,2,12.86,100,1,14.22,100,1,12.73,100,1,14.48,1400,2,12.71,100,1,14.53,100,1,12.5,700,1,14.54,700,1,12.46,100,1,14.6,100,1,12.43,700,1,14.68,700,1,12.42,700,1,14.77,100,1,12.37,700,1,14.8,200,2,ARL,355038373
1995,2025-07-17T16:25:54.511765715Z,2025-07-17T16:25:54.511765715Z,10,2,1108,A,A,0,13.84,15,130,165643,295392773,13.11,102,2,13.84,15,1,12.98,200,2,13.9,15,1,12.86,100,1,13.91,102,2,12.73,100,1,14.22,100,1,12.71,100,1,14.48,1400,2,12.5,700,1,14.53,100,1,12.46,100,1,14.54,700,1,12.43,700,1,14.6,100,1,12.42,700,1,14.68,700,1,12.37,700,1,14.77,100,1,ARL,355455441
1996,2025-07-17T16:25:54.512035936Z,2025-07-17T16:25:54.512035936Z,10,2,1108,C,A,2,13.91,100,0,165514,295392775,13.11,102,2,13.84,15,1,12.98,200,2,13.9,15,1,12.86,100,1,13.91,2,1,12.73,100,1,14.22,100,1,12.71,100,1,14.48,1400,2,12.5,700,1,14.53,100,1,12.46,100,1,14.54,700,1,12.43,700,1,14.6,100,1,12.42,700,1,14.68,700,1,12.37,700,1,14.77,100,1,ARL,352939465
1997,2025-07-17T16:25:54.512035936Z,2025-07-17T16:25:54.512035936Z,10,2,1108,A,A,1,13.85,100,130,165514,295392775,13.11,102,2,13.84,15,1,12.98,200,2,13.85,100,1,12.86,100,1,13.9,15,1,12.73,100,1,13.91,2,1,12.71,100,1,14.22,100,1,12.5,700,1,14.48,1400,2,12.46,100,1,14.53,100,1,12.43,700,1,14.54,700,1,12.42,700,1,14.6,100,1,12.37,700,1,14.68,700,1,ARL,355455445
1998,2025-07-17T16:25:54.534917732Z,2025-07-17T16:25:54.534917732Z,10,2,1108,C,A,4,14.22,100,130,165347,295392911,13.11,102,2,13.84,15,1,12.98,200,2,13.85,100,1,12.86,100,1,13.9,15,1,12.73,100,1,13.91,2,1,12.71,100,1,14.48,1400,2,12.5,700,1,14.53,100,1,12.46,100,1,14.54,700,1,12.43,700,1,14.6,100,1,12.42,700,1,14.68,700,1,12.37,700,1,14.77,100,1,ARL,349366121
1999,2025-07-17T16:25:54.534970016Z,2025-07-17T16:25:54.534970016Z,10,2,1108,A,A,4,14.13,100,130,165651,295392912,13.11,102,2,13.84,15,1,12.98,200,2,13.85,100,1,12.86,100,1,13.9,15,1,12.73,100,1,13.91,2,1,12.71,100,1,14.13,100,1,12.5,700,1,14.48,1400,2,12.46,100,1,14.53,100,1,12.43,700,1,14.54,700,1,12.42,700,1,14.6,100,1,12.37,700,1,14.68,700,1,ARL,355455809
2000,2025-07-17T16:26:01.563424507Z,2025-07-17T16:26:01.563424507Z,10,2,1108,C,A,2,13.9,15,130,165420,295507323,13.11,102,2,13.84,15,1,12.98,200,2,13.85,100,1,12.86,100,1,13.91,2,1,12.73,100,1,14.13,100,1,12.71,100,1,14.48,1400,2,12.5,700,1,14.53,100,1,12.46,100,1,14.54,700,1,12.43,700,1,14.6,100,1,12.42,700,1,14.68,700,1,12.37,700,1,14.77,100,1,ARL,355097305
2001,2025-07-17T16:26:05.322373598Z,2025-07-17T16:26:05.322373598Z,10,2,1108,A,A,0,13.82,15,130,165285,295580795,13.11,102,2,13.82,15,1,12.98,200,2,13.84,15,1,12.86,100,1,13.85,100,1,12.73,100,1,13.91,2,1,12.71,100,1,14.13,100,1,12.5,700,1,14.48,1400,2,12.46,100,1,14.53,100,1,12.43,700,1,14.54,700,1,12.42,700,1,14.6,100,1,12.37,700,1,14.68,700,1,ARL,355692501
2002,2025-07-17T16:26:05.323503152Z,2025-07-17T16:26:05.323503152Z,10,2,1108,C,A,2,13.85,100,0,166197,295580842,13.11,102,2,13.82,15,1,12.98,200,2,13.84,15,1,12.86,100,1,13.91,2,1,12.73,100,1,14.13,100,1,12.71,100,1,14.48,1400,2,12.5,700,1,14.53,100,1,12.46,100,1,14.54,700,1,12.43,700,1,14.6,100,1,12.42,700,1,14.68,700,1,12.37,700,1,14.77,100,1,ARL,355455445
2003,2025-07-17T16:26:05.323503152Z,2025-07-17T16:26:05.323503152Z,10,2,1108,A,A,1,13.83,100,130,166197,295580842,13.11,102,2,13.82,15,1,12.98,200,2,13.83,100,1,12.86,100,1,13.84,15,1,12.73,100,1,13.91,2,1,12.71,100,1,14.13,100,1,12.5,700,1,14.48,1400,2,12.46,100,1,14.53,100,1,12.43,700,1,14.54,700,1,12.42,700,1,14.6,100,1,12.37,700,1,14.68,700,1,ARL,355692553
2004,2025-07-17T16:26:05.328155098Z,2025-07-17T16:26:05.328155098Z,10,2,1108,A,A,9,14.62,100,130,165539,295581043,13.11,102,2,13.82,15,1,12.98,200,2,13.83,100,1,12.86,100,1,13.84,15,1,12.73,100,1,13.91,2,1,12.71,100,1,14.13,100,1,12.5,700,1,14.48,1400,2,12.46,100,1,14.53,100,1,12.43,700,1,14.54,700,1,12.42,700,1,14.6,100,1,12.37,700,1,14.62,100,1,ARL,355692649
2005,2025-07-17T16:26:10.885204270Z,2025-07-17T16:26:10.885204270Z,10,2,1108,C,A,2,13.84,15,128,174881,295674513,13.11,102,2,13.82,15,1,12.98,200,2,13.83,100,1,12.86,100,1,13.91,2,1,12.73,100,1,14.13,100,1,12.71,100,1,14.48,1400,2,12.5,700,1,14.53,100,1,12.46,100,1,14.54,700,1,12.43,700,1,14.6,100,1,12.42,700,1,14.62,100,1,12.37,700,1,14.68,700,1,ARL,355455441
2006,2025-07-17T16:26:12.458607766Z,2025-07-17T16:26:12.458607766Z,10,2,1108,A,A,0,13.8,15,130,165246,295697152,13.11,102,2,13.8,15,1,12.98,200,2,13.82,15,1,12.86,100,1,13.83,100,1,12.73,100,1,13.91,2,1,12.71,100,1,14.13,100,1,12.5,700,1,14.48,1400,2,12.46,100,1,14.53,100,1,12.43,700,1,14.54,700,1,12.42,700,1,14.6,100,1,12.37,700,1,14.62,100,1,ARL,355834369
2007,2025-07-17T16:26:12.458873979Z,2025-07-17T16:26:12.458873979Z,10,2,1108,C,A,2,13.83,100,0,165521,295697153,13.11,102,2,13.8,15,1,12.98,200,2,13.82,15,1,12.86,100,1,13.91,2,1,12.73,100,1,14.13,100,1,12.71,100,1,14.48,1400,2,12.5,700,1,14.53,100,1,12.46,100,1,14.54,700,1,12.43,700,1,14.6,100,1,12.42,700,1,14.62,100,1,12.37,700,1,14.68,700,1,ARL,355692553
2008,2025-07-17T16:26:12.458873979Z,2025-07-17T16:26:12.458873979Z,10,2,1108,A,A,1,13.81,100,130,165521,295697153,13.11,102,2,13.8,15,1,12.98,200,2,13.81,100,1,12.86,100,1,13.82,15,1,12.73,100,1,13.91,2,1,12.71,100,1,14.13,100,1,12.5,700,1,14.48,1400,2,12.46,100,1,14.53,100,1,12.43,700,1,14.54,700,1,12.42,700,1,14.6,100,1,12.37,700,1,14.62,100,1,ARL,355834377
2009,2025-07-17T16:26:12.460621327Z,2025-07-17T16:26:12.460621327Z,10,2,1108,A,A,10,14.68,100,130,165569,295697158,13.11,102,2,13.8,15,1,12.98,200,2,13.81,100,1,12.86,100,1,13.82,15,1,12.73,100,1,13.91,2,1,12.71,100,1,14.13,100,1,12.5,700,1,14.48,1400,2,12.46,100,1,14.53,100,1,12.43,700,1,14.54,700,1,12.42,700,1,14.6,100,1,12.37,700,1,14.62,100,1,ARL,355834413
2010,2025-07-17T16:26:12.461023943Z,2025-07-17T16:26:12.461023943Z,10,2,1108,A,A,10,14.68,100,130,165503,295697159,13.11,102,2,13.8,15,1,12.98,200,2,13.81,100,1,12.86,100,1,13.82,15,1,12.73,100,1,13.91,2,1,12.71,100,1,14.13,100,1,12.5,700,1,14.48,1400,2,12.46,100,1,14.53,100,1,12.43,700,1,14.54,700,1,12.42,700,1,14.6,100,1,12.37,700,1,14.62,100,1,ARL,355834425
2011,2025-07-17T16:26:21.188218529Z,2025-07-17T16:26:21.188218529Z,10,2,1108,C,B,0,13.11,2,0,165829,295810309,13.11,100,1,13.8,15,1,12.98,200,2,13.81,100,1,12.86,100,1,13.82,15,1,12.73,100,1,13.91,2,1,12.71,100,1,14.13,100,1,12.5,700,1,14.48,1400,2,12.46,100,1,14.53,100,1,12.43,700,1,14.54,700,1,12.42,700,1,14.6,100,1,12.37,700,1,14.62,100,1,ARL,354187617
2012,2025-07-17T16:26:21.188218529Z,2025-07-17T16:26:21.188218529Z,10,2,1108,A,B,1,13.01,2,130,165829,295810309,13.11,100,1,13.8,15,1,13.01,2,1,13.81,100,1,12.98,200,2,13.82,15,1,12.86,100,1,13.91,2,1,12.73,100,1,14.13,100,1,12.71,100,1,14.48,1400,2,12.5,700,1,14.53,100,1,12.46,100,1,14.54,700,1,12.43,700,1,14.6,100,1,12.42,700,1,14.62,100,1,ARL,355990209
2013,2025-07-17T16:26:22.849483693Z,2025-07-17T16:26:22.849483693Z,10,2,1108,C,A,2,13.82,15,130,165349,295833352,13.11,100,1,13.8,15,1,13.01,2,1,13.81,100,1,12.98,200,2,13.91,2,1,12.86,100,1,14.13,100,1,12.73,100,1,14.48,1400,2,12.71,100,1,14.53,100,1,12.5,700,1,14.54,700,1,12.46,100,1,14.6,100,1,12.43,700,1,14.62,100,1,12.42,700,1,14.68,900,3,ARL,355692501
2014,2025-07-17T16:26:32.848604005Z,2025-07-17T16:26:32.848604005Z,10,2,1108,A,A,0,13.76,15,130,165437,295978389,13.11,100,1,13.76,15,1,13.01,2,1,13.8,15,1,12.98,200,2,13.81,100,1,12.86,100,1,13.91,2,1,12.73,100,1,14.13,100,1,12.71,100,1,14.48,1400,2,12.5,700,1,14.53,100,1,12.46,100,1,14.54,700,1,12.43,700,1,14.6,100,1,12.42,700,1,14.62,100,1,ARL,356212397
2015,2025-07-17T16:26:34.578928535Z,2025-07-17T16:26:34.578928535Z,10,2,1108,C,A,2,13.81,100,0,165348,296006812,13.11,100,1,13.76,15,1,13.01,2,1,13.8,15,1,12.98,200,2,13.91,2,1,12.86,100,1,14.13,100,1,12.73,100,1,14.48,1400,2,12.71,100,1,14.53,100,1,12.5,700,1,14.54,700,1,12.46,100,1,14.6,100,1,12.43,700,1,14.62,100,1,12.42,700,1,14.68,900,3,ARL,355834377
2016,2025-07-17T16:26:34.578928535Z,2025-07-17T16:26:34.578928535Z,10,2,1108,A,A,1,13.77,100,130,165348,296006812,13.11,100,1,13.76,15,1,13.01,2,1,13.77,100,1,12.98,200,2,13.8,15,1,12.86,100,1,13.91,2,1,12.73,100,1,14.13,100,1,12.71,100,1,14.48,1400,2,12.5,700,1,14.53,100,1,12.46,100,1,14.54,700,1,12.43,700,1,14.6,100,1,12.42,700,1,14.62,100,1,ARL,356249197
2017,2025-07-17T16:26:34.579668245Z,2025-07-17T16:26:34.579668245Z,10,2,1108,C,A,8,14.6,100,130,165232,296006823,13.11,100,1,13.76,15,1,13.01,2,1,13.77,100,1,12.98,200,2,13.8,15,1,12.86,100,1,13.91,2,1,12.73,100,1,14.13,100,1,12.71,100,1,14.48,1400,2,12.5,700,1,14.53,100,1,12.46,100,1,14.54,700,1,12.43,700,1,14.62,100,1,12.42,700,1,14.68,900,3,ARL,349378277
2018,2025-07-17T16:26:34.580024867Z,2025-07-17T16:26:34.580024867Z,10,2,1108,A,A,5,14.38,100,130,165315,296006828,13.11,100,1,13.76,15,1,13.01,2,1,13.77,100,1,12.98,200,2,13.8,15,1,12.86,100,1,13.91,2,1,12.73,100,1,14.13,100,1,12.71,100,1,14.38,100,1,12.5,700,1,14.48,1400,2,12.46,100,1,14.53,100,1,12.43,700,1,14.54,700,1,12.42,700,1,14.62,100,1,ARL,356249249
2019,2025-07-17T16:26:34.598014487Z,2025-07-17T16:26:34.598014487Z,10,2,1108,C,A,4,14.13,100,130,165378,296007149,13.11,100,1,13.76,15,1,13.01,2,1,13.77,100,1,12.98,200,2,13.8,15,1,12.86,100,1,13.91,2,1,12.73,100,1,14.38,100,1,12.71,100,1,14.48,1400,2,12.5,700,1,14.53,100,1,12.46,100,1,14.54,700,1,12.43,700,1,14.62,100,1,12.42,700,1,14.68,900,3,ARL,355455809
2020,2025-07-17T16:26:34.598066762Z,2025-07-17T16:26:34.598066762Z,10,2,1108,A,A,4,14.05,100,130,165216,296007150,13.11,100,1,13.76,15,1,13.01,2,1,13.77,100,1,12.98,200,2,13.8,15,1,12.86,100,1,13.91,2,1,12.73,100,1,14.05,100,1,12.71,100,1,14.38,100,1,12.5,700,1,14.48,1400,2,12.46,100,1,14.53,100,1,12.43,700,1,14.54,700,1,12.42,700,1,14.62,100,1,ARL,356249781
2021,2025-07-17T16:26:40.081907812Z,2025-07-17T16:26:40.081907812Z,10,2,1108,C,A,2,13.8,15,130,166268,296079992,13.11,100,1,13.76,15,1,13.01,2,1,13.77,100,1,12.98,200,2,13.91,2,1,12.86,100,1,14.05,100,1,12.73,100,1,14.38,100,1,12.71,100,1,14.48,1400,2,12.5,700,1,14.53,100,1,12.46,100,1,14.54,700,1,12.43,700,1,14.62,100,1,12.42,700,1,14.68,900,3,ARL,355834369
2022,2025-07-17T16:26:41.282951271Z,2025-07-17T16:26:41.282951271Z,10,2,1108,A,A,0,13.73,15,130,165530,296093549,13.11,100,1,13.73,15,1,13.01,2,1,13.76,15,1,12.98,200,2,13.77,100,1,12.86,100,1,13.91,2,1,12.73,100,1,14.05,100,1,12.71,100,1,14.38,100,1,12.5,700,1,14.48,1400,2,12.46,100,1,14.53,100,1,12.43,700,1,14.54,700,1,12.42,700,1,14.62,100,1,ARL,356366025
2023,2025-07-17T16:26:41.283218820Z,2025-07-17T16:26:41.283218820Z,10,2,1108,C,A,2,13.77,100,0,165964,296093550,13.11,100,1,13.73,15,1,13.01,2,1,13.76,15,1,12.98,200,2,13.91,2,1,12.86,100,1,14.05,100,1,12.73,100,1,14.38,100,1,12.71,100,1,14.48,1400,2,12.5,700,1,14.53,100,1,12.46,100,1,14.54,700,1,12.43,700,1,14.62,100,1,12.42,700,1,14.68,900,3,ARL,356249197
2024,2025-07-17T16:26:41.283218820Z,2025-07-17T16:26:41.283218820Z,10,2,1108,A,A,1,13.74,100,130,165964,296093550,13.11,100,1,13.73,15,1,13.01,2,1,13.74,100,1,12.98,200,2,13.76,15,1,12.86,100,1,13.91,2,1,12.73,100,1,14.05,100,1,12.71,100,1,14.38,100,1,12.5,700,1,14.48,1400,2,12.46,100,1,14.53,100,1,12.43,700,1,14.54,700,1,12.42,700,1,14.62,100,1,ARL,356366029
2025,2025-07-17T16:26:52.849764152Z,2025-07-17T16:26:52.849764152Z,10,2,1108,C,A,2,13.76,15,130,165555,296250544,13.11,100,1,13.73,15,1,13.01,2,1,13.74,100,1,12.98,200,2,13.91,2,1,12.86,100,1,14.05,100,1,12.73,100,1,14.38,100,1,12.71,100,1,14.48,1400,2,12.5,700,1,14.53,100,1,12.46,100,1,14.54,700,1,12.43,700,1,14.62,100,1,12.42,700,1,14.68,900,3,ARL,356212397
2026,2025-07-17T16:26:59.805255232Z,2025-07-17T16:26:59.805255232Z,10,2,1108,A,A,0,13.7,15,130,165862,296350781,13.11,100,1,13.7,15,1,13.01,2,1,13.73,15,1,12.98,200,2,13.74,100,1,12.86,100,1,13.91,2,1,12.73,100,1,14.05,100,1,12.71,100,1,14.38,100,1,12.5,700,1,14.48,1400,2,12.46,100,1,14.53,100,1,12.43,700,1,14.54,700,1,12.42,700,1,14.62,100,1,ARL,356686001
2027,2025-07-17T16:27:00.881078814Z,2025-07-17T16:27:00.881078814Z,10,2,1108,C,A,2,13.74,100,0,165513,296372801,13.11,100,1,13.7,15,1,13.01,2,1,13.73,15,1,12.98,200,2,13.91,2,1,12.86,100,1,14.05,100,1,12.73,100,1,14.38,100,1,12.71,100,1,14.48,1400,2,12.5,700,1,14.53,100,1,12.46,100,1,14.54,700,1,12.43,700,1,14.62,100,1,12.42,700,1,14.68,900,3,ARL,356366029
2028,2025-07-17T16:27:00.881078814Z,2025-07-17T16:27:00.881078814Z,10,2,1108,A,A,1,13.71,100,130,165513,296372801,13.11,100,1,13.7,15,1,13.01,2,1,13.71,100,1,12.98,200,2,13.73,15,1,12.86,100,1,13.91,2,1,12.73,100,1,14.05,100,1,12.71,100,1,14.38,100,1,12.5,700,1,14.48,1400,2,12.46,100,1,14.53,100,1,12.43,700,1,14.54,700,1,12.42,700,1,14.62,100,1,ARL,356714633
2029,2025-07-17T16:27:00.888818817Z,2025-07-17T16:27:00.888818817Z,10,2,1108,C,A,4,14.05,100,130,167365,296372958,13.11,100,1,13.7,15,1,13.01,2,1,13.71,100,1,12.98,200,2,13.73,15,1,12.86,100,1,13.91,2,1,12.73,100,1,14.38,100,1,12.71,100,1,14.48,1400,2,12.5,700,1,14.53,100,1,12.46,100,1,14.54,700,1,12.43,700,1,14.62,100,1,12.42,700,1,14.68,900,3,ARL,356249781
2030,2025-07-17T16:27:00.888868946Z,2025-07-17T16:27:00.888868946Z,10,2,1108,A,A,4,13.98,100,130,165222,296372964,13.11,100,1,13.7,15,1,13.01,2,1,13.71,100,1,12.98,200,2,13.73,15,1,12.86,100,1,13.91,2,1,12.73,100,1,13.98,100,1,12.71,100,1,14.38,100,1,12.5,700,1,14.48,1400,2,12.46,100,1,14.53,100,1,12.43,700,1,14.54,700,1,12.42,700,1,14.62,100,1,ARL,356714765
2031,2025-07-17T16:27:01.382629641Z,2025-07-17T16:27:01.382629641Z,10,2,1108,A,A,7,14.53,100,130,165185,296378810,13.11,100,1,13.7,15,1,13.01,2,1,13.71,100,1,12.98,200,2,13.73,15,1,12.86,100,1,13.91,2,1,12.73,100,1,13.98,100,1,12.71,100,1,14.38,100,1,12.5,700,1,14.48,1400,2,12.46,100,1,14.53,200,2,12.43,700,1,14.54,700,1,12.42,700,1,14.62,100,1,ARL,356722649
2032,2025-07-17T16:27:03.871623478Z,2025-07-17T16:27:03.871623478Z,10,2,1108,C,A,2,13.73,15,130,165458,296454461,13.11,100,1,13.7,15,1,13.01,2,1,13.71,100,1,12.98,200,2,13.91,2,1,12.86,100,1,13.98,100,1,12.73,100,1,14.38,100,1,12.71,100,1,14.48,1400,2,12.5,700,1,14.53,200,2,12.46,100,1,14.54,700,1,12.43,700,1,14.62,100,1,12.42,700,1,14.68,900,3,ARL,356366025
2033,2025-07-17T16:27:06.196810370Z,2025-07-17T16:27:06.196810370Z,10,2,1108,A,A,0,13.67,15,130,165509,296495602,13.11,100,1,13.67,15,1,13.01,2,1,13.7,15,1,12.98,200,2,13.71,100,1,12.86,100,1,13.91,2,1,12.73,100,1,13.98,100,1,12.71,100,1,14.38,100,1,12.5,700,1,14.48,1400,2,12.46,100,1,14.53,200,2,12.43,700,1,14.54,700,1,12.42,700,1,14.62,100,1,ARL,356868209
2034,2025-07-17T16:27:06.197657115Z,2025-07-17T16:27:06.197657115Z,10,2,1108,A,A,9,14.57,100,130,165599,296495681,13.11,100,1,13.67,15,1,13.01,2,1,13.7,15,1,12.98,200,2,13.71,100,1,12.86,100,1,13.91,2,1,12.73,100,1,13.98,100,1,12.71,100,1,14.38,100,1,12.5,700,1,14.48,1400,2,12.46,100,1,14.53,200,2,12.43,700,1,14.54,700,1,12.42,700,1,14.57,100,1,ARL,356868353
2035,2025-07-17T16:27:06.197902486Z,2025-07-17T16:27:06.197902486Z,10,2,1108,A,A,9,14.57,100,128,169274,296495716,13.11,100,1,13.67,15,1,13.01,2,1,13.7,15,1,12.98,200,2,13.71,100,1,12.86,100,1,13.91,2,1,12.73,100,1,13.98,100,1,12.71,100,1,14.38,100,1,12.5,700,1,14.48,1400,2,12.46,100,1,14.53,200,2,12.43,700,1,14.54,700,1,12.42,700,1,14.57,200,2,ARL,356868473
2036,2025-07-17T16:27:06.203607410Z,2025-07-17T16:27:06.203607410Z,10,2,1108,C,A,2,13.71,100,0,178782,296497538,13.11,100,1,13.67,15,1,13.01,2,1,13.7,15,1,12.98,200,2,13.91,2,1,12.86,100,1,13.98,100,1,12.73,100,1,14.38,100,1,12.71,100,1,14.48,1400,2,12.5,700,1,14.53,200,2,12.46,100,1,14.54,700,1,12.43,700,1,14.57,200,2,12.42,700,1,14.62,100,1,ARL,356714633
2037,2025-07-17T16:27:06.203607410Z,2025-07-17T16:27:06.203607410Z,10,2,1108,A,A,1,13.68,100,128,178782,296497538,13.11,100,1,13.67,15,1,13.01,2,1,13.68,100,1,12.98,200,2,13.7,15,1,12.86,100,1,13.91,2,1,12.73,100,1,13.98,100,1,12.71,100,1,14.38,100,1,12.5,700,1,14.48,1400,2,12.46,100,1,14.53,200,2,12.43,700,1,14.54,700,1,12.42,700,1,14.57,200,2,ARL,356870513
2038,2025-07-17T16:27:06.367693589Z,2025-07-17T16:27:06.367693589Z,10,2,1108,C,A,7,14.53,100,130,165591,296505003,13.11,100,1,13.67,15,1,13.01,2,1,13.68,100,1,12.98,200,2,13.7,15,1,12.86,100,1,13.91,2,1,12.73,100,1,13.98,100,1,12.71,100,1,14.38,100,1,12.5,700,1,14.48,1400,2,12.46,100,1,14.53,100,1,12.43,700,1,14.54,700,1,12.42,700,1,14.57,200,2,ARL,349382189
2039,2025-07-17T16:27:06.367695483Z,2025-07-17T16:27:06.367695483Z,10,2,1108,A,A,5,14.23,100,130,165270,296505004,13.11,100,1,13.67,15,1,13.01,2,1,13.68,100,1,12.98,200,2,13.7,15,1,12.86,100,1,13.91,2,1,12.73,100,1,13.98,100,1,12.71,100,1,14.23,100,1,12.5,700,1,14.38,100,1,12.46,100,1,14.48,1400,2,12.43,700,1,14.53,100,1,12.42,700,1,14.54,700,1,ARL,356878397
2040,2025-07-17T16:27:06.379374401Z,2025-07-17T16:27:06.379374401Z,10,2,1108,A,A,7,14.47,100,130,165750,296505373,13.11,100,1,13.67,15,1,13.01,2,1,13.68,100,1,12.98,200,2,13.7,15,1,12.86,100,1,13.91,2,1,12.73,100,1,13.98,100,1,12.71,100,1,14.23,100,1,12.5,700,1,14.38,100,1,12.46,100,1,14.47,100,1,12.43,700,1,14.48,1400,2,12.42,700,1,14.53,100,1,ARL,356878557
2041,2025-07-17T16:27:16.850167737Z,2025-07-17T16:27:16.850167737Z,10,2,1108,C,A,2,13.7,15,130,165176,296665928,13.11,100,1,13.67,15,1,13.01,2,1,13.68,100,1,12.98,200,2,13.91,2,1,12.86,100,1,13.98,100,1,12.73,100,1,14.23,100,1,12.71,100,1,14.38,100,1,12.5,700,1,14.47,100,1,12.46,100,1,14.48,1400,2,12.43,700,1,14.53,100,1,12.42,700,1,14.54,700,1,ARL,356686001
2042,2025-07-17T16:27:26.588907795Z,2025-07-17T16:27:26.588907795Z,10,2,1108,C,B,1,13.01,2,0,165686,296801845,13.11,100,1,13.67,15,1,12.98,200,2,13.68,100,1,12.86,100,1,13.91,2,1,12.73,100,1,13.98,100,1,12.71,100,1,14.23,100,1,12.5,700,1,14.38,100,1,12.46,100,1,14.47,100,1,12.43,700,1,14.48,1400,2,12.42,700,1,14.53,100,1,12.37,700,1,14.54,700,1,ARL,355990209
2043,2025-07-17T16:27:26.588907795Z,2025-07-17T16:27:26.588907795Z,10,2,1108,A,B,2,12.9,2,130,165686,296801845,13.11,100,1,13.67,15,1,12.98,200,2,13.68,100,1,12.9,2,1,13.91,2,1,12.86,100,1,13.98,100,1,12.73,100,1,14.23,100,1,12.71,100,1,14.38,100,1,12.5,700,1,14.47,100,1,12.46,100,1,14.48,1400,2,12.43,700,1,14.53,100,1,12.42,700,1,14.54,700,1,ARL,357261961
2044,2025-07-17T16:27:26.850423539Z,2025-07-17T16:27:26.850423539Z,10,2,1108,A,A,0,13.65,15,130,165407,296804447,13.11,100,1,13.65,15,1,12.98,200,2,13.67,15,1,12.9,2,1,13.68,100,1,12.86,100,1,13.91,2,1,12.73,100,1,13.98,100,1,12.71,100,1,14.23,100,1,12.5,700,1,14.38,100,1,12.46,100,1,14.47,100,1,12.43,700,1,14.48,1400,2,12.42,700,1,14.53,100,1,ARL,357266817
2045,2025-07-17T16:27:26.850689196Z,2025-07-17T16:27:26.850689196Z,10,2,1108,C,A,2,13.68,100,0,165657,296804468,13.11,100,1,13.65,15,1,12.98,200,2,13.67,15,1,12.9,2,1,13.91,2,1,12.86,100,1,13.98,100,1,12.73,100,1,14.23,100,1,12.71,100,1,14.38,100,1,12.5,700,1,14.47,100,1,12.46,100,1,14.48,1400,2,12.43,700,1,14.53,100,1,12.42,700,1,14.54,700,1,ARL,356870513
2046,2025-07-17T16:27:26.850689196Z,2025-07-17T16:27:26.850689196Z,10,2,1108,A,A,1,13.66,100,130,165657,296804468,13.11,100,1,13.65,15,1,12.98,200,2,13.66,100,1,12.9,2,1,13.67,15,1,12.86,100,1,13.91,2,1,12.73,100,1,13.98,100,1,12.71,100,1,14.23,100,1,12.5,700,1,14.38,100,1,12.46,100,1,14.47,100,1,12.43,700,1,14.48,1400,2,12.42,700,1,14.53,100,1,ARL,357266825
2047,2025-07-17T16:27:44.755305413Z,2025-07-17T16:27:44.755305413Z,10,2,1108,C,A,2,13.67,15,130,165451,297181709,13.11,100,1,13.65,15,1,12.98,200,2,13.66,100,1,12.9,2,1,13.91,2,1,12.86,100,1,13.98,100,1,12.73,100,1,14.23,100,1,12.71,100,1,14.38,100,1,12.5,700,1,14.47,100,1,12.46,100,1,14.48,1400,2,12.43,700,1,14.53,100,1,12.42,700,1,14.54,700,1,ARL,356868209
2048,2025-07-17T16:27:51.274028105Z,2025-07-17T16:27:51.274028105Z,10,2,1108,A,A,0,13.63,15,130,165642,297262308,13.11,100,1,13.63,15,1,12.98,200,2,13.65,15,1,12.9,2,1,13.66,100,1,12.86,100,1,13.91,2,1,12.73,100,1,13.98,100,1,12.71,100,1,14.23,100,1,12.5,700,1,14.38,100,1,12.46,100,1,14.47,100,1,12.43,700,1,14.48,1400,2,12.42,700,1,14.53,100,1,ARL,357831017
2049,2025-07-17T16:27:51.287829323Z,2025-07-17T16:27:51.287829323Z,10,2,1108,C,A,2,13.66,100,0,165497,297264561,13.11,100,1,13.63,15,1,12.98,200,2,13.65,15,1,12.9,2,1,13.91,2,1,12.86,100,1,13.98,100,1,12.73,100,1,14.23,100,1,12.71,100,1,14.38,100,1,12.5,700,1,14.47,100,1,12.46,100,1,14.48,1400,2,12.43,700,1,14.53,100,1,12.42,700,1,14.54,700,1,ARL,357266825
2050,2025-07-17T16:27:51.287829323Z,2025-07-17T16:27:51.287829323Z,10,2,1108,A,A,1,13.64,100,130,165497,297264561,13.11,100,1,13.63,15,1,12.98,200,2,13.64,100,1,12.9,2,1,13.65,15,1,12.86,100,1,13.91,2,1,12.73,100,1,13.98,100,1,12.71,100,1,14.23,100,1,12.5,700,1,14.38,100,1,12.46,100,1,14.47,100,1,12.43,700,1,14.48,1400,2,12.42,700,1,14.53,100,1,ARL,357833401
2051,2025-07-17T16:27:51.309729367Z,2025-07-17T16:27:51.309729367Z,10,2,1108,C,A,4,13.98,100,130,165423,297265448,13.11,100,1,13.63,15,1,12.98,200,2,13.64,100,1,12.9,2,1,13.65,15,1,12.86,100,1,13.91,2,1,12.73,100,1,14.23,100,1,12.71,100,1,14.38,100,1,12.5,700,1,14.47,100,1,12.46,100,1,14.48,1400,2,12.43,700,1,14.53,100,1,12.42,700,1,14.54,700,1,ARL,356714765
2052,2025-07-17T16:27:51.309780024Z,2025-07-17T16:27:51.309780024Z,10,2,1108,A,A,3,13.91,100,130,165343,297265452,13.11,100,1,13.63,15,1,12.98,200,2,13.64,100,1,12.9,2,1,13.65,15,1,12.86,100,1,13.91,102,2,12.73,100,1,14.23,100,1,12.71,100,1,14.38,100,1,12.5,700,1,14.47,100,1,12.46,100,1,14.48,1400,2,12.43,700,1,14.53,100,1,12.42,700,1,14.54,700,1,ARL,357834073
2053,2025-07-17T16:28:02.851272527Z,2025-07-17T16:28:02.851272527Z,10,2,1108,C,A,2,13.65,15,130,165339,297397036,13.11,100,1,13.63,15,1,12.98,200,2,13.64,100,1,12.9,2,1,13.91,102,2,12.86,100,1,14.23,100,1,12.73,100,1,14.38,100,1,12.71,100,1,14.47,100,1,12.5,700,1,14.48,1400,2,12.46,100,1,14.53,100,1,12.43,700,1,14.54,700,1,12.42,700,1,14.57,200,2,ARL,357266817
2054,2025-07-17T16:28:09.315122562Z,2025-07-17T16:28:09.315122562Z,10,2,1108,A,A,0,13.61,15,130,165466,297494103,13.11,100,1,13.61,15,1,12.98,200,2,13.63,15,1,12.9,2,1,13.64,100,1,12.86,100,1,13.91,102,2,12.73,100,1,14.23,100,1,12.71,100,1,14.38,100,1,12.5,700,1,14.47,100,1,12.46,100,1,14.48,1400,2,12.43,700,1,14.53,100,1,12.42,700,1,14.54,700,1,ARL,358150085
2055,2025-07-17T16:28:09.320239872Z,2025-07-17T16:28:09.320239872Z,10,2,1108,C,A,2,13.64,100,0,168840,297494317,13.11,100,1,13.61,15,1,12.98,200,2,13.63,15,1,12.9,2,1,13.91,102,2,12.86,100,1,14.23,100,1,12.73,100,1,14.38,100,1,12.71,100,1,14.47,100,1,12.5,700,1,14.48,1400,2,12.46,100,1,14.53,100,1,12.43,700,1,14.54,700,1,12.42,700,1,14.57,200,2,ARL,357833401
2056,2025-07-17T16:28:09.320239872Z,2025-07-17T16:28:09.320239872Z,10,2,1108,A,A,1,13.62,100,130,168840,297494317,13.11,100,1,13.61,15,1,12.98,200,2,13.62,100,1,12.9,2,1,13.63,15,1,12.86,100,1,13.91,102,2,12.73,100,1,14.23,100,1,12.71,100,1,14.38,100,1,12.5,700,1,14.47,100,1,12.46,100,1,14.48,1400,2,12.43,700,1,14.53,100,1,12.42,700,1,14.54,700,1,ARL,358150237
2057,2025-07-17T16:28:20.851472409Z,2025-07-17T16:28:20.851472409Z,10,2,1108,C,A,2,13.63,15,130,165598,297651898,13.11,100,1,13.61,15,1,12.98,200,2,13.62,100,1,12.9,2,1,13.91,102,2,12.86,100,1,14.23,100,1,12.73,100,1,14.38,100,1,12.71,100,1,14.47,100,1,12.5,700,1,14.48,1400,2,12.46,100,1,14.53,100,1,12.43,700,1,14.54,700,1,12.42,700,1,14.57,200,2,ARL,357831017
2058,2025-07-17T16:28:24.674343969Z,2025-07-17T16:28:24.674343969Z,10,2,1108,A,A,0,13.59,15,130,165389,297733885,13.11,100,1,13.59,15,1,12.98,200,2,13.61,15,1,12.9,2,1,13.62,100,1,12.86,100,1,13.91,102,2,12.73,100,1,14.23,100,1,12.71,100,1,14.38,100,1,12.5,700,1,14.47,100,1,12.46,100,1,14.48,1400,2,12.43,700,1,14.53,100,1,12.42,700,1,14.54,700,1,ARL,358449973
2059,2025-07-17T16:28:25.348230623Z,2025-07-17T16:28:25.348230623Z,10,2,1108,C,A,2,13.62,100,0,165512,297742434,13.11,100,1,13.59,15,1,12.98,200,2,13.61,15,1,12.9,2,1,13.91,102,2,12.86,100,1,14.23,100,1,12.73,100,1,14.38,100,1,12.71,100,1,14.47,100,1,12.5,700,1,14.48,1400,2,12.46,100,1,14.53,100,1,12.43,700,1,14.54,700,1,12.42,700,1,14.57,200,2,ARL,358150237
2060,2025-07-17T16:28:25.348230623Z,2025-07-17T16:28:25.348230623Z,10,2,1108,A,A,1,13.6,100,130,165512,297742434,13.11,100,1,13.59,15,1,12.98,200,2,13.6,100,1,12.9,2,1,13.61,15,1,12.86,100,1,13.91,102,2,12.73,100,1,14.23,100,1,12.71,100,1,14.38,100,1,12.5,700,1,14.47,100,1,12.46,100,1,14.48,1400,2,12.43,700,1,14.53,100,1,12.42,700,1,14.54,700,1,ARL,358463553
2061,2025-07-17T16:28:30.151612118Z,2025-07-17T16:28:30.151612118Z,10,2,1108,C,A,2,13.61,15,130,165448,297801782,13.11,100,1,13.59,15,1,12.98,200,2,13.6,100,1,12.9,2,1,13.91,102,2,12.86,100,1,14.23,100,1,12.73,100,1,14.38,100,1,12.71,100,1,14.47,100,1,12.5,700,1,14.48,1400,2,12.46,100,1,14.53,100,1,12.43,700,1,14.54,700,1,12.42,700,1,14.57,200,2,ARL,358150085
2062,2025-07-17T16:28:31.156364385Z,2025-07-17T16:28:31.156364385Z,10,2,1108,A,A,0,13.57,15,130,165769,297818676,13.11,100,1,13.57,15,1,12.98,200,2,13.59,15,1,12.9,2,1,13.6,100,1,12.86,100,1,13.91,102,2,12.73,100,1,14.23,100,1,12.71,100,1,14.38,100,1,12.5,700,1,14.47,100,1,12.46,100,1,14.48,1400,2,12.43,700,1,14.53,100,1,12.42,700,1,14.54,700,1,ARL,358570565
2063,2025-07-17T16:28:31.749624268Z,2025-07-17T16:28:31.749624268Z,10,2,1108,C,A,2,13.6,100,0,165429,297824579,13.11,100,1,13.57,15,1,12.98,200,2,13.59,15,1,12.9,2,1,13.91,102,2,12.86,100,1,14.23,100,1,12.73,100,1,14.38,100,1,12.71,100,1,14.47,100,1,12.5,700,1,14.48,1400,2,12.46,100,1,14.53,100,1,12.43,700,1,14.54,700,1,12.42,700,1,14.57,200,2,ARL,358463553
2064,2025-07-17T16:28:31.749624268Z,2025-07-17T16:28:31.749624268Z,10,2,1108,A,A,1,13.58,100,130,165429,297824579,13.11,100,1,13.57,15,1,12.98,200,2,13.58,100,1,12.9,2,1,13.59,15,1,12.86,100,1,13.91,102,2,12.73,100,1,14.23,100,1,12.71,100,1,14.38,100,1,12.5,700,1,14.47,100,1,12.46,100,1,14.48,1400,2,12.43,700,1,14.53,100,1,12.42,700,1,14.54,700,1,ARL,358578625
2065,2025-07-17T16:28:32.698506029Z,2025-07-17T16:28:32.698506029Z,10,2,1108,A,A,6,14.46,100,130,166135,297835499,13.11,100,1,13.57,15,1,12.98,200,2,13.58,100,1,12.9,2,1,13.59,15,1,12.86,100,1,13.91,102,2,12.73,100,1,14.23,100,1,12.71,100,1,14.38,100,1,12.5,700,1,14.46,100,1,12.46,100,1,14.47,100,1,12.43,700,1,14.48,1400,2,12.42,700,1,14.53,100,1,ARL,358596029
2066,2025-07-17T16:28:32.698952035Z,2025-07-17T16:28:32.698952035Z,10,2,1108,A,A,6,14.46,100,130,165745,297835506,13.11,100,1,13.57,15,1,12.98,200,2,13.58,100,1,12.9,2,1,13.59,15,1,12.86,100,1,13.91,102,2,12.73,100,1,14.23,100,1,12.71,100,1,14.38,100,1,12.5,700,1,14.46,200,2,12.46,100,1,14.47,100,1,12.43,700,1,14.48,1400,2,12.42,700,1,14.53,100,1,ARL,358596037
2067,2025-07-17T16:28:40.030511022Z,2025-07-17T16:28:40.030511022Z,10,2,1108,A,A,5,14.26,700,130,165281,297918373,13.11,100,1,13.57,15,1,12.98,200,2,13.58,100,1,12.9,2,1,13.59,15,1,12.86,100,1,13.91,102,2,12.73,100,1,14.23,100,1,12.71,100,1,14.26,700,1,12.5,700,1,14.38,100,1,12.46,100,1,14.46,200,2,12.43,700,1,14.47,100,1,12.42,700,1,14.48,1400,2,ARL,358712189
2068,2025-07-17T16:28:42.853298390Z,2025-07-17T16:28:42.853298390Z,10,2,1108,C,A,2,13.59,15,130,165265,297952225,13.11,100,1,13.57,15,1,12.98,200,2,13.58,100,1,12.9,2,1,13.91,102,2,12.86,100,1,14.23,100,1,12.73,100,1,14.26,700,1,12.71,100,1,14.38,100,1,12.5,700,1,14.46,200,2,12.46,100,1,14.47,100,1,12.43,700,1,14.48,1400,2,12.42,700,1,14.53,100,1,ARL,358449973
2069,2025-07-17T16:28:52.853361257Z,2025-07-17T16:28:52.853361257Z,10,2,1108,A,A,0,13.55,15,130,165124,298071838,13.11,100,1,13.55,15,1,12.98,200,2,13.57,15,1,12.9,2,1,13.58,100,1,12.86,100,1,13.91,102,2,12.73,100,1,14.23,100,1,12.71,100,1,14.26,700,1,12.5,700,1,14.38,100,1,12.46,100,1,14.46,200,2,12.43,700,1,14.47,100,1,12.42,700,1,14.48,1400,2,ARL,358923309
2070,2025-07-17T16:28:52.853628543Z,2025-07-17T16:28:52.853628543Z,10,2,1108,C,A,2,13.58,100,0,165353,298071841,13.11,100,1,13.55,15,1,12.98,200,2,13.57,15,1,12.9,2,1,13.91,102,2,12.86,100,1,14.23,100,1,12.73,100,1,14.26,700,1,12.71,100,1,14.38,100,1,12.5,700,1,14.46,200,2,12.46,100,1,14.47,100,1,12.43,700,1,14.48,1400,2,12.42,700,1,14.53,100,1,ARL,358578625
2071,2025-07-17T16:28:52.853628543Z,2025-07-17T16:28:52.853628543Z,10,2,1108,A,A,1,13.56,100,130,165353,298071841,13.11,100,1,13.55,15,1,12.98,200,2,13.56,100,1,12.9,2,1,13.57,15,1,12.86,100,1,13.91,102,2,12.73,100,1,14.23,100,1,12.71,100,1,14.26,700,1,12.5,700,1,14.38,100,1,12.46,100,1,14.46,200,2,12.43,700,1,14.47,100,1,12.42,700,1,14.48,1400,2,ARL,358923321
2072,2025-07-17T16:28:52.854365748Z,2025-07-17T16:28:52.854365748Z,10,2,1108,C,A,6,14.38,100,130,165303,298071844,13.11,100,1,13.55,15,1,12.98,200,2,13.56,100,1,12.9,2,1,13.57,15,1,12.86,100,1,13.91,102,2,12.73,100,1,14.23,100,1,12.71,100,1,14.26,700,1,12.5,700,1,14.46,200,2,12.46,100,1,14.47,100,1,12.43,700,1,14.48,1400,2,12.42,700,1,14.53,100,1,ARL,356249249
2073,2025-07-17T16:28:52.854727375Z,2025-07-17T16:28:52.854727375Z,10,2,1108,A,A,4,14.17,100,130,165358,298071846,13.11,100,1,13.55,15,1,12.98,200,2,13.56,100,1,12.9,2,1,13.57,15,1,12.86,100,1,13.91,102,2,12.73,100,1,14.17,100,1,12.71,100,1,14.23,100,1,12.5,700,1,14.26,700,1,12.46,100,1,14.46,200,2,12.43,700,1,14.47,100,1,12.42,700,1,14.48,1400,2,ARL,358923345
2074,2025-07-17T16:28:52.874803773Z,2025-07-17T16:28:52.874803773Z,10,2,1108,C,A,3,13.91,100,130,165391,298071937,13.11,100,1,13.55,15,1,12.98,200,2,13.56,100,1,12.9,2,1,13.57,15,1,12.86,100,1,13.91,2,1,12.73,100,1,14.17,100,1,12.71,100,1,14.23,100,1,12.5,700,1,14.26,700,1,12.46,100,1,14.46,200,2,12.43,700,1,14.47,100,1,12.42,700,1,14.48,1400,2,ARL,357834073
2075,2025-07-17T16:28:52.874854173Z,2025-07-17T16:28:52.874854173Z,10,2,1108,A,A,3,13.83,100,130,165227,298071938,13.11,100,1,13.55,15,1,12.98,200,2,13.56,100,1,12.9,2,1,13.57,15,1,12.86,100,1,13.83,100,1,12.73,100,1,13.91,2,1,12.71,100,1,14.17,100,1,12.5,700,1,14.23,100,1,12.46,100,1,14.26,700,1,12.43,700,1,14.46,200,2,12.42,700,1,14.47,100,1,ARL,358923457
2076,2025-07-17T16:29:12.853059452Z,2025-07-17T16:29:12.853059452Z,10,2,1108,C,A,2,13.57,15,130,165465,298434087,13.11,100,1,13.55,15,1,12.98,200,2,13.56,100,1,12.9,2,1,13.83,100,1,12.86,100,1,13.91,2,1,12.73,100,1,14.17,100,1,12.71,100,1,14.23,100,1,12.5,700,1,14.26,700,1,12.46,100,1,14.46,200,2,12.43,700,1,14.47,100,1,12.42,700,1,14.48,1400,2,ARL,358570565
2077,2025-07-17T16:29:15.051471390Z,2025-07-17T16:29:15.051471390Z,10,2,1108,A,A,0,13.53,15,130,165333,298465823,13.11,100,1,13.53,15,1,12.98,200,2,13.55,15,1,12.9,2,1,13.56,100,1,12.86,100,1,13.83,100,1,12.73,100,1,13.91,2,1,12.71,100,1,14.17,100,1,12.5,700,1,14.23,100,1,12.46,100,1,14.26,700,1,12.43,700,1,14.46,200,2,12.42,700,1,14.47,100,1,ARL,359402805
2078,2025-07-17T16:29:15.091620748Z,2025-07-17T16:29:15.091620748Z,10,2,1108,C,A,2,13.56,100,0,165551,298467504,13.11,100,1,13.53,15,1,12.98,200,2,13.55,15,1,12.9,2,1,13.83,100,1,12.86,100,1,13.91,2,1,12.73,100,1,14.17,100,1,12.71,100,1,14.23,100,1,12.5,700,1,14.26,700,1,12.46,100,1,14.46,200,2,12.43,700,1,14.47,100,1,12.42,700,1,14.48,1400,2,ARL,358923321
2079,2025-07-17T16:29:15.091620748Z,2025-07-17T16:29:15.091620748Z,10,2,1108,A,A,1,13.54,100,130,165551,298467504,13.11,100,1,13.53,15,1,12.98,200,2,13.54,100,1,12.9,2,1,13.55,15,1,12.86,100,1,13.83,100,1,12.73,100,1,13.91,2,1,12.71,100,1,14.17,100,1,12.5,700,1,14.23,100,1,12.46,100,1,14.26,700,1,12.43,700,1,14.46,200,2,12.42,700,1,14.47,100,1,ARL,359403945
2080,2025-07-17T16:29:15.203765956Z,2025-07-17T16:29:15.203765956Z,10,2,1108,C,A,9,14.47,100,0,165416,298471150,13.11,100,1,13.53,15,1,12.98,200,2,13.54,100,1,12.9,2,1,13.55,15,1,12.86,100,1,13.83,100,1,12.73,100,1,13.91,2,1,12.71,100,1,14.17,100,1,12.5,700,1,14.23,100,1,12.46,100,1,14.26,700,1,12.43,700,1,14.46,200,2,12.42,700,1,14.48,1400,2,ARL,356878557
2081,2025-07-17T16:29:15.203765956Z,2025-07-17T16:29:15.203765956Z,10,2,1108,A,A,8,14.33,100,130,165416,298471150,13.11,100,1,13.53,15,1,12.98,200,2,13.54,100,1,12.9,2,1,13.55,15,1,12.86,100,1,13.83,100,1,12.73,100,1,13.91,2,1,12.71,100,1,14.17,100,1,12.5,700,1,14.23,100,1,12.46,100,1,14.26,700,1,12.43,700,1,14.33,100,1,12.42,700,1,14.46,200,2,ARL,359406981
2082,2025-07-17T16:29:18.185960448Z,2025-07-17T16:29:18.185960448Z,10,2,1108,C,A,4,13.91,2,0,165787,298518298,13.11,100,1,13.53,15,1,12.98,200,2,13.54,100,1,12.9,2,1,13.55,15,1,12.86,100,1,13.83,100,1,12.73,100,1,14.17,100,1,12.71,100,1,14.23,100,1,12.5,700,1,14.26,700,1,12.46,100,1,14.33,100,1,12.43,700,1,14.46,200,2,12.42,700,1,14.48,1400,2,ARL,354292533
2083,2025-07-17T16:29:18.185960448Z,2025-07-17T16:29:18.185960448Z,10,2,1108,A,A,3,13.82,2,130,165787,298518298,13.11,100,1,13.53,15,1,12.98,200,2,13.54,100,1,12.9,2,1,13.55,15,1,12.86,100,1,13.82,2,1,12.73,100,1,13.83,100,1,12.71,100,1,14.17,100,1,12.5,700,1,14.23,100,1,12.46,100,1,14.26,700,1,12.43,700,1,14.33,100,1,12.42,700,1,14.46,200,2,ARL,359459321
2084,2025-07-17T16:29:22.814459272Z,2025-07-17T16:29:22.814459272Z,10,2,1108,C,A,2,13.55,15,130,165545,298597575,13.11,100,1,13.53,15,1,12.98,200,2,13.54,100,1,12.9,2,1,13.82,2,1,12.86,100,1,13.83,100,1,12.73,100,1,14.17,100,1,12.71,100,1,14.23,100,1,12.5,700,1,14.26,700,1,12.46,100,1,14.33,100,1,12.43,700,1,14.46,200,2,12.42,700,1,14.48,1400,2,ARL,358923309
2085,2025-07-17T16:29:34.353360056Z,2025-07-17T16:29:34.353360056Z,10,2,1108,A,A,0,13.51,15,130,165310,298768484,13.11,100,1,13.51,15,1,12.98,200,2,13.53,15,1,12.9,2,1,13.54,100,1,12.86,100,1,13.82,2,1,12.73,100,1,13.83,100,1,12.71,100,1,14.17,100,1,12.5,700,1,14.23,100,1,12.46,100,1,14.26,700,1,12.43,700,1,14.33,100,1,12.42,700,1,14.46,200,2,ARL,359747973
2086,2025-07-17T16:29:37.353652254Z,2025-07-17T16:29:37.353652254Z,10,2,1108,C,A,1,13.53,15,130,165432,298809584,13.11,100,1,13.51,15,1,12.98,200,2,13.54,100,1,12.9,2,1,13.82,2,1,12.86,100,1,13.83,100,1,12.73,100,1,14.17,100,1,12.71,100,1,14.23,100,1,12.5,700,1,14.26,700,1,12.46,100,1,14.33,100,1,12.43,700,1,14.46,200,2,12.42,700,1,14.48,1400,2,ARL,359402805
2087,2025-07-17T16:29:38.016544503Z,2025-07-17T16:29:38.016544503Z,10,2,1108,C,A,1,13.54,100,0,165589,298816720,13.11,100,1,13.51,15,1,12.98,200,2,13.82,2,1,12.9,2,1,13.83,100,1,12.86,100,1,14.17,100,1,12.73,100,1,14.23,100,1,12.71,100,1,14.26,700,1,12.5,700,1,14.33,100,1,12.46,100,1,14.46,200,2,12.43,700,1,14.48,1400,2,12.42,700,1,14.49,200,2,ARL,359403945
2088,2025-07-17T16:29:38.016544503Z,2025-07-17T16:29:38.016544503Z,10,2,1108,A,A,1,13.52,100,130,165589,298816720,13.11,100,1,13.51,15,1,12.98,200,2,13.52,100,1,12.9,2,1,13.82,2,1,12.86,100,1,13.83,100,1,12.73,100,1,14.17,100,1,12.71,100,1,14.23,100,1,12.5,700,1,14.26,700,1,12.46,100,1,14.33,100,1,12.43,700,1,14.46,200,2,12.42,700,1,14.48,1400,2,ARL,359803101
2089,2025-07-17T16:29:38.358532978Z,2025-07-17T16:29:38.358532978Z,10,2,1108,A,A,0,13.49,15,130,165402,298820897,13.11,100,1,13.49,15,1,12.98,200,2,13.51,15,1,12.9,2,1,13.52,100,1,12.86,100,1,13.82,2,1,12.73,100,1,13.83,100,1,12.71,100,1,14.17,100,1,12.5,700,1,14.23,100,1,12.46,100,1,14.26,700,1,12.43,700,1,14.33,100,1,12.42,700,1,14.46,200,2,ARL,359807057
2090,2025-07-17T16:29:39.396248056Z,2025-07-17T16:29:39.396248056Z,10,2,1108,C,A,2,13.52,100,0,165394,298834883,13.11,100,1,13.49,15,1,12.98,200,2,13.51,15,1,12.9,2,1,13.82,2,1,12.86,100,1,13.83,100,1,12.73,100,1,14.17,100,1,12.71,100,1,14.23,100,1,12.5,700,1,14.26,700,1,12.46,100,1,14.33,100,1,12.43,700,1,14.46,200,2,12.42,700,1,14.48,1400,2,ARL,359803101
2091,2025-07-17T16:29:39.396248056Z,2025-07-17T16:29:39.396248056Z,10,2,1108,A,A,1,13.5,100,130,165394,298834883,13.11,100,1,13.49,15,1,12.98,200,2,13.5,100,1,12.9,2,1,13.51,15,1,12.86,100,1,13.82,2,1,12.73,100,1,13.83,100,1,12.71,100,1,14.17,100,1,12.5,700,1,14.23,100,1,12.46,100,1,14.26,700,1,12.43,700,1,14.33,100,1,12.42,700,1,14.46,200,2,ARL,359822513
2092,2025-07-17T16:29:44.668873033Z,2025-07-17T16:29:44.668873033Z,10,2,1108,C,A,2,13.51,15,130,165445,298899512,13.11,100,1,13.49,15,1,12.98,200,2,13.5,100,1,12.9,2,1,13.82,2,1,12.86,100,1,13.83,100,1,12.73,100,1,14.17,100,1,12.71,100,1,14.23,100,1,12.5,700,1,14.26,700,1,12.46,100,1,14.33,100,1,12.43,700,1,14.46,200,2,12.42,700,1,14.48,1400,2,ARL,359747973
2093,2025-07-17T16:29:56.855401137Z,2025-07-17T16:29:56.855401137Z,10,2,1108,A,A,0,13.47,15,130,165455,299064196,13.11,100,1,13.47,15,1,12.98,200,2,13.49,15,1,12.9,2,1,13.5,100,1,12.86,100,1,13.82,2,1,12.73,100,1,13.83,100,1,12.71,100,1,14.17,100,1,12.5,700,1,14.23,100,1,12.46,100,1,14.26,700,1,12.43,700,1,14.33,100,1,12.42,700,1,14.46,200,2,ARL,360132781
2094,2025-07-17T16:29:57.332665339Z,2025-07-17T16:29:57.332665339Z,10,2,1108,C,A,2,13.5,100,130,165558,299070813,13.11,100,1,13.47,15,1,12.98,200,2,13.49,15,1,12.9,2,1,13.82,2,1,12.86,100,1,13.83,100,1,12.73,100,1,14.17,100,1,12.71,100,1,14.23,100,1,12.5,700,1,14.26,700,1,12.46,100,1,14.33,100,1,12.43,700,1,14.46,200,2,12.42,700,1,14.48,1400,2,ARL,359822513
2095,2025-07-17T16:29:57.332939872Z,2025-07-17T16:29:57.332939872Z,10,2,1108,C,A,6,14.26,700,130,165574,299070819,13.11,100,1,13.47,15,1,12.98,200,2,13.49,15,1,12.9,2,1,13.82,2,1,12.86,100,1,13.83,100,1,12.73,100,1,14.17,100,1,12.71,100,1,14.23,100,1,12.5,700,1,14.33,100,1,12.46,100,1,14.46,200,2,12.43,700,1,14.48,1400,2,12.42,700,1,14.49,200,2,ARL,358712189
2096,2025-07-17T16:29:57.332990460Z,2025-07-17T16:29:57.332990460Z,10,2,1108,A,A,7,14.46,700,130,165656,299070821,13.11,100,1,13.47,15,1,12.98,200,2,13.49,15,1,12.9,2,1,13.82,2,1,12.86,100,1,13.83,100,1,12.73,100,1,14.17,100,1,12.71,100,1,14.23,100,1,12.5,700,1,14.33,100,1,12.46,100,1,14.46,900,3,12.43,700,1,14.48,1400,2,12.42,700,1,14.49,200,2,ARL,360140477
2097,2025-07-17T16:29:57.333403536Z,2025-07-17T16:29:57.333403536Z,10,2,1108,C,A,4,14.17,100,130,165352,299070833,13.11,100,1,13.47,15,1,12.98,200,2,13.49,15,1,12.9,2,1,13.82,2,1,12.86,100,1,13.83,100,1,12.73,100,1,14.23,100,1,12.71,100,1,14.33,100,1,12.5,700,1,14.46,900,3,12.46,100,1,14.48,1400,2,12.43,700,1,14.49,200,2,12.42,700,1,14.53,100,1,ARL,358923345
2098,2025-07-17T16:29:57.333760331Z,2025-07-17T16:29:57.333760331Z,10,2,1108,A,A,6,14.38,100,130,165209,299070841,13.11,100,1,13.47,15,1,12.98,200,2,13.49,15,1,12.9,2,1,13.82,2,1,12.86,100,1,13.83,100,1,12.73,100,1,14.23,100,1,12.71,100,1,14.33,100,1,12.5,700,1,14.38,100,1,12.46,100,1,14.46,900,3,12.43,700,1,14.48,1400,2,12.42,700,1,14.49,200,2,ARL,360140533
2099,2025-07-17T16:29:57.334656229Z,2025-07-17T16:29:57.334656229Z,10,2,1108,C,A,9,14.49,100,0,165974,299070877,13.11,100,1,13.47,15,1,12.98,200,2,13.49,15,1,12.9,2,1,13.82,2,1,12.86,100,1,13.83,100,1,12.73,100,1,14.23,100,1,12.71,100,1,14.33,100,1,12.5,700,1,14.38,100,1,12.46,100,1,14.46,900,3,12.43,700,1,14.48,1400,2,12.42,700,1,14.49,100,1,ARL,359403985
2100,2025-07-17T16:29:57.342360168Z,2025-07-17T16:29:57.342360168Z,10,2,1108,C,A,5,14.33,100,130,165318,299071022,13.11,100,1,13.47,15,1,12.98,200,2,13.49,15,1,12.9,2,1,13.82,2,1,12.86,100,1,13.83,100,1,12.73,100,1,14.23,100,1,12.71,100,1,14.38,100,1,12.5,700,1,14.46,900,3,12.46,100,1,14.48,1400,2,12.43,700,1,14.49,100,1,12.42,700,1,14.53,100,1,ARL,359406981
2101,2025-07-17T16:29:57.346522920Z,2025-07-17T16:29:57.346522920Z,10,2,1108,C,A,3,13.83,100,130,165406,299071131,13.11,100,1,13.47,15,1,12.98,200,2,13.49,15,1,12.9,2,1,13.82,2,1,12.86,100,1,14.23,100,1,12.73,100,1,14.38,100,1,12.71,100,1,14.46,900,3,12.5,700,1,14.48,1400,2,12.46,100,1,14.49,100,1,12.43,700,1,14.53,100,1,12.42,700,1,14.54,700,1,ARL,358923457
2102,2025-07-17T16:29:57.346555573Z,2025-07-17T16:29:57.346555573Z,10,2,1108,C,A,5,14.46,700,130,165048,299071132,13.11,100,1,13.47,15,1,12.98,200,2,13.49,15,1,12.9,2,1,13.82,2,1,12.86,100,1,14.23,100,1,12.73,100,1,14.38,100,1,12.71,100,1,14.46,200,2,12.5,700,1,14.48,1400,2,12.46,100,1,14.49,100,1,12.43,700,1,14.53,100,1,12.42,700,1,14.54,700,1,ARL,360140477
2103,2025-07-17T16:29:57.346575752Z,2025-07-17T16:29:57.346575752Z,10,2,1108,A,A,3,14.05,100,130,165491,299071133,13.11,100,1,13.47,15,1,12.98,200,2,13.49,15,1,12.9,2,1,13.82,2,1,12.86,100,1,14.05,100,1,12.73,100,1,14.23,100,1,12.71,100,1,14.38,100,1,12.5,700,1,14.46,200,2,12.46,100,1,14.48,1400,2,12.43,700,1,14.49,100,1,12.42,700,1,14.53,100,1,ARL,360140905
2104,2025-07-17T16:29:57.351177695Z,2025-07-17T16:29:57.351177695Z,10,2,1108,A,A,1,13.48,100,130,165351,299071172,13.11,100,1,13.47,15,1,12.98,200,2,13.48,100,1,12.9,2,1,13.49,15,1,12.86,100,1,13.82,2,1,12.73,100,1,14.05,100,1,12.71,100,1,14.23,100,1,12.5,700,1,14.38,100,1,12.46,100,1,14.46,200,2,12.43,700,1,14.48,1400,2,12.42,700,1,14.49,100,1,ARL,360140981
2105,2025-07-17T16:29:57.352902068Z,2025-07-17T16:29:57.352902068Z,10,2,1108,A,A,7,14.43,100,130,165323,299071184,13.11,100,1,13.47,15,1,12.98,200,2,13.48,100,1,12.9,2,1,13.49,15,1,12.86,100,1,13.82,2,1,12.73,100,1,14.05,100,1,12.71,100,1,14.23,100,1,12.5,700,1,14.38,100,1,12.46,100,1,14.43,100,1,12.43,700,1,14.46,200,2,12.42,700,1,14.48,1400,2,ARL,360141061
2106,2025-07-17T16:29:57.365286456Z,2025-07-17T16:29:57.365286456Z,10,2,1108,C,A,4,14.05,100,130,165057,299071406,13.11,100,1,13.47,15,1,12.98,200,2,13.48,100,1,12.9,2,1,13.49,15,1,12.86,100,1,13.82,2,1,12.73,100,1,14.23,100,1,12.71,100,1,14.38,100,1,12.5,700,1,14.43,100,1,12.46,100,1,14.46,200,2,12.43,700,1,14.48,1400,2,12.42,700,1,14.49,100,1,ARL,360140905
2107,2025-07-17T16:29:57.365333299Z,2025-07-17T16:29:57.365333299Z,10,2,1108,A,A,5,14.26,100,130,165468,299071407,13.11,100,1,13.47,15,1,12.98,200,2,13.48,100,1,12.9,2,1,13.49,15,1,12.86,100,1,13.82,2,1,12.73,100,1,14.23,100,1,12.71,100,1,14.26,100,1,12.5,700,1,14.38,100,1,12.46,100,1,14.43,100,1,12.43,700,1,14.46,200,2,12.42,700,1,14.48,1400,2,ARL,360141269
2108,2025-07-17T16:29:57.366149175Z,2025-07-17T16:29:57.366149175Z,10,2,1108,C,A,5,14.26,100,130,165221,299071411,13.11,100,1,13.47,15,1,12.98,200,2,13.48,100,1,12.9,2,1,13.49,15,1,12.86,100,1,13.82,2,1,12.73,100,1,14.23,100,1,12.71,100,1,14.38,100,1,12.5,700,1,14.43,100,1,12.46,100,1,14.46,200,2,12.43,700,1,14.48,1400,2,12.42,700,1,14.49,100,1,ARL,360141269
2109,2025-07-17T16:29:57.366196404Z,2025-07-17T16:29:57.366196404Z,10,2,1108,A,A,3,13.75,100,130,165690,299071412,13.11,100,1,13.47,15,1,12.98,200,2,13.48,100,1,12.9,2,1,13.49,15,1,12.86,100,1,13.75,100,1,12.73,100,1,13.82,2,1,12.71,100,1,14.23,100,1,12.5,700,1,14.38,100,1,12.46,100,1,14.43,100,1,12.43,700,1,14.46,200,2,12.42,700,1,14.48,1400,2,ARL,360141273
2110,2025-07-17T16:29:57.981737315Z,2025-07-17T16:29:57.981737315Z,10,2,1108,C,A,6,14.38,100,130,165183,299079629,13.11,100,1,13.47,15,1,12.98,200,2,13.48,100,1,12.9,2,1,13.49,15,1,12.86,100,1,13.75,100,1,12.73,100,1,13.82,2,1,12.71,100,1,14.23,100,1,12.5,700,1,14.43,100,1,12.46,100,1,14.46,200,2,12.43,700,1,14.48,1400,2,12.42,700,1,14.49,100,1,ARL,360140533
2111,2025-07-17T16:29:57.982089749Z,2025-07-17T16:29:57.982089749Z,10,2,1108,A,A,5,14.08,100,130,165985,299079655,13.11,100,1,13.47,15,1,12.98,200,2,13.48,100,1,12.9,2,1,13.49,15,1,12.86,100,1,13.75,100,1,12.73,100,1,13.82,2,1,12.71,100,1,14.08,100,1,12.5,700,1,14.23,100,1,12.46,100,1,14.43,100,1,12.43,700,1,14.46,200,2,12.42,700,1,14.48,1400,2,ARL,360153053
2112,2025-07-17T16:29:58.344397545Z,2025-07-17T16:29:58.344397545Z,10,2,1108,A,A,7,14.27,100,130,165541,299094491,13.11,100,1,13.47,15,1,12.98,200,2,13.48,100,1,12.9,2,1,13.49,15,1,12.86,100,1,13.75,100,1,12.73,100,1,13.82,2,1,12.71,100,1,14.08,100,1,12.5,700,1,14.23,100,1,12.46,100,1,14.27,100,1,12.43,700,1,14.43,100,1,12.42,700,1,14.46,200,2,ARL,360169365
2113,2025-07-17T16:30:02.830774434Z,2025-07-17T16:30:02.830774434Z,10,2,1108,A,A,6,14.19,700,130,165407,299196935,13.11,100,1,13.47,15,1,12.98,200,2,13.48,100,1,12.9,2,1,13.49,15,1,12.86,100,1,13.75,100,1,12.73,100,1,13.82,2,1,12.71,100,1,14.08,100,1,12.5,700,1,14.19,700,1,12.46,100,1,14.23,100,1,12.43,700,1,14.27,100,1,12.42,700,1,14.43,100,1,ARL,360283881
2114,2025-07-17T16:30:05.499406444Z,2025-07-17T16:30:05.499406444Z,10,2,1108,C,A,2,13.49,15,130,165318,299240923,13.11,100,1,13.47,15,1,12.98,200,2,13.48,100,1,12.9,2,1,13.75,100,1,12.86,100,1,13.82,2,1,12.73,100,1,14.08,100,1,12.71,100,1,14.19,700,1,12.5,700,1,14.23,100,1,12.46,100,1,14.27,100,1,12.43,700,1,14.43,100,1,12.42,700,1,14.46,200,2,ARL,359807057
2115,2025-07-17T16:30:10.414112314Z,2025-07-17T16:30:10.414112314Z,10,2,1108,C,A,0,13.47,15,130,165571,299312853,13.11,100,1,13.48,100,1,12.98,200,2,13.75,100,1,12.9,2,1,13.82,2,1,12.86,100,1,14.08,100,1,12.73,100,1,14.19,700,1,12.71,100,1,14.23,100,1,12.5,700,1,14.27,100,1,12.46,100,1,14.43,100,1,12.43,700,1,14.46,200,2,12.42,700,1,14.48,1400,2,ARL,360132781
2116,2025-07-17T16:30:10.416115247Z,2025-07-17T16:30:10.416115247Z,10,2,1108,A,A,0,13.45,15,130,167237,299313346,13.11,100,1,13.45,15,1,12.98,200,2,13.48,100,1,12.9,2,1,13.75,100,1,12.86,100,1,13.82,2,1,12.73,100,1,14.08,100,1,12.71,100,1,14.19,700,1,12.5,700,1,14.23,100,1,12.46,100,1,14.27,100,1,12.43,700,1,14.43,100,1,12.42,700,1,14.46,200,2,ARL,360438585
2117,2025-07-17T16:30:10.418822976Z,2025-07-17T16:30:10.418822976Z,10,2,1108,C,A,9,14.46,100,0,166027,299313811,13.11,100,1,13.45,15,1,12.98,200,2,13.48,100,1,12.9,2,1,13.75,100,1,12.86,100,1,13.82,2,1,12.73,100,1,14.08,100,1,12.71,100,1,14.19,700,1,12.5,700,1,14.23,100,1,12.46,100,1,14.27,100,1,12.43,700,1,14.43,100,1,12.42,700,1,14.46,100,1,ARL,358596029
2118,2025-07-17T16:30:10.418822976Z,2025-07-17T16:30:10.418822976Z,10,2,1108,A,A,8,14.35,100,130,166027,299313811,13.11,100,1,13.45,15,1,12.98,200,2,13.48,100,1,12.9,2,1,13.75,100,1,12.86,100,1,13.82,2,1,12.73,100,1,14.08,100,1,12.71,100,1,14.19,700,1,12.5,700,1,14.23,100,1,12.46,100,1,14.27,100,1,12.43,700,1,14.35,100,1,12.42,700,1,14.43,100,1,ARL,360438973
2119,2025-07-17T16:30:10.421853908Z,2025-07-17T16:30:10.421853908Z,10,2,1108,A,A,8,14.35,100,130,165940,299314095,13.11,100,1,13.45,15,1,12.98,200,2,13.48,100,1,12.9,2,1,13.75,100,1,12.86,100,1,13.82,2,1,12.73,100,1,14.08,100,1,12.71,100,1,14.19,700,1,12.5,700,1,14.23,100,1,12.46,100,1,14.27,100,1,12.43,700,1,14.35,200,2,12.42,700,1,14.43,100,1,ARL,360439617
2120,2025-07-17T16:30:10.853617251Z,2025-07-17T16:30:10.853617251Z,10,2,1108,C,A,0,13.45,15,128,166165,299339139,13.11,100,1,13.48,100,1,12.98,200,2,13.75,100,1,12.9,2,1,13.82,2,1,12.86,100,1,14.08,100,1,12.73,100,1,14.19,700,1,12.71,100,1,14.23,100,1,12.5,700,1,14.27,100,1,12.46,100,1,14.35,200,2,12.43,700,1,14.43,100,1,12.42,700,1,14.48,1400,2,ARL,360438585
2121,2025-07-17T16:30:17.585941385Z,2025-07-17T16:30:17.585941385Z,10,2,1108,C,A,2,13.82,2,0,165621,299471791,13.11,100,1,13.48,100,1,12.98,200,2,13.75,100,1,12.9,2,1,14.08,100,1,12.86,100,1,14.19,700,1,12.73,100,1,14.23,100,1,12.71,100,1,14.27,100,1,12.5,700,1,14.35,200,2,12.46,100,1,14.43,100,1,12.43,700,1,14.48,1400,2,12.42,700,1,14.49,100,1,ARL,359459321
2122,2025-07-17T16:30:17.585941385Z,2025-07-17T16:30:17.585941385Z,10,2,1108,A,A,1,13.74,2,130,165621,299471791,13.11,100,1,13.48,100,1,12.98,200,2,13.74,2,1,12.9,2,1,13.75,100,1,12.86,100,1,14.08,100,1,12.73,100,1,14.19,700,1,12.71,100,1,14.23,100,1,12.5,700,1,14.27,100,1,12.46,100,1,14.35,200,2,12.43,700,1,14.43,100,1,12.42,700,1,14.48,1400,2,ARL,360630309
2123,2025-07-17T16:30:20.998120507Z,2025-07-17T16:30:20.998120507Z,10,2,1108,C,A,0,13.48,100,130,165816,299514720,13.11,100,1,13.74,2,1,12.98,200,2,13.75,100,1,12.9,2,1,14.08,100,1,12.86,100,1,14.19,700,1,12.73,100,1,14.23,100,1,12.71,100,1,14.27,100,1,12.5,700,1,14.35,200,2,12.46,100,1,14.43,100,1,12.43,700,1,14.48,1400,2,12.42,700,1,14.49,100,1,ARL,360140981
2124,2025-07-17T16:30:22.627136264Z,2025-07-17T16:30:22.627136264Z,10,2,1108,A,A,2,13.76,100,130,165384,299534828,13.11,100,1,13.74,2,1,12.98,200,2,13.75,100,1,12.9,2,1,13.76,100,1,12.86,100,1,14.08,100,1,12.73,100,1,14.19,700,1,12.71,100,1,14.23,100,1,12.5,700,1,14.27,100,1,12.46,100,1,14.35,200,2,12.43,700,1,14.43,100,1,12.42,700,1,14.48,1400,2,ARL,360721497
2125,2025-07-17T16:30:22.654329199Z,2025-07-17T16:30:22.654329199Z,10,2,1108,A,A,0,13.47,15,128,166904,299538824,13.11,100,1,13.47,15,1,12.98,200,2,13.74,2,1,12.9,2,1,13.75,100,1,12.86,100,1,13.76,100,1,12.73,100,1,14.08,100,1,12.71,100,1,14.19,700,1,12.5,700,1,14.23,100,1,12.46,100,1,14.27,100,1,12.43,700,1,14.35,200,2,12.42,700,1,14.43,100,1,ARL,360725173
2126,2025-07-17T16:30:22.654486255Z,2025-07-17T16:30:22.654486255Z,10,2,1108,C,A,3,13.76,100,0,165570,299538851,13.11,100,1,13.47,15,1,12.98,200,2,13.74,2,1,12.9,2,1,13.75,100,1,12.86,100,1,14.08,100,1,12.73,100,1,14.19,700,1,12.71,100,1,14.23,100,1,12.5,700,1,14.27,100,1,12.46,100,1,14.35,200,2,12.43,700,1,14.43,100,1,12.42,700,1,14.48,1400,2,ARL,360721497
2127,2025-07-17T16:30:22.654486255Z,2025-07-17T16:30:22.654486255Z,10,2,1108,A,A,1,13.48,100,130,165570,299538851,13.11,100,1,13.47,15,1,12.98,200,2,13.48,100,1,12.9,2,1,13.74,2,1,12.86,100,1,13.75,100,1,12.73,100,1,14.08,100,1,12.71,100,1,14.19,700,1,12.5,700,1,14.23,100,1,12.46,100,1,14.27,100,1,12.43,700,1,14.35,200,2,12.42,700,1,14.43,100,1,ARL,360725257
2128,2025-07-17T16:30:32.855591892Z,2025-07-17T16:30:32.855591892Z,10,2,1108,A,A,0,13.45,15,130,165273,299703863,13.11,100,1,13.45,15,1,12.98,200,2,13.47,15,1,12.9,2,1,13.48,100,1,12.86,100,1,13.74,2,1,12.73,100,1,13.75,100,1,12.71,100,1,14.08,100,1,12.5,700,1,14.19,700,1,12.46,100,1,14.23,100,1,12.43,700,1,14.27,100,1,12.42,700,1,14.35,200,2,ARL,360937965
2129,2025-07-17T16:30:37.084955904Z,2025-07-17T16:30:37.084955904Z,10,2,1108,C,A,2,13.48,100,0,166517,299811310,13.11,100,1,13.45,15,1,12.98,200,2,13.47,15,1,12.9,2,1,13.74,2,1,12.86,100,1,13.75,100,1,12.73,100,1,14.08,100,1,12.71,100,1,14.19,700,1,12.5,700,1,14.23,100,1,12.46,100,1,14.27,100,1,12.43,700,1,14.35,200,2,12.42,700,1,14.43,100,1,ARL,360725257
2130,2025-07-17T16:30:37.084955904Z,2025-07-17T16:30:37.084955904Z,10,2,1108,A,A,1,13.46,100,128,166517,299811310,13.11,100,1,13.45,15,1,12.98,200,2,13.46,100,1,12.9,2,1,13.47,15,1,12.86,100,1,13.74,2,1,12.73,100,1,13.75,100,1,12.71,100,1,14.08,100,1,12.5,700,1,14.19,700,1,12.46,100,1,14.23,100,1,12.43,700,1,14.27,100,1,12.42,700,1,14.35,200,2,ARL,361057077
2131,2025-07-17T16:30:37.137592621Z,2025-07-17T16:30:37.137592621Z,10,2,1108,C,A,2,13.47,15,130,165237,299813487,13.11,100,1,13.45,15,1,12.98,200,2,13.46,100,1,12.9,2,1,13.74,2,1,12.86,100,1,13.75,100,1,12.73,100,1,14.08,100,1,12.71,100,1,14.19,700,1,12.5,700,1,14.23,100,1,12.46,100,1,14.27,100,1,12.43,700,1,14.35,200,2,12.42,700,1,14.43,100,1,ARL,360725173
2132,2025-07-17T16:30:38.141240528Z,2025-07-17T16:30:38.141240528Z,10,2,1108,A,A,0,13.43,15,130,165366,299865395,13.11,100,1,13.43,15,1,12.98,200,2,13.45,15,1,12.9,2,1,13.46,100,1,12.86,100,1,13.74,2,1,12.73,100,1,13.75,100,1,12.71,100,1,14.08,100,1,12.5,700,1,14.19,700,1,12.46,100,1,14.23,100,1,12.43,700,1,14.27,100,1,12.42,700,1,14.35,200,2,ARL,361107853
2133,2025-07-17T16:30:47.573300334Z,2025-07-17T16:30:47.573300334Z,10,2,1108,C,A,1,13.45,15,130,165315,300016920,13.11,100,1,13.43,15,1,12.98,200,2,13.46,100,1,12.9,2,1,13.74,2,1,12.86,100,1,13.75,100,1,12.73,100,1,14.08,100,1,12.71,100,1,14.19,700,1,12.5,700,1,14.23,100,1,12.46,100,1,14.27,100,1,12.43,700,1,14.35,200,2,12.42,700,1,14.43,100,1,ARL,360937965
2134,2025-07-17T16:30:48.578195765Z,2025-07-17T16:30:48.578195765Z,10,2,1108,A,A,0,13.41,15,130,165346,300031495,13.11,100,1,13.41,15,1,12.98,200,2,13.43,15,1,12.9,2,1,13.46,100,1,12.86,100,1,13.74,2,1,12.73,100,1,13.75,100,1,12.71,100,1,14.08,100,1,12.5,700,1,14.19,700,1,12.46,100,1,14.23,100,1,12.43,700,1,14.27,100,1,12.42,700,1,14.35,200,2,ARL,361297545
2135,2025-07-17T16:31:01.839792805Z,2025-07-17T16:31:01.839792805Z,10,2,1108,C,A,1,13.43,15,130,165506,300264348,13.11,100,1,13.41,15,1,12.98,200,2,13.46,100,1,12.9,2,1,13.74,2,1,12.86,100,1,13.75,100,1,12.73,100,1,14.08,100,1,12.71,100,1,14.19,700,1,12.5,700,1,14.23,100,1,12.46,100,1,14.27,100,1,12.43,700,1,14.35,200,2,12.42,700,1,14.43,100,1,ARL,361107853
2136,2025-07-17T16:31:03.518351610Z,2025-07-17T16:31:03.518351610Z,10,2,1108,A,A,0,13.39,15,130,165898,300289961,13.11,100,1,13.39,15,1,12.98,200,2,13.41,15,1,12.9,2,1,13.46,100,1,12.86,100,1,13.74,2,1,12.73,100,1,13.75,100,1,12.71,100,1,14.08,100,1,12.5,700,1,14.19,700,1,12.46,100,1,14.23,100,1,12.43,700,1,14.27,100,1,12.42,700,1,14.35,200,2,ARL,361608869
2137,2025-07-17T16:31:54.027625924Z,2025-07-17T16:31:54.027625924Z,10,2,1108,C,A,0,13.39,15,128,173537,301134389,13.11,100,1,13.41,15,1,12.98,200,2,13.46,100,1,12.9,2,1,13.74,2,1,12.86,100,1,13.75,100,1,12.73,100,1,14.08,100,1,12.71,100,1,14.19,700,1,12.5,700,1,14.23,100,1,12.46,100,1,14.27,100,1,12.43,700,1,14.35,200,2,12.42,700,1,14.43,100,1,ARL,361608869
2138,2025-07-17T16:31:54.028224104Z,2025-07-17T16:31:54.028224104Z,10,2,1108,C,A,0,13.41,15,128,168293,301134777,13.11,100,1,13.46,100,1,12.98,200,2,13.74,2,1,12.9,2,1,13.75,100,1,12.86,100,1,14.08,100,1,12.73,100,1,14.19,700,1,12.71,100,1,14.23,100,1,12.5,700,1,14.27,100,1,12.46,100,1,14.35,200,2,12.43,700,1,14.43,100,1,12.42,700,1,14.48,1400,2,ARL,361297545
2139,2025-07-17T16:31:54.032676481Z,2025-07-17T16:31:54.032676481Z,10,2,1108,A,A,0,13.4,15,130,165282,301135720,13.11,100,1,13.4,15,1,12.98,200,2,13.46,100,1,12.9,2,1,13.74,2,1,12.86,100,1,13.75,100,1,12.73,100,1,14.08,100,1,12.71,100,1,14.19,700,1,12.5,700,1,14.23,100,1,12.46,100,1,14.27,100,1,12.43,700,1,14.35,200,2,12.42,700,1,14.43,100,1,ARL,362676381
2140,2025-07-17T16:31:54.397082756Z,2025-07-17T16:31:54.397082756Z,10,2,1108,C,A,0,13.4,15,128,169133,301159766,13.11,100,1,13.46,100,1,12.98,200,2,13.74,2,1,12.9,2,1,13.75,100,1,12.86,100,1,14.08,100,1,12.73,100,1,14.19,700,1,12.71,100,1,14.23,100,1,12.5,700,1,14.27,100,1,12.46,100,1,14.35,200,2,12.43,700,1,14.43,100,1,12.42,700,1,14.48,1400,2,ARL,362676381
2141,2025-07-17T16:32:07.237509237Z,2025-07-17T16:32:07.237509237Z,10,2,1108,A,A,0,13.43,15,130,165199,301520854,13.11,100,1,13.43,15,1,12.98,200,2,13.46,100,1,12.9,2,1,13.74,2,1,12.86,100,1,13.75,100,1,12.73,100,1,14.08,100,1,12.71,100,1,14.19,700,1,12.5,700,1,14.23,100,1,12.46,100,1,14.27,100,1,12.43,700,1,14.35,200,2,12.42,700,1,14.43,100,1,ARL,363127401
2142,2025-07-17T16:32:11.247654753Z,2025-07-17T16:32:11.247654753Z,10,2,1108,A,A,0,13.41,15,130,165563,301601389,13.11,100,1,13.41,15,1,12.98,200,2,13.43,15,1,12.9,2,1,13.46,100,1,12.86,100,1,13.74,2,1,12.73,100,1,13.75,100,1,12.71,100,1,14.08,100,1,12.5,700,1,14.19,700,1,12.46,100,1,14.23,100,1,12.43,700,1,14.27,100,1,12.42,700,1,14.35,200,2,ARL,363219933
2143,2025-07-17T16:32:14.460177384Z,2025-07-17T16:32:14.460177384Z,10,2,1108,C,A,1,13.43,15,130,165327,301668882,13.11,100,1,13.41,15,1,12.98,200,2,13.46,100,1,12.9,2,1,13.74,2,1,12.86,100,1,13.75,100,1,12.73,100,1,14.08,100,1,12.71,100,1,14.19,700,1,12.5,700,1,14.23,100,1,12.46,100,1,14.27,100,1,12.43,700,1,14.35,200,2,12.42,700,1,14.43,100,1,ARL,363127401
2144,2025-07-17T16:32:15.799985302Z,2025-07-17T16:32:15.799985302Z,10,2,1108,A,A,0,13.39,15,128,166944,301682529,13.11,100,1,13.39,15,1,12.98,200,2,13.41,15,1,12.9,2,1,13.46,100,1,12.86,100,1,13.74,2,1,12.73,100,1,13.75,100,1,12.71,100,1,14.08,100,1,12.5,700,1,14.19,700,1,12.46,100,1,14.23,100,1,12.43,700,1,14.27,100,1,12.42,700,1,14.35,200,2,ARL,363311909
2145,2025-07-17T16:32:24.791064822Z,2025-07-17T16:32:24.791064822Z,10,2,1108,C,A,0,13.39,15,130,166555,301841660,13.11,100,1,13.41,15,1,12.98,200,2,13.46,100,1,12.9,2,1,13.74,2,1,12.86,100,1,13.75,100,1,12.73,100,1,14.08,100,1,12.71,100,1,14.19,700,1,12.5,700,1,14.23,100,1,12.46,100,1,14.27,100,1,12.43,700,1,14.35,200,2,12.42,700,1,14.43,100,1,ARL,363311909
2146,2025-07-17T16:32:24.791200959Z,2025-07-17T16:32:24.791200959Z,10,2,1108,C,A,0,13.41,15,130,165196,301841671,13.11,100,1,13.46,100,1,12.98,200,2,13.74,2,1,12.9,2,1,13.75,100,1,12.86,100,1,14.08,100,1,12.73,100,1,14.19,700,1,12.71,100,1,14.23,100,1,12.5,700,1,14.27,100,1,12.46,100,1,14.35,200,2,12.43,700,1,14.43,100,1,12.42,700,1,14.48,1400,2,ARL,363219933
2147,2025-07-17T16:32:29.844658946Z,2025-07-17T16:32:29.844658946Z,10,2,1108,A,A,0,13.45,15,130,165290,301914964,13.11,100,1,13.45,15,1,12.98,200,2,13.46,100,1,12.9,2,1,13.74,2,1,12.86,100,1,13.75,100,1,12.73,100,1,14.08,100,1,12.71,100,1,14.19,700,1,12.5,700,1,14.23,100,1,12.46,100,1,14.27,100,1,12.43,700,1,14.35,200,2,12.42,700,1,14.43,100,1,ARL,363610537
2148,2025-07-17T16:32:29.844711976Z,2025-07-17T16:32:29.844711976Z,10,2,1108,C,A,1,13.46,100,130,165292,301914968,13.11,100,1,13.45,15,1,12.98,200,2,13.74,2,1,12.9,2,1,13.75,100,1,12.86,100,1,14.08,100,1,12.73,100,1,14.19,700,1,12.71,100,1,14.23,100,1,12.5,700,1,14.27,100,1,12.46,100,1,14.35,200,2,12.43,700,1,14.43,100,1,12.42,700,1,14.48,1400,2,ARL,361057077
2149,2025-07-17T16:32:29.845442602Z,2025-07-17T16:32:29.845442602Z,10,2,1108,C,A,4,14.19,700,130,165488,301914978,13.11,100,1,13.45,15,1,12.98,200,2,13.74,2,1,12.9,2,1,13.75,100,1,12.86,100,1,14.08,100,1,12.73,100,1,14.23,100,1,12.71,100,1,14.27,100,1,12.5,700,1,14.35,200,2,12.46,100,1,14.43,100,1,12.43,700,1,14.48,1400,2,12.42,700,1,14.49,100,1,ARL,360283881
2150,2025-07-17T16:32:29.845485675Z,2025-07-17T16:32:29.845485675Z,10,2,1108,A,A,8,14.44,700,130,165291,301914979,13.11,100,1,13.45,15,1,12.98,200,2,13.74,2,1,12.9,2,1,13.75,100,1,12.86,100,1,14.08,100,1,12.73,100,1,14.23,100,1,12.71,100,1,14.27,100,1,12.5,700,1,14.35,200,2,12.46,100,1,14.43,100,1,12.43,700,1,14.44,700,1,12.42,700,1,14.48,1400,2,ARL,363610557
2151,2025-07-17T16:32:29.846012015Z,2025-07-17T16:32:29.846012015Z,10,2,1108,C,A,3,14.08,100,130,165612,301914986,13.11,100,1,13.45,15,1,12.98,200,2,13.74,2,1,12.9,2,1,13.75,100,1,12.86,100,1,14.23,100,1,12.73,100,1,14.27,100,1,12.71,100,1,14.35,200,2,12.5,700,1,14.43,100,1,12.46,100,1,14.44,700,1,12.43,700,1,14.48,1400,2,12.42,700,1,14.49,100,1,ARL,360153053
2152,2025-07-17T16:32:29.846367579Z,2025-07-17T16:32:29.846367579Z,10,2,1108,A,A,6,14.36,100,130,165666,301914994,13.11,100,1,13.45,15,1,12.98,200,2,13.74,2,1,12.9,2,1,13.75,100,1,12.86,100,1,14.23,100,1,12.73,100,1,14.27,100,1,12.71,100,1,14.35,200,2,12.5,700,1,14.36,100,1,12.46,100,1,14.43,100,1,12.43,700,1,14.44,700,1,12.42,700,1,14.48,1400,2,ARL,363610593
2153,2025-07-17T16:32:29.848085539Z,2025-07-17T16:32:29.848085539Z,10,2,1108,C,A,7,14.43,100,0,165525,301915015,13.11,100,1,13.45,15,1,12.98,200,2,13.74,2,1,12.9,2,1,13.75,100,1,12.86,100,1,14.23,100,1,12.73,100,1,14.27,100,1,12.71,100,1,14.35,200,2,12.5,700,1,14.36,100,1,12.46,100,1,14.44,700,1,12.43,700,1,14.48,1400,2,12.42,700,1,14.49,100,1,ARL,360141061
2154,2025-07-17T16:32:29.852046762Z,2025-07-17T16:32:29.852046762Z,10,2,1108,C,A,4,14.27,100,130,165276,301915065,13.11,100,1,13.45,15,1,12.98,200,2,13.74,2,1,12.9,2,1,13.75,100,1,12.86,100,1,14.23,100,1,12.73,100,1,14.35,200,2,12.71,100,1,14.36,100,1,12.5,700,1,14.44,700,1,12.46,100,1,14.48,1400,2,12.43,700,1,14.49,100,1,12.42,700,1,14.53,100,1,ARL,360169365
2155,2025-07-17T16:32:29.852164762Z,2025-07-17T16:32:29.852164762Z,10,2,1108,A,A,10,14.54,100,130,165239,301915069,13.11,100,1,13.45,15,1,12.98,200,2,13.74,2,1,12.9,2,1,13.75,100,1,12.86,100,1,14.23,100,1,12.73,100,1,14.35,200,2,12.71,100,1,14.36,100,1,12.5,700,1,14.44,700,1,12.46,100,1,14.48,1400,2,12.43,700,1,14.49,100,1,12.42,700,1,14.53,100,1,ARL,363610649
2156,2025-07-17T16:32:29.855929386Z,2025-07-17T16:32:29.855929386Z,10,2,1108,C,A,2,13.75,100,130,165410,301915115,13.11,100,1,13.45,15,1,12.98,200,2,13.74,2,1,12.9,2,1,14.23,100,1,12.86,100,1,14.35,200,2,12.73,100,1,14.36,100,1,12.71,100,1,14.44,700,1,12.5,700,1,14.48,1400,2,12.46,100,1,14.49,100,1,12.43,700,1,14.53,100,1,12.42,700,1,14.54,800,2,ARL,360141273
2157,2025-07-17T16:32:29.855960388Z,2025-07-17T16:32:29.855960388Z,10,2,1108,C,A,5,14.44,700,130,164953,301915116,13.11,100,1,13.45,15,1,12.98,200,2,13.74,2,1,12.9,2,1,14.23,100,1,12.86,100,1,14.35,200,2,12.73,100,1,14.36,100,1,12.71,100,1,14.48,1400,2,12.5,700,1,14.49,100,1,12.46,100,1,14.53,100,1,12.43,700,1,14.54,800,2,12.42,700,1,14.72,100,1,ARL,363610557
2158,2025-07-17T16:32:29.855981505Z,2025-07-17T16:32:29.855981505Z,10,2,1108,A,A,2,14.03,100,130,165414,301915117,13.11,100,1,13.45,15,1,12.98,200,2,13.74,2,1,12.9,2,1,14.03,100,1,12.86,100,1,14.23,100,1,12.73,100,1,14.35,200,2,12.71,100,1,14.36,100,1,12.5,700,1,14.48,1400,2,12.46,100,1,14.49,100,1,12.43,700,1,14.53,100,1,12.42,700,1,14.54,800,2,ARL,363610673
2159,2025-07-17T16:32:29.858716093Z,2025-07-17T16:32:29.858716093Z,10,2,1108,C,A,1,13.74,2,0,165584,301915144,13.11,100,1,13.45,15,1,12.98,200,2,14.03,100,1,12.9,2,1,14.23,100,1,12.86,100,1,14.35,200,2,12.73,100,1,14.36,100,1,12.71,100,1,14.48,1400,2,12.5,700,1,14.49,100,1,12.46,100,1,14.53,100,1,12.43,700,1,14.54,800,2,12.42,700,1,14.81,100,1,ARL,360630309
2160,2025-07-17T16:32:29.858716093Z,2025-07-17T16:32:29.858716093Z,10,2,1108,A,A,1,13.98,2,130,165584,301915144,13.11,100,1,13.45,15,1,12.98,200,2,13.98,2,1,12.9,2,1,14.03,100,1,12.86,100,1,14.23,100,1,12.73,100,1,14.35,200,2,12.71,100,1,14.36,100,1,12.5,700,1,14.48,1400,2,12.46,100,1,14.49,100,1,12.43,700,1,14.53,100,1,12.42,700,1,14.54,800,2,ARL,363610729
2161,2025-07-17T16:32:29.876096205Z,2025-07-17T16:32:29.876096205Z,10,2,1108,C,A,2,14.03,100,130,164945,301915267,13.11,100,1,13.45,15,1,12.98,200,2,13.98,2,1,12.9,2,1,14.23,100,1,12.86,100,1,14.35,200,2,12.73,100,1,14.36,100,1,12.71,100,1,14.48,1400,2,12.5,700,1,14.49,100,1,12.46,100,1,14.53,100,1,12.43,700,1,14.54,800,2,12.42,700,1,14.81,100,1,ARL,363610673
2162,2025-07-17T16:32:29.876146665Z,2025-07-17T16:32:29.876146665Z,10,2,1108,A,A,3,14.25,100,130,165664,301915268,13.11,100,1,13.45,15,1,12.98,200,2,13.98,2,1,12.9,2,1,14.23,100,1,12.86,100,1,14.25,100,1,12.73,100,1,14.35,200,2,12.71,100,1,14.36,100,1,12.5,700,1,14.48,1400,2,12.46,100,1,14.49,100,1,12.43,700,1,14.53,100,1,12.42,700,1,14.54,800,2,ARL,363610909
2163,2025-07-17T16:32:29.912262068Z,2025-07-17T16:32:29.912262068Z,10,2,1108,A,A,1,13.46,100,130,165173,301915922,13.11,100,1,13.45,15,1,12.98,200,2,13.46,100,1,12.9,2,1,13.98,2,1,12.86,100,1,14.23,100,1,12.73,100,1,14.25,100,1,12.71,100,1,14.35,200,2,12.5,700,1,14.36,100,1,12.46,100,1,14.48,1400,2,12.43,700,1,14.49,100,1,12.42,700,1,14.53,100,1,ARL,363611637
2164,2025-07-17T16:32:29.913082173Z,2025-07-17T16:32:29.913082173Z,10,2,1108,A,A,7,14.41,100,130,165323,301915949,13.11,100,1,13.45,15,1,12.98,200,2,13.46,100,1,12.9,2,1,13.98,2,1,12.86,100,1,14.23,100,1,12.73,100,1,14.25,100,1,12.71,100,1,14.35,200,2,12.5,700,1,14.36,100,1,12.46,100,1,14.41,100,1,12.43,700,1,14.48,1400,2,12.42,700,1,14.49,100,1,ARL,363611673
2165,2025-07-17T16:32:29.935826022Z,2025-07-17T16:32:29.935826022Z,10,2,1108,C,A,4,14.25,100,130,165649,301916340,13.11,100,1,13.45,15,1,12.98,200,2,13.46,100,1,12.9,2,1,13.98,2,1,12.86,100,1,14.23,100,1,12.73,100,1,14.35,200,2,12.71,100,1,14.36,100,1,12.5,700,1,14.41,100,1,12.46,100,1,14.48,1400,2,12.43,700,1,14.49,100,1,12.42,700,1,14.53,100,1,ARL,363610909
2166,2025-07-17T16:32:29.935877281Z,2025-07-17T16:32:29.935877281Z,10,2,1108,A,A,2,13.73,100,130,165247,301916344,13.11,100,1,13.45,15,1,12.98,200,2,13.46,100,1,12.9,2,1,13.73,100,1,12.86,100,1,13.98,2,1,12.73,100,1,14.23,100,1,12.71,100,1,14.35,200,2,12.5,700,1,14.36,100,1,12.46,100,1,14.41,100,1,12.43,700,1,14.48,1400,2,12.42,700,1,14.49,100,1,ARL,363612541
2167,2025-07-17T16:32:29.947031116Z,2025-07-17T16:32:29.947031116Z,10,2,1108,A,A,10,14.5,100,130,165415,301916544,13.11,100,1,13.45,15,1,12.98,200,2,13.46,100,1,12.9,2,1,13.73,100,1,12.86,100,1,13.98,2,1,12.73,100,1,14.23,100,1,12.71,100,1,14.35,200,2,12.5,700,1,14.36,100,1,12.46,100,1,14.41,100,1,12.43,700,1,14.48,1400,2,12.42,700,1,14.49,100,1,ARL,363612705
2168,2025-07-17T16:32:30.189441584Z,2025-07-17T16:32:30.189441584Z,10,2,1108,C,A,3,13.98,2,0,165662,301922126,13.11,100,1,13.45,15,1,12.98,200,2,13.46,100,1,12.9,2,1,13.73,100,1,12.86,100,1,14.23,100,1,12.73,100,1,14.35,200,2,12.71,100,1,14.36,100,1,12.5,700,1,14.41,100,1,12.46,100,1,14.48,1400,2,12.43,700,1,14.49,100,1,12.42,700,1,14.5,100,1,ARL,363610729
2169,2025-07-17T16:32:30.189441584Z,2025-07-17T16:32:30.189441584Z,10,2,1108,A,A,2,13.7,2,130,165662,301922126,13.11,100,1,13.45,15,1,12.98,200,2,13.46,100,1,12.9,2,1,13.7,2,1,12.86,100,1,13.73,100,1,12.73,100,1,14.23,100,1,12.71,100,1,14.35,200,2,12.5,700,1,14.36,100,1,12.46,100,1,14.41,100,1,12.43,700,1,14.48,1400,2,12.42,700,1,14.49,100,1,ARL,363619809
2170,2025-07-17T16:32:30.540828846Z,2025-07-17T16:32:30.540828846Z,10,2,1108,C,A,6,14.36,100,130,164974,301928173,13.11,100,1,13.45,15,1,12.98,200,2,13.46,100,1,12.9,2,1,13.7,2,1,12.86,100,1,13.73,100,1,12.73,100,1,14.23,100,1,12.71,100,1,14.35,200,2,12.5,700,1,14.41,100,1,12.46,100,1,14.48,1400,2,12.43,700,1,14.49,100,1,12.42,700,1,14.5,100,1,ARL,363610593
2171,2025-07-17T16:32:30.541188934Z,2025-07-17T16:32:30.541188934Z,10,2,1108,A,A,4,14.06,100,130,165369,301928175,13.11,100,1,13.45,15,1,12.98,200,2,13.46,100,1,12.9,2,1,13.7,2,1,12.86,100,1,13.73,100,1,12.73,100,1,14.06,100,1,12.71,100,1,14.23,100,1,12.5,700,1,14.35,200,2,12.46,100,1,14.41,100,1,12.43,700,1,14.48,1400,2,12.42,700,1,14.49,100,1,ARL,363629061
2172,2025-07-17T16:32:30.849867081Z,2025-07-17T16:32:30.849867081Z,10,2,1108,A,A,6,14.25,100,130,165971,301933741,13.11,100,1,13.45,15,1,12.98,200,2,13.46,100,1,12.9,2,1,13.7,2,1,12.86,100,1,13.73,100,1,12.73,100,1,14.06,100,1,12.71,100,1,14.23,100,1,12.5,700,1,14.25,100,1,12.46,100,1,14.35,200,2,12.43,700,1,14.41,100,1,12.42,700,1,14.48,1400,2,ARL,363634009
2173,2025-07-17T16:32:34.631393080Z,2025-07-17T16:32:34.631393080Z,10,2,1108,A,A,5,14.18,700,130,165379,301979109,13.11,100,1,13.45,15,1,12.98,200,2,13.46,100,1,12.9,2,1,13.7,2,1,12.86,100,1,13.73,100,1,12.73,100,1,14.06,100,1,12.71,100,1,14.18,700,1,12.5,700,1,14.23,100,1,12.46,100,1,14.25,100,1,12.43,700,1,14.35,200,2,12.42,700,1,14.41,100,1,ARL,363687721
2174,2025-07-17T16:32:34.859947247Z,2025-07-17T16:32:34.859947247Z,10,2,1108,C,A,0,13.45,15,130,165390,301982608,13.11,100,1,13.46,100,1,12.98,200,2,13.7,2,1,12.9,2,1,13.73,100,1,12.86,100,1,14.06,100,1,12.73,100,1,14.18,700,1,12.71,100,1,14.23,100,1,12.5,700,1,14.25,100,1,12.46,100,1,14.35,200,2,12.43,700,1,14.41,100,1,12.42,700,1,14.48,1400,2,ARL,363610537
2175,2025-07-17T16:33:30.089711013Z,2025-07-17T16:33:30.089711013Z,10,2,1108,C,A,0,13.46,100,130,165345,302886447,13.11,100,1,13.7,2,1,12.98,200,2,13.73,100,1,12.9,2,1,14.06,100,1,12.86,100,1,14.18,700,1,12.73,100,1,14.23,100,1,12.71,100,1,14.25,100,1,12.5,700,1,14.35,200,2,12.46,100,1,14.41,100,1,12.43,700,1,14.48,1400,2,12.42,700,1,14.49,100,1,ARL,363611637
2176,2025-07-17T16:33:30.090246420Z,2025-07-17T16:33:30.090246420Z,10,2,1108,C,A,3,14.18,700,130,165261,302886453,13.11,100,1,13.7,2,1,12.98,200,2,13.73,100,1,12.9,2,1,14.06,100,1,12.86,100,1,14.23,100,1,12.73,100,1,14.25,100,1,12.71,100,1,14.35,200,2,12.5,700,1,14.41,100,1,12.46,100,1,14.48,1400,2,12.43,700,1,14.49,100,1,12.42,700,1,14.5,100,1,ARL,363687721
2177,2025-07-17T16:33:30.090305998Z,2025-07-17T16:33:30.090305998Z,10,2,1108,A,A,7,14.42,700,130,165808,302886454,13.11,100,1,13.7,2,1,12.98,200,2,13.73,100,1,12.9,2,1,14.06,100,1,12.86,100,1,14.23,100,1,12.73,100,1,14.25,100,1,12.71,100,1,14.35,200,2,12.5,700,1,14.41,100,1,12.46,100,1,14.42,700,1,12.43,700,1,14.48,1400,2,12.42,700,1,14.49,100,1,ARL,364850805
2178,2025-07-17T16:33:30.090815784Z,2025-07-17T16:33:30.090815784Z,10,2,1108,C,A,2,14.06,100,130,165331,302886458,13.11,100,1,13.7,2,1,12.98,200,2,13.73,100,1,12.9,2,1,14.23,100,1,12.86,100,1,14.25,100,1,12.73,100,1,14.35,200,2,12.71,100,1,14.41,100,1,12.5,700,1,14.42,700,1,12.46,100,1,14.48,1400,2,12.43,700,1,14.49,100,1,12.42,700,1,14.53,100,1,ARL,363629061
2179,2025-07-17T16:33:30.091173730Z,2025-07-17T16:33:30.091173730Z,10,2,1108,A,A,4,14.34,100,130,165291,302886460,13.11,100,1,13.7,2,1,12.98,200,2,13.73,100,1,12.9,2,1,14.23,100,1,12.86,100,1,14.25,100,1,12.73,100,1,14.34,100,1,12.71,100,1,14.35,200,2,12.5,700,1,14.41,100,1,12.46,100,1,14.42,700,1,12.43,700,1,14.48,1400,2,12.42,700,1,14.49,100,1,ARL,364850829
2180,2025-07-17T16:33:30.092789154Z,2025-07-17T16:33:30.092789154Z,10,2,1108,C,A,6,14.41,100,0,165665,302886527,13.11,100,1,13.7,2,1,12.98,200,2,13.73,100,1,12.9,2,1,14.23,100,1,12.86,100,1,14.25,100,1,12.73,100,1,14.34,100,1,12.71,100,1,14.35,200,2,12.5,700,1,14.42,700,1,12.46,100,1,14.48,1400,2,12.43,700,1,14.49,100,1,12.42,700,1,14.53,100,1,ARL,363611673
2181,2025-07-17T16:33:30.095936436Z,2025-07-17T16:33:30.095936436Z,10,2,1108,C,A,3,14.25,100,130,165090,302886538,13.11,100,1,13.7,2,1,12.98,200,2,13.73,100,1,12.9,2,1,14.23,100,1,12.86,100,1,14.34,100,1,12.73,100,1,14.35,200,2,12.71,100,1,14.42,700,1,12.5,700,1,14.48,1400,2,12.46,100,1,14.49,100,1,12.43,700,1,14.53,100,1,12.42,700,1,14.54,700,1,ARL,363634009
2182,2025-07-17T16:33:30.096080731Z,2025-07-17T16:33:30.096080731Z,10,2,1108,A,A,8,14.52,100,130,165136,302886541,13.11,100,1,13.7,2,1,12.98,200,2,13.73,100,1,12.9,2,1,14.23,100,1,12.86,100,1,14.34,100,1,12.73,100,1,14.35,200,2,12.71,100,1,14.42,700,1,12.5,700,1,14.48,1400,2,12.46,100,1,14.49,100,1,12.43,700,1,14.52,100,1,12.42,700,1,14.53,100,1,ARL,364850857
2183,2025-07-17T16:33:30.098253924Z,2025-07-17T16:33:30.098253924Z,10,2,1108,C,A,1,13.73,100,130,165232,302886562,13.11,100,1,13.7,2,1,12.98,200,2,14.23,100,1,12.9,2,1,14.34,100,1,12.86,100,1,14.35,200,2,12.73,100,1,14.42,700,1,12.71,100,1,14.48,1400,2,12.5,700,1,14.49,100,1,12.46,100,1,14.52,100,1,12.43,700,1,14.53,100,1,12.42,700,1,14.54,700,1,ARL,363612541
2184,2025-07-17T16:33:30.098285415Z,2025-07-17T16:33:30.098285415Z,10,2,1108,C,A,4,14.42,700,130,164991,302886563,13.11,100,1,13.7,2,1,12.98,200,2,14.23,100,1,12.9,2,1,14.34,100,1,12.86,100,1,14.35,200,2,12.73,100,1,14.48,1400,2,12.71,100,1,14.49,100,1,12.5,700,1,14.52,100,1,12.46,100,1,14.53,100,1,12.43,700,1,14.54,700,1,12.42,700,1,14.7,100,1,ARL,364850805
2185,2025-07-17T16:33:30.098305102Z,2025-07-17T16:33:30.098305102Z,10,2,1108,A,A,1,14,100,130,165051,302886564,13.11,100,1,13.7,2,1,12.98,200,2,14,100,1,12.9,2,1,14.23,100,1,12.86,100,1,14.34,100,1,12.73,100,1,14.35,200,2,12.71,100,1,14.48,1400,2,12.5,700,1,14.49,100,1,12.46,100,1,14.52,100,1,12.43,700,1,14.53,100,1,12.42,700,1,14.54,700,1,ARL,364850865
2186,2025-07-17T16:33:30.098595621Z,2025-07-17T16:33:30.098595621Z,10,2,1108,C,A,0,13.7,2,0,165479,302886565,13.11,100,1,14,100,1,12.98,200,2,14.23,100,1,12.9,2,1,14.34,100,1,12.86,100,1,14.35,200,2,12.73,100,1,14.48,1400,2,12.71,100,1,14.49,100,1,12.5,700,1,14.52,100,1,12.46,100,1,14.53,100,1,12.43,700,1,14.54,700,1,12.42,700,1,14.7,100,1,ARL,363619809
2187,2025-07-17T16:33:30.098595621Z,2025-07-17T16:33:30.098595621Z,10,2,1108,A,A,0,13.95,2,130,165479,302886565,13.11,100,1,13.95,2,1,12.98,200,2,14,100,1,12.9,2,1,14.23,100,1,12.86,100,1,14.34,100,1,12.73,100,1,14.35,200,2,12.71,100,1,14.48,1400,2,12.5,700,1,14.49,100,1,12.46,100,1,14.52,100,1,12.43,700,1,14.53,100,1,12.42,700,1,14.54,700,1,ARL,364850881
2188,2025-07-17T16:33:30.107892023Z,2025-07-17T16:33:30.107892023Z,10,2,1108,C,A,1,14,100,130,164991,302887072,13.11,100,1,13.95,2,1,12.98,200,2,14.23,100,1,12.9,2,1,14.34,100,1,12.86,100,1,14.35,200,2,12.73,100,1,14.48,1400,2,12.71,100,1,14.49,100,1,12.5,700,1,14.52,100,1,12.46,100,1,14.53,100,1,12.43,700,1,14.54,700,1,12.42,700,1,14.79,100,1,ARL,364850865
2189,2025-07-17T16:33:30.107939741Z,2025-07-17T16:33:30.107939741Z,10,2,1108,A,A,1,14.23,100,130,165135,302887073,13.11,100,1,13.95,2,1,12.98,200,2,14.23,200,2,12.9,2,1,14.34,100,1,12.86,100,1,14.35,200,2,12.73,100,1,14.48,1400,2,12.71,100,1,14.49,100,1,12.5,700,1,14.52,100,1,12.46,100,1,14.53,100,1,12.43,700,1,14.54,700,1,12.42,700,1,14.79,100,1,ARL,364851745
2190,2025-07-17T16:33:30.141027528Z,2025-07-17T16:33:30.141027528Z,10,2,1108,C,A,9,14.79,100,0,165198,302887727,13.11,100,1,13.95,2,1,12.98,200,2,14.23,200,2,12.9,2,1,14.34,100,1,12.86,100,1,14.35,200,2,12.73,100,1,14.48,1400,2,12.71,100,1,14.49,100,1,12.5,700,1,14.52,100,1,12.46,100,1,14.53,100,1,12.43,700,1,14.54,700,1,12.42,700,1,14.81,100,1,ARL,364850825
2191,2025-07-17T16:33:30.231685682Z,2025-07-17T16:33:30.231685682Z,10,2,1108,A,A,9,14.68,700,130,165292,302888895,13.11,100,1,13.95,2,1,12.98,200,2,14.23,200,2,12.9,2,1,14.34,100,1,12.86,100,1,14.35,200,2,12.73,100,1,14.48,1400,2,12.71,100,1,14.49,100,1,12.5,700,1,14.52,100,1,12.46,100,1,14.53,100,1,12.43,700,1,14.54,700,1,12.42,700,1,14.68,700,1,ARL,364854641
2192,2025-07-17T16:33:30.550669776Z,2025-07-17T16:33:30.550669776Z,10,2,1108,A,A,10,14.81,100,130,165141,302893143,13.11,100,1,13.95,2,1,12.98,200,2,14.23,200,2,12.9,2,1,14.34,100,1,12.86,100,1,14.35,200,2,12.73,100,1,14.48,1400,2,12.71,100,1,14.49,100,1,12.5,700,1,14.52,100,1,12.46,100,1,14.53,100,1,12.43,700,1,14.54,700,1,12.42,700,1,14.68,700,1,ARL,364862229
2193,2025-07-17T16:33:30.550682972Z,2025-07-17T16:33:30.550682972Z,10,2,1108,C,A,7,14.53,100,130,165321,302893144,13.11,100,1,13.95,2,1,12.98,200,2,14.23,200,2,12.9,2,1,14.34,100,1,12.86,100,1,14.35,200,2,12.73,100,1,14.48,1400,2,12.71,100,1,14.49,100,1,12.5,700,1,14.52,100,1,12.46,100,1,14.54,700,1,12.43,700,1,14.68,700,1,12.42,700,1,14.81,200,2,ARL,356722649
2194,2025-07-17T16:33:30.604472710Z,2025-07-17T16:33:30.604472710Z,10,2,1108,C,A,9,14.81,100,0,165162,302893497,13.11,100,1,13.95,2,1,12.98,200,2,14.23,200,2,12.9,2,1,14.34,100,1,12.86,100,1,14.35,200,2,12.73,100,1,14.48,1400,2,12.71,100,1,14.49,100,1,12.5,700,1,14.52,100,1,12.46,100,1,14.54,700,1,12.43,700,1,14.68,700,1,12.42,700,1,14.81,100,1,ARL,363613421
2195,2025-07-17T16:33:30.612356156Z,2025-07-17T16:33:30.612356156Z,10,2,1108,C,A,5,14.49,100,0,165565,302893537,13.11,100,1,13.95,2,1,12.98,200,2,14.23,200,2,12.9,2,1,14.34,100,1,12.86,100,1,14.35,200,2,12.73,100,1,14.48,1400,2,12.71,100,1,14.52,100,1,12.5,700,1,14.54,700,1,12.46,100,1,14.68,700,1,12.43,700,1,14.81,100,1,12.42,700,1,14.96,100,1,ARL,359404829
2196,2025-07-17T16:33:30.612356156Z,2025-07-17T16:33:30.612356156Z,10,2,1108,A,A,9,14.96,100,130,165565,302893537,13.11,100,1,13.95,2,1,12.98,200,2,14.23,200,2,12.9,2,1,14.34,100,1,12.86,100,1,14.35,200,2,12.73,100,1,14.48,1400,2,12.71,100,1,14.52,100,1,12.5,700,1,14.54,700,1,12.46,100,1,14.68,700,1,12.43,700,1,14.81,100,1,12.42,700,1,14.96,200,2,ARL,364862829
2197,2025-07-17T16:33:30.817076178Z,2025-07-17T16:33:30.817076178Z,10,2,1108,C,A,2,14.34,100,130,165758,302896626,13.11,100,1,13.95,2,1,12.98,200,2,14.23,200,2,12.9,2,1,14.35,200,2,12.86,100,1,14.48,1400,2,12.73,100,1,14.52,100,1,12.71,100,1,14.54,700,1,12.5,700,1,14.68,700,1,12.46,100,1,14.81,100,1,12.43,700,1,14.96,200,2,12.42,700,1,15.03,100,1,ARL,364850829
2198,2025-07-17T16:33:30.817425307Z,2025-07-17T16:33:30.817425307Z,10,2,1108,A,A,6,14.6,100,130,165622,302896627,13.11,100,1,13.95,2,1,12.98,200,2,14.23,200,2,12.9,2,1,14.35,200,2,12.86,100,1,14.48,1400,2,12.73,100,1,14.52,100,1,12.71,100,1,14.54,700,1,12.5,700,1,14.6,100,1,12.46,100,1,14.68,700,1,12.43,700,1,14.81,100,1,12.42,700,1,14.96,200,2,ARL,364866209
2199,2025-07-17T16:33:30.966062395Z,2025-07-17T16:33:30.966062395Z,10,2,1108,A,A,1,13.96,100,130,165270,302898973,13.11,100,1,13.95,2,1,12.98,200,2,13.96,100,1,12.9,2,1,14.23,200,2,12.86,100,1,14.35,200,2,12.73,100,1,14.48,1400,2,12.71,100,1,14.52,100,1,12.5,700,1,14.54,700,1,12.46,100,1,14.6,100,1,12.43,700,1,14.68,700,1,12.42,700,1,14.81,100,1,ARL,364868901
2200,2025-07-17T16:33:31.084610021Z,2025-07-17T16:33:31.084610021Z,10,2,1108,A,A,5,14.51,100,0,166411,302900128,13.11,100,1,13.95,2,1,12.98,200,2,13.96,100,1,12.9,2,1,14.23,200,2,12.86,100,1,14.35,200,2,12.73,100,1,14.48,1400,2,12.71,100,1,14.51,100,1,12.5,700,1,14.52,100,1,12.46,100,1,14.54,700,1,12.43,700,1,14.6,100,1,12.42,700,1,14.68,700,1,ARL,364870969
2201,2025-07-17T16:33:31.084610406Z,2025-07-17T16:33:31.084610406Z,10,2,1108,C,A,2,14.23,100,130,166026,302900129,13.11,100,1,13.95,2,1,12.98,200,2,13.96,100,1,12.9,2,1,14.23,100,1,12.86,100,1,14.35,200,2,12.73,100,1,14.48,1400,2,12.71,100,1,14.51,100,1,12.5,700,1,14.52,100,1,12.46,100,1,14.54,700,1,12.43,700,1,14.6,100,1,12.42,700,1,14.68,700,1,ARL,356878397
2202,2025-07-17T16:33:31.100868523Z,2025-07-17T16:33:31.100868523Z,10,2,1108,C,A,6,14.52,100,0,165315,302900253,13.11,100,1,13.95,2,1,12.98,200,2,13.96,100,1,12.9,2,1,14.23,100,1,12.86,100,1,14.35,200,2,12.73,100,1,14.48,1400,2,12.71,100,1,14.51,100,1,12.5,700,1,14.54,700,1,12.46,100,1,14.6,100,1,12.43,700,1,14.68,700,1,12.42,700,1,14.81,100,1,ARL,364850857
2203,2025-07-17T16:33:31.100868523Z,2025-07-17T16:33:31.100868523Z,10,2,1108,A,A,9,14.75,100,130,165315,302900253,13.11,100,1,13.95,2,1,12.98,200,2,13.96,100,1,12.9,2,1,14.23,100,1,12.86,100,1,14.35,200,2,12.73,100,1,14.48,1400,2,12.71,100,1,14.51,100,1,12.5,700,1,14.54,700,1,12.46,100,1,14.6,100,1,12.43,700,1,14.68,700,1,12.42,700,1,14.75,100,1,ARL,364871373
2204,2025-07-17T16:33:44.517994545Z,2025-07-17T16:33:44.517994545Z,10,2,1108,A,A,0,13.43,15,130,166295,303072465,13.11,100,1,13.43,15,1,12.98,200,2,13.95,2,1,12.9,2,1,13.96,100,1,12.86,100,1,14.23,100,1,12.73,100,1,14.35,200,2,12.71,100,1,14.48,1400,2,12.5,700,1,14.51,100,1,12.46,100,1,14.54,700,1,12.43,700,1,14.6,100,1,12.42,700,1,14.68,700,1,ARL,365099977
2205,2025-07-17T16:33:44.585985363Z,2025-07-17T16:33:44.585985363Z,10,2,1108,C,B,2,12.9,2,0,165333,303074172,13.11,100,1,13.43,15,1,12.98,200,2,13.95,2,1,12.86,100,1,13.96,100,1,12.73,100,1,14.23,100,1,12.71,100,1,14.35,200,2,12.5,700,1,14.48,1400,2,12.46,100,1,14.51,100,1,12.43,700,1,14.54,700,1,12.42,700,1,14.6,100,1,12.37,700,1,14.68,700,1,ARL,357261961
2206,2025-07-17T16:33:44.585985363Z,2025-07-17T16:33:44.585985363Z,10,2,1108,A,B,1,12.99,2,130,165333,303074172,13.11,100,1,13.43,15,1,12.99,2,1,13.95,2,1,12.98,200,2,13.96,100,1,12.86,100,1,14.23,100,1,12.73,100,1,14.35,200,2,12.71,100,1,14.48,1400,2,12.5,700,1,14.51,100,1,12.46,100,1,14.54,700,1,12.43,700,1,14.6,100,1,12.42,700,1,14.68,700,1,ARL,365101121
2207,2025-07-17T16:33:54.862565014Z,2025-07-17T16:33:54.862565014Z,10,2,1108,A,A,0,13.41,15,130,165356,303210030,13.11,100,1,13.41,15,1,12.99,2,1,13.43,15,1,12.98,200,2,13.95,2,1,12.86,100,1,13.96,100,1,12.73,100,1,14.23,100,1,12.71,100,1,14.35,200,2,12.5,700,1,14.48,1400,2,12.46,100,1,14.51,100,1,12.43,700,1,14.54,700,1,12.42,700,1,14.6,100,1,ARL,365283485
2208,2025-07-17T16:33:59.769246037Z,2025-07-17T16:33:59.769246037Z,10,2,1108,C,A,3,13.96,100,0,165501,303268214,13.11,100,1,13.41,15,1,12.99,2,1,13.43,15,1,12.98,200,2,13.95,2,1,12.86,100,1,14.23,100,1,12.73,100,1,14.35,200,2,12.71,100,1,14.48,1400,2,12.5,700,1,14.51,100,1,12.46,100,1,14.54,700,1,12.43,700,1,14.6,100,1,12.42,700,1,14.68,700,1,ARL,364868901
2209,2025-07-17T16:33:59.769246037Z,2025-07-17T16:33:59.769246037Z,10,2,1108,A,A,2,13.94,100,130,165501,303268214,13.11,100,1,13.41,15,1,12.99,2,1,13.43,15,1,12.98,200,2,13.94,100,1,12.86,100,1,13.95,2,1,12.73,100,1,14.23,100,1,12.71,100,1,14.35,200,2,12.5,700,1,14.48,1400,2,12.46,100,1,14.51,100,1,12.43,700,1,14.54,700,1,12.42,700,1,14.6,100,1,ARL,365359953
2210,2025-07-17T16:33:59.769531404Z,2025-07-17T16:33:59.769531404Z,10,2,1108,C,A,3,13.95,2,0,165409,303268221,13.11,100,1,13.41,15,1,12.99,2,1,13.43,15,1,12.98,200,2,13.94,100,1,12.86,100,1,14.23,100,1,12.73,100,1,14.35,200,2,12.71,100,1,14.48,1400,2,12.5,700,1,14.51,100,1,12.46,100,1,14.54,700,1,12.43,700,1,14.6,100,1,12.42,700,1,14.68,700,1,ARL,364850881
2211,2025-07-17T16:33:59.769531404Z,2025-07-17T16:33:59.769531404Z,10,2,1108,A,A,2,13.94,2,130,165409,303268221,13.11,100,1,13.41,15,1,12.99,2,1,13.43,15,1,12.98,200,2,13.94,102,2,12.86,100,1,14.23,100,1,12.73,100,1,14.35,200,2,12.71,100,1,14.48,1400,2,12.5,700,1,14.51,100,1,12.46,100,1,14.54,700,1,12.43,700,1,14.6,100,1,12.42,700,1,14.68,700,1,ARL,365359981
2212,2025-07-17T16:34:17.588187064Z,2025-07-17T16:34:17.588187064Z,10,2,1108,C,B,1,12.99,2,0,165496,303567720,13.11,100,1,13.41,15,1,12.98,200,2,13.43,15,1,12.86,100,1,13.94,102,2,12.73,100,1,14.23,100,1,12.71,100,1,14.35,200,2,12.5,700,1,14.48,1400,2,12.46,100,1,14.51,100,1,12.43,700,1,14.54,700,1,12.42,700,1,14.6,100,1,12.37,700,1,14.68,700,1,ARL,365101121
2213,2025-07-17T16:34:17.588187064Z,2025-07-17T16:34:17.588187064Z,10,2,1108,A,B,1,13.07,2,130,165496,303567720,13.11,100,1,13.41,15,1,13.07,2,1,13.43,15,1,12.98,200,2,13.94,102,2,12.86,100,1,14.23,100,1,12.73,100,1,14.35,200,2,12.71,100,1,14.48,1400,2,12.5,700,1,14.51,100,1,12.46,100,1,14.54,700,1,12.43,700,1,14.6,100,1,12.42,700,1,14.68,700,1,ARL,365743281
2214,2025-07-17T16:34:22.930728013Z,2025-07-17T16:34:22.930728013Z,10,2,1108,C,A,1,13.43,15,130,165255,303633305,13.11,100,1,13.41,15,1,13.07,2,1,13.94,102,2,12.98,200,2,14.23,100,1,12.86,100,1,14.35,200,2,12.73,100,1,14.48,1400,2,12.71,100,1,14.51,100,1,12.5,700,1,14.54,700,1,12.46,100,1,14.6,100,1,12.43,700,1,14.68,700,1,12.42,700,1,14.75,100,1,ARL,365099977
2215,2025-07-17T16:34:23.935500330Z,2025-07-17T16:34:23.935500330Z,10,2,1108,A,A,0,13.39,15,130,165383,303659749,13.11,100,1,13.39,15,1,13.07,2,1,13.41,15,1,12.98,200,2,13.94,102,2,12.86,100,1,14.23,100,1,12.73,100,1,14.35,200,2,12.71,100,1,14.48,1400,2,12.5,700,1,14.51,100,1,12.46,100,1,14.54,700,1,12.43,700,1,14.6,100,1,12.42,700,1,14.68,700,1,ARL,365868793
2216,2025-07-17T16:34:24.279370835Z,2025-07-17T16:34:24.279370835Z,10,2,1108,C,A,2,13.94,100,0,166087,303666139,13.11,100,1,13.39,15,1,13.07,2,1,13.41,15,1,12.98,200,2,13.94,2,1,12.86,100,1,14.23,100,1,12.73,100,1,14.35,200,2,12.71,100,1,14.48,1400,2,12.5,700,1,14.51,100,1,12.46,100,1,14.54,700,1,12.43,700,1,14.6,100,1,12.42,700,1,14.68,700,1,ARL,365359953
2217,2025-07-17T16:34:24.279370835Z,2025-07-17T16:34:24.279370835Z,10,2,1108,A,A,2,13.92,100,130,166087,303666139,13.11,100,1,13.39,15,1,13.07,2,1,13.41,15,1,12.98,200,2,13.92,100,1,12.86,100,1,13.94,2,1,12.73,100,1,14.23,100,1,12.71,100,1,14.35,200,2,12.5,700,1,14.48,1400,2,12.46,100,1,14.51,100,1,12.43,700,1,14.54,700,1,12.42,700,1,14.6,100,1,ARL,365876341
2218,2025-07-17T16:36:08.787533217Z,2025-07-17T16:36:08.787533217Z,10,2,1108,A,A,2,13.42,100,130,165339,305042754,13.11,100,1,13.39,15,1,13.07,2,1,13.41,15,1,12.98,200,2,13.42,100,1,12.86,100,1,13.92,100,1,12.73,100,1,13.94,2,1,12.71,100,1,14.23,100,1,12.5,700,1,14.35,200,2,12.46,100,1,14.48,1400,2,12.43,700,1,14.51,100,1,12.42,700,1,14.54,700,1,ARL,367721465
2219,2025-07-17T16:36:08.788305174Z,2025-07-17T16:36:08.788305174Z,10,2,1108,A,A,7,14.46,100,128,166535,305042788,13.11,100,1,13.39,15,1,13.07,2,1,13.41,15,1,12.98,200,2,13.42,100,1,12.86,100,1,13.92,100,1,12.73,100,1,13.94,2,1,12.71,100,1,14.23,100,1,12.5,700,1,14.35,200,2,12.46,100,1,14.46,100,1,12.43,700,1,14.48,1400,2,12.42,700,1,14.51,100,1,ARL,367721513
2220,2025-07-17T16:36:08.788673150Z,2025-07-17T16:36:08.788673150Z,10,2,1108,A,A,5,14.02,100,130,165494,305042798,13.11,100,1,13.39,15,1,13.07,2,1,13.41,15,1,12.98,200,2,13.42,100,1,12.86,100,1,13.92,100,1,12.73,100,1,13.94,2,1,12.71,100,1,14.02,100,1,12.5,700,1,14.23,100,1,12.46,100,1,14.35,200,2,12.43,700,1,14.46,100,1,12.42,700,1,14.48,1400,2,ARL,367721521
2221,2025-07-17T16:36:08.790998871Z,2025-07-17T16:36:08.790998871Z,10,2,1108,A,A,8,14.36,100,130,165781,305042843,13.11,100,1,13.39,15,1,13.07,2,1,13.41,15,1,12.98,200,2,13.42,100,1,12.86,100,1,13.92,100,1,12.73,100,1,13.94,2,1,12.71,100,1,14.02,100,1,12.5,700,1,14.23,100,1,12.46,100,1,14.35,200,2,12.43,700,1,14.36,100,1,12.42,700,1,14.46,100,1,ARL,367721617
2222,2025-07-17T16:36:08.813098222Z,2025-07-17T16:36:08.813098222Z,10,2,1108,C,A,6,14.23,100,130,165533,305043109,13.11,100,1,13.39,15,1,13.07,2,1,13.41,15,1,12.98,200,2,13.42,100,1,12.86,100,1,13.92,100,1,12.73,100,1,13.94,2,1,12.71,100,1,14.02,100,1,12.5,700,1,14.35,200,2,12.46,100,1,14.36,100,1,12.43,700,1,14.46,100,1,12.42,700,1,14.48,1400,2,ARL,364851745
2223,2025-07-17T16:36:08.813150617Z,2025-07-17T16:36:08.813150617Z,10,2,1108,A,A,3,13.69,100,130,165251,305043110,13.11,100,1,13.39,15,1,13.07,2,1,13.41,15,1,12.98,200,2,13.42,100,1,12.86,100,1,13.69,100,1,12.73,100,1,13.92,100,1,12.71,100,1,13.94,2,1,12.5,700,1,14.02,100,1,12.46,100,1,14.35,200,2,12.43,700,1,14.36,100,1,12.42,700,1,14.46,100,1,ARL,367721969
2224,2025-07-17T16:36:08.861139066Z,2025-07-17T16:36:08.861139066Z,10,2,1108,A,A,8,14.36,100,130,165570,305043519,13.11,100,1,13.39,15,1,13.07,2,1,13.41,15,1,12.98,200,2,13.42,100,1,12.86,100,1,13.69,100,1,12.73,100,1,13.92,100,1,12.71,100,1,13.94,2,1,12.5,700,1,14.02,100,1,12.46,100,1,14.35,200,2,12.43,700,1,14.36,200,2,12.42,700,1,14.46,100,1,ARL,367722697
2225,2025-07-17T16:36:08.927620800Z,2025-07-17T16:36:08.927620800Z,10,2,1108,A,A,7,14.22,100,130,165526,305044162,13.11,100,1,13.39,15,1,13.07,2,1,13.41,15,1,12.98,200,2,13.42,100,1,12.86,100,1,13.69,100,1,12.73,100,1,13.92,100,1,12.71,100,1,13.94,2,1,12.5,700,1,14.02,100,1,12.46,100,1,14.22,100,1,12.43,700,1,14.35,200,2,12.42,700,1,14.36,200,2,ARL,367724041
2226,2025-07-17T16:36:08.966685380Z,2025-07-17T16:36:08.966685380Z,10,2,1108,A,A,6,13.95,100,130,165345,305045055,13.11,100,1,13.39,15,1,13.07,2,1,13.41,15,1,12.98,200,2,13.42,100,1,12.86,100,1,13.69,100,1,12.73,100,1,13.92,100,1,12.71,100,1,13.94,2,1,12.5,700,1,13.95,100,1,12.46,100,1,14.02,100,1,12.43,700,1,14.22,100,1,12.42,700,1,14.35,200,2,ARL,367724713
2227,2025-07-17T16:36:08.984613329Z,2025-07-17T16:36:08.984613329Z,10,2,1108,A,A,8,14.21,100,130,165470,305045290,13.11,100,1,13.39,15,1,13.07,2,1,13.41,15,1,12.98,200,2,13.42,100,1,12.86,100,1,13.69,100,1,12.73,100,1,13.92,100,1,12.71,100,1,13.94,2,1,12.5,700,1,13.95,100,1,12.46,100,1,14.02,100,1,12.43,700,1,14.21,100,1,12.42,700,1,14.22,100,1,ARL,367724841
2228,2025-07-17T16:36:09.001859949Z,2025-07-17T16:36:09.001859949Z,10,2,1108,C,A,4,13.92,100,0,165541,305045747,13.11,100,1,13.39,15,1,13.07,2,1,13.41,15,1,12.98,200,2,13.42,100,1,12.86,100,1,13.69,100,1,12.73,100,1,13.94,2,1,12.71,100,1,13.95,100,1,12.5,700,1,14.02,100,1,12.46,100,1,14.21,100,1,12.43,700,1,14.22,100,1,12.42,700,1,14.35,200,2,ARL,365876341
2229,2025-07-17T16:36:09.001859949Z,2025-07-17T16:36:09.001859949Z,10,2,1108,A,A,3,13.43,100,130,165541,305045747,13.11,100,1,13.39,15,1,13.07,2,1,13.41,15,1,12.98,200,2,13.42,100,1,12.86,100,1,13.43,100,1,12.73,100,1,13.69,100,1,12.71,100,1,13.94,2,1,12.5,700,1,13.95,100,1,12.46,100,1,14.02,100,1,12.43,700,1,14.21,100,1,12.42,700,1,14.22,100,1,ARL,367725181
2230,2025-07-17T16:36:09.186148784Z,2025-07-17T16:36:09.186148784Z,10,2,1108,C,B,1,13.07,2,0,165548,305049492,13.11,100,1,13.39,15,1,12.98,200,2,13.41,15,1,12.86,100,1,13.42,100,1,12.73,100,1,13.43,100,1,12.71,100,1,13.69,100,1,12.5,700,1,13.94,2,1,12.46,100,1,13.95,100,1,12.43,700,1,14.02,100,1,12.42,700,1,14.21,100,1,12.37,700,1,14.22,100,1,ARL,365743281
2231,2025-07-17T16:36:09.186148784Z,2025-07-17T16:36:09.186148784Z,10,2,1108,A,B,1,12.99,2,130,165548,305049492,13.11,100,1,13.39,15,1,12.99,2,1,13.41,15,1,12.98,200,2,13.42,100,1,12.86,100,1,13.43,100,1,12.73,100,1,13.69,100,1,12.71,100,1,13.94,2,1,12.5,700,1,13.95,100,1,12.46,100,1,14.02,100,1,12.43,700,1,14.21,100,1,12.42,700,1,14.22,100,1,ARL,367731761
2232,2025-07-17T16:36:15.432181896Z,2025-07-17T16:36:15.432181896Z,10,2,1108,A,A,8,14.16,700,130,165321,305159106,13.11,100,1,13.39,15,1,12.99,2,1,13.41,15,1,12.98,200,2,13.42,100,1,12.86,100,1,13.43,100,1,12.73,100,1,13.69,100,1,12.71,100,1,13.94,2,1,12.5,700,1,13.95,100,1,12.46,100,1,14.02,100,1,12.43,700,1,14.16,700,1,12.42,700,1,14.21,100,1,ARL,367862613
2233,2025-07-17T16:36:15.789986725Z,2025-07-17T16:36:15.789986725Z,10,2,1108,C,A,5,13.94,2,0,165626,305163657,13.11,100,1,13.39,15,1,12.99,2,1,13.41,15,1,12.98,200,2,13.42,100,1,12.86,100,1,13.43,100,1,12.73,100,1,13.69,100,1,12.71,100,1,13.95,100,1,12.5,700,1,14.02,100,1,12.46,100,1,14.16,700,1,12.43,700,1,14.21,100,1,12.42,700,1,14.22,100,1,ARL,365359981
2234,2025-07-17T16:36:15.789986725Z,2025-07-17T16:36:15.789986725Z,10,2,1108,A,A,5,13.85,2,130,165626,305163657,13.11,100,1,13.39,15,1,12.99,2,1,13.41,15,1,12.98,200,2,13.42,100,1,12.86,100,1,13.43,100,1,12.73,100,1,13.69,100,1,12.71,100,1,13.85,2,1,12.5,700,1,13.95,100,1,12.46,100,1,14.02,100,1,12.43,700,1,14.16,700,1,12.42,700,1,14.21,100,1,ARL,367868161
2235,2025-07-17T16:36:25.985698920Z,2025-07-17T16:36:25.985698920Z,10,2,1108,C,A,5,13.85,2,0,165597,305274495,13.11,100,1,13.39,15,1,12.99,2,1,13.41,15,1,12.98,200,2,13.42,100,1,12.86,100,1,13.43,100,1,12.73,100,1,13.69,100,1,12.71,100,1,13.95,100,1,12.5,700,1,14.02,100,1,12.46,100,1,14.16,700,1,12.43,700,1,14.21,100,1,12.42,700,1,14.22,100,1,ARL,367868161
2236,2025-07-17T16:36:25.985698920Z,2025-07-17T16:36:25.985698920Z,10,2,1108,A,A,5,13.77,2,130,165597,305274495,13.11,100,1,13.39,15,1,12.99,2,1,13.41,15,1,12.98,200,2,13.42,100,1,12.86,100,1,13.43,100,1,12.73,100,1,13.69,100,1,12.71,100,1,13.77,2,1,12.5,700,1,13.95,100,1,12.46,100,1,14.02,100,1,12.43,700,1,14.16,700,1,12.42,700,1,14.21,100,1,ARL,368018937
2237,2025-07-17T16:37:00.789841841Z,2025-07-17T16:37:00.789841841Z,10,2,1108,C,A,5,13.77,2,0,165610,305798904,13.11,100,1,13.39,15,1,12.99,2,1,13.41,15,1,12.98,200,2,13.42,100,1,12.86,100,1,13.43,100,1,12.73,100,1,13.69,100,1,12.71,100,1,13.95,100,1,12.5,700,1,14.02,100,1,12.46,100,1,14.16,700,1,12.43,700,1,14.21,100,1,12.42,700,1,14.22,100,1,ARL,368018937
2238,2025-07-17T16:37:00.789841841Z,2025-07-17T16:37:00.789841841Z,10,2,1108,A,A,5,13.7,2,130,165610,305798904,13.11,100,1,13.39,15,1,12.99,2,1,13.41,15,1,12.98,200,2,13.42,100,1,12.86,100,1,13.43,100,1,12.73,100,1,13.69,100,1,12.71,100,1,13.7,2,1,12.5,700,1,13.95,100,1,12.46,100,1,14.02,100,1,12.43,700,1,14.16,700,1,12.42,700,1,14.21,100,1,ARL,368710393
2239,2025-07-17T16:37:37.386081296Z,2025-07-17T16:37:37.386081296Z,10,2,1108,C,B,1,12.99,2,0,165594,306324624,13.11,100,1,13.39,15,1,12.98,200,2,13.41,15,1,12.86,100,1,13.42,100,1,12.73,100,1,13.43,100,1,12.71,100,1,13.69,100,1,12.5,700,1,13.7,2,1,12.46,100,1,13.95,100,1,12.43,700,1,14.02,100,1,12.42,700,1,14.16,700,1,12.37,700,1,14.21,100,1,ARL,367731761
2240,2025-07-17T16:37:37.386081296Z,2025-07-17T16:37:37.386081296Z,10,2,1108,A,B,2,12.91,2,130,165594,306324624,13.11,100,1,13.39,15,1,12.98,200,2,13.41,15,1,12.91,2,1,13.42,100,1,12.86,100,1,13.43,100,1,12.73,100,1,13.69,100,1,12.71,100,1,13.7,2,1,12.5,700,1,13.95,100,1,12.46,100,1,14.02,100,1,12.43,700,1,14.16,700,1,12.42,700,1,14.21,100,1,ARL,369392197
2241,2025-07-17T16:38:28.877439870Z,2025-07-17T16:38:28.877439870Z,10,2,1108,C,A,2,13.42,100,130,165260,307157610,13.11,100,1,13.39,15,1,12.98,200,2,13.41,15,1,12.91,2,1,13.43,100,1,12.86,100,1,13.69,100,1,12.73,100,1,13.7,2,1,12.71,100,1,13.95,100,1,12.5,700,1,14.02,100,1,12.46,100,1,14.16,700,1,12.43,700,1,14.21,100,1,12.42,700,1,14.22,100,1,ARL,367721465
2242,2025-07-17T16:38:28.883590127Z,2025-07-17T16:38:28.883590127Z,10,2,1108,C,A,0,13.39,15,130,168274,307158368,13.11,100,1,13.41,15,1,12.98,200,2,13.43,100,1,12.91,2,1,13.69,100,1,12.86,100,1,13.7,2,1,12.73,100,1,13.95,100,1,12.71,100,1,14.02,100,1,12.5,700,1,14.16,700,1,12.46,100,1,14.21,100,1,12.43,700,1,14.22,100,1,12.42,700,1,14.35,200,2,ARL,365868793
2243,2025-07-17T16:38:28.883720539Z,2025-07-17T16:38:28.883720539Z,10,2,1108,C,A,0,13.41,15,130,166583,307158422,13.11,100,1,13.43,100,1,12.98,200,2,13.69,100,1,12.91,2,1,13.7,2,1,12.86,100,1,13.95,100,1,12.73,100,1,14.02,100,1,12.71,100,1,14.16,700,1,12.5,700,1,14.21,100,1,12.46,100,1,14.22,100,1,12.43,700,1,14.35,200,2,12.42,700,1,14.36,200,2,ARL,365283485
2244,2025-07-17T16:38:28.883766503Z,2025-07-17T16:38:28.883766503Z,10,2,1108,C,A,0,13.43,100,128,168217,307158437,13.11,100,1,13.69,100,1,12.98,200,2,13.7,2,1,12.91,2,1,13.95,100,1,12.86,100,1,14.02,100,1,12.73,100,1,14.16,700,1,12.71,100,1,14.21,100,1,12.5,700,1,14.22,100,1,12.46,100,1,14.35,200,2,12.43,700,1,14.36,200,2,12.42,700,1,14.46,100,1,ARL,367725181
2245,2025-07-17T16:38:28.884518373Z,2025-07-17T16:38:28.884518373Z,10,2,1108,C,A,3,14.02,100,128,168298,307158750,13.11,100,1,13.69,100,1,12.98,200,2,13.7,2,1,12.91,2,1,13.95,100,1,12.86,100,1,14.16,700,1,12.73,100,1,14.21,100,1,12.71,100,1,14.22,100,1,12.5,700,1,14.35,200,2,12.46,100,1,14.36,200,2,12.43,700,1,14.46,100,1,12.42,700,1,14.48,1400,2,ARL,367721521
2246,2025-07-17T16:38:28.884800337Z,2025-07-17T16:38:28.884800337Z,10,2,1108,C,A,8,14.46,100,0,169813,307158964,13.11,100,1,13.69,100,1,12.98,200,2,13.7,2,1,12.91,2,1,13.95,100,1,12.86,100,1,14.16,700,1,12.73,100,1,14.21,100,1,12.71,100,1,14.22,100,1,12.5,700,1,14.35,200,2,12.46,100,1,14.36,200,2,12.43,700,1,14.48,1400,2,12.42,700,1,14.54,700,1,ARL,367721513
2247,2025-07-17T16:38:28.884800337Z,2025-07-17T16:38:28.884800337Z,10,2,1108,A,A,10,14.75,100,128,169813,307158964,13.11,100,1,13.69,100,1,12.98,200,2,13.7,2,1,12.91,2,1,13.95,100,1,12.86,100,1,14.16,700,1,12.73,100,1,14.21,100,1,12.71,100,1,14.22,100,1,12.5,700,1,14.35,200,2,12.46,100,1,14.36,200,2,12.43,700,1,14.48,1400,2,12.42,700,1,14.54,700,1,ARL,370437189
2248,2025-07-17T16:38:28.884882340Z,2025-07-17T16:38:28.884882340Z,10,2,1108,A,A,6,14.3,100,128,170348,307159022,13.11,100,1,13.69,100,1,12.98,200,2,13.7,2,1,12.91,2,1,13.95,100,1,12.86,100,1,14.16,700,1,12.73,100,1,14.21,100,1,12.71,100,1,14.22,100,1,12.5,700,1,14.3,100,1,12.46,100,1,14.35,200,2,12.43,700,1,14.36,200,2,12.42,700,1,14.48,1400,2,ARL,370437229
2249,2025-07-17T16:38:28.885058824Z,2025-07-17T16:38:28.885058824Z,10,2,1108,C,A,3,14.16,700,128,169631,307159152,13.11,100,1,13.69,100,1,12.98,200,2,13.7,2,1,12.91,2,1,13.95,100,1,12.86,100,1,14.21,100,1,12.73,100,1,14.22,100,1,12.71,100,1,14.3,100,1,12.5,700,1,14.35,200,2,12.46,100,1,14.36,200,2,12.43,700,1,14.48,1400,2,12.42,700,1,14.54,700,1,ARL,367862613
2250,2025-07-17T16:38:28.885115892Z,2025-07-17T16:38:28.885115892Z,10,2,1108,A,A,8,14.38,700,128,167659,307159202,13.11,100,1,13.69,100,1,12.98,200,2,13.7,2,1,12.91,2,1,13.95,100,1,12.86,100,1,14.21,100,1,12.73,100,1,14.22,100,1,12.71,100,1,14.3,100,1,12.5,700,1,14.35,200,2,12.46,100,1,14.36,200,2,12.43,700,1,14.38,700,1,12.42,700,1,14.48,1400,2,ARL,370437313
